Workbook
Name _INTERNAL_KEY1: '1. ГПП-АГПЗ+'!$9:$9
Name _INTERNAL_KEY10: '10. ГД Ноябрьск'!$10:$10
Name _INTERNAL_KEY11: '11. ГД Надым'!$9:$9
Name _INTERNAL_KEY12: '12. ГД Иркутск'!$9:$9
Name _INTERNAL_KEY13: '13. ГД Шельф'!$9:$9
Name _INTERNAL_KEY14: '14. ГП Благовещенск (Ам ГПЗ)'!$9:$9
Name _INTERNAL_KEY15: '15. КСПГ Портовая'!$9:$9
Name _INTERNAL_KEY16: '16. Востокгазпром'!$9:$9
Name _INTERNAL_KEY17: '17. Нефтехим Салават'!$9:$9
Name _INTERNAL_KEY18: '18. Газпром нефть'!$9:$9
Name _INTERNAL_KEY2: '2. ГПП-ОГХК'!$9:$9
Name _INTERNAL_KEY3: '3. ГПП-СГПЗ'!$9:$9
Name _INTERNAL_KEY4: '4. ГПП-УЗПКТ-СЗСК'!$10:$10
Name _INTERNAL_KEY5: '5. ГД Астрахань'!$9:$9
Name _INTERNAL_KEY6: '6. ГД Оренбург'!$9:$9
Name _INTERNAL_KEY7: '7. ГД Ямбург'!$9:$9
Name _INTERNAL_KEY8: '8. ГД Уренгой'!$9:$9
Name _INTERNAL_KEY9: '9. ГД Краснодар'!$9:$9
Name _SET_ROW1: '1. ГПП-АГПЗ+'!$E:$I
Name _SET_ROW10: '10. ГД Ноябрьск'!$E:$I
Name _SET_ROW11: '11. ГД Надым'!$E:$I
Name _SET_ROW12: '12. ГД Иркутск'!$E:$I
Name _SET_ROW13: '13. ГД Шельф'!$E:$I
Name _SET_ROW14: '14. ГП Благовещенск (Ам ГПЗ)'!$E:$I
Name _SET_ROW15: '15. КСПГ Портовая'!$E:$I
Name _SET_ROW16: '16. Востокгазпром'!$E:$I
Name _SET_ROW17: '17. Нефтехим Салават'!$E:$I
Name _SET_ROW18: '18. Газпром нефть'!$E:$I
Name _SET_ROW2: '2. ГПП-ОГХК'!$E:$I
Name _SET_ROW3: '3. ГПП-СГПЗ'!$E:$I
Name _SET_ROW4: '4. ГПП-УЗПКТ-СЗСК'!$E:$I
Name _SET_ROW5: '5. ГД Астрахань'!$E:$I
Name _SET_ROW6: '6. ГД Оренбург'!$E:$I
Name _SET_ROW7: '7. ГД Ямбург'!$E:$I
Name _SET_ROW8: '8. ГД Уренгой'!$E:$I
Name _SET_ROW9: '9. ГД Краснодар'!$E:$I
Name _SUM_REP_INTERNAL_KEY1: 'План общий'!$9:$9
Name _SUM_REP_INTERNAL_KEY2: 'Баланс ЗС'!$9:$9
Name _SUM_REP_SET_ROW1: 'План общий'!$D:$H
Name _SUM_REP_SET_ROW2: 'Баланс ЗС'!$D:$H

Sheet tech
A1: Имя | B1: Стиль
A2: FONT_SIMPLE | B2: 1.2345679e+09
A3: FONT_FORMULA | B3: 1.2345679e+09
A4: FONT_TITLE_LVL0 | B4: Текст пример 1234567890,1234567891
A5: FONT_TITLE_LVL1 | B5: Текст пример 1234567890,1234567891
A6: RULES_GREEN_RED_DASH | B6: 1.2345679e+09
A7: FULL_BORDER | B7: Текст пример 1234567890,1234567891
A8: FORMAT_PERCENTAGE | B8: 0.76
A9: FONT_TITLE_LVL1_GROUP1 | B9: Текст пример 1234567890,1234567891
A10: FONT_TITLE_LVL2_GROUP1 | B10: Текст пример 1234567890,1234567891
A11: FONT_CHECKER1 | B11: 1.2345679e+09
A12: RULE_DASH_FOR_ZERO | B12: 0

Sheet План общий
B3: Показатели по переработке углеводородного сырья и производству продукции Группы Газпром на _______________ год/годы
B6: Показатели | D6: Внутренние настройки листа | I6: Един. изм. | J6: 2026 | K6: 2025 | N6: 2026 год 1 квартал | O6: 2025 год 1 квартал | R6: 2026 год январь | S6: 2025 год январь | V6: 2026 год февраль | W6: 2025 год февраль | Z6: 2026 год март | AA6: 2025 год март | AD6: 2026 год 2 квартал | AE6: 2025 год 2 квартал | AH6: 2026 год апрель | AI6: 2025 год апрель | AL6: 2026 год май | AM6: 2025 год май | AP6: 2026 год июнь | AQ6: 2025 год июнь | AT6: 2026 год 3 квартал | AU6: 2025 год 3 квартал | AX6: 2026 год июль | AY6: 2025 год июль | BB6: 2026 год август | BC6: 2025 год август | BF6: 2026 год сентябрь | BG6: 2025 год сентябрь | BJ6: 2026 год 4 квартал | BK6: 2025 год 4 квартал | BN6: 2026 год октябрь | BO6: 2025 год октябрь | BR6: 2026 год ноябрь | BS6: 2025 год ноябрь | BV6: 2026 год декабрь | BW6: 2025 год декабрь
D7: Ключ статьи | E7: Ключ спец | F7: Ключ ввод данных | G7: Формулы месяца | H7: Формулы % выхода | J7: Среднесрочн. план 2026: Вариант утвержденный | K7: Факт | L7: Отклонение | N7: Среднесрочн. план 2026: Вариант утвержденный | O7: Факт | P7: Отклонение | R7: Среднесрочн. план 2026: Вариант утвержденный | S7: Факт | T7: Отклонение | V7: Среднесрочн. план 2026: Вариант утвержденный | W7: Факт | X7: Отклонение | Z7: Среднесрочн. план 2026: Вариант утвержденный | AA7: Факт | AB7: Отклонение | AD7: Среднесрочн. план 2026: Вариант утвержденный | AE7: Факт | AF7: Отклонение | AH7: Среднесрочн. план 2026: Вариант утвержденный | AI7: Факт | AJ7: Отклонение | AL7: Среднесрочн. план 2026: Вариант утвержденный | AM7: Факт | AN7: Отклонение | AP7: Среднесрочн. план 2026: Вариант утвержденный | AQ7: Факт | AR7: Отклонение | AT7: Среднесрочн. план 2026: Вариант утвержденный | AU7: Факт | AV7: Отклонение | AX7: Среднесрочн. план 2026: Вариант утвержденный | AY7: Факт | AZ7: Отклонение | BB7: Среднесрочн. план 2026: Вариант утвержденный | BC7: Факт | BD7: Отклонение | BF7: Среднесрочн. план 2026: Вариант утвержденный | BG7: Факт | BH7: Отклонение | BJ7: Среднесрочн. план 2026: Вариант утвержденный | BK7: Факт | BL7: Отклонение | BN7: Среднесрочн. план 2026: Вариант утвержденный | BO7: Факт | BP7: Отклонение | BR7: Среднесрочн. план 2026: Вариант утвержденный | BS7: Факт | BT7: Отклонение | BV7: Среднесрочн. план 2026: Вариант утвержденный | BW7: Факт | BX7: Отклонение
L8: + / - | M8: % вып. | P8: + / - | Q8: % вып. | T8: + / - | U8: % вып. | X8: + / - | Y8: % вып. | AB8: + / - | AC8: % вып. | AF8: + / - | AG8: % вып. | AJ8: + / - | AK8: % вып. | AN8: + / - | AO8: % вып. | AR8: + / - | AS8: % вып. | AV8: + / - | AW8: % вып. | AZ8: + / - | BA8: % вып. | BD8: + / - | BE8: % вып. | BH8: + / - | BI8: % вып. | BL8: + / - | BM8: % вып. | BP8: + / - | BQ8: % вып. | BT8: + / - | BU8: % вып. | BX8: + / - | BY8: % вып.
J9: year2026:1:2260099 | K9: year2025:15:None | N9: year2026:Q1:1:2260099 | O9: year2025:Q1:15:None | R9: year2026:M1_1:1:2260099 | S9: year2025:M1_1:15:None | V9: year2026:M1_2:1:2260099 | W9: year2025:M1_2:15:None | Z9: year2026:M1_3:1:2260099 | AA9: year2025:M1_3:15:None | AD9: year2026:Q2:1:2260099 | AE9: year2025:Q2:15:None | AH9: year2026:M2_1:1:2260099 | AI9: year2025:M2_1:15:None | AL9: year2026:M2_2:1:2260099 | AM9: year2025:M2_2:15:None | AP9: year2026:M2_3:1:2260099 | AQ9: year2025:M2_3:15:None | AT9: year2026:Q3:1:2260099 | AU9: year2025:Q3:15:None | AX9: year2026:M3_1:1:2260099 | AY9: year2025:M3_1:15:None | BB9: year2026:M3_2:1:2260099 | BC9: year2025:M3_2:15:None | BF9: year2026:M3_3:1:2260099 | BG9: year2025:M3_3:15:None | BJ9: year2026:Q4:1:2260099 | BK9: year2025:Q4:15:None | BN9: year2026:M4_1:1:2260099 | BO9: year2025:M4_1:15:None | BR9: year2026:M4_2:1:2260099 | BS9: year2025:M4_2:15:None | BV9: year2026:M4_3:1:2260099 | BW9: year2025:M4_3:15:None
B10: Раздел 1. Прогнозные показатели по переработке углеводородного сырья и производству продукции ПАО "Газпром" и основных дочерних обществ
C11: CЫРЬЕ
B12: 1. | C12: Переработка газа на ГПЗ-всего | G12: 1_1003335807+2_100332038+2_100332040+2_100332042+2_100332044+2_100332916+2_100332944+2_100335129+3_100330552+3_100330008+14_100335074+14_100335076 | I12: млн куб.м. | J12: =N12+AD12+AT12+BJ12 -> 58789.9 | K12: =O12+AE12+AU12+BK12 -> 0 | L12: =IFERROR(K12-J12,"-") -> -58789.9 | M12: =IFERROR(K12/J12,"-") -> 0 | N12: =R12+V12+Z12 -> 14950.5 | O12: =S12+W12+AA12 -> 0 | P12: =IFERROR(O12-N12,"-") -> -14950.5 | Q12: =IFERROR(O12/N12,"-") -> 0 | R12: ='1. ГПП-АГПЗ+'!W22+'2. ГПП-ОГХК'!W21+'2. ГПП-ОГХК'!W25+'2. ГПП-ОГХК'!W27+'2. ГПП-ОГХК'!W29+'2. ГПП-ОГХК'!W31+'2. ГПП-ОГХК'!W33+'2. ГПП-ОГХК'!W35+'3. ГПП-СГПЗ'!W18+'3. ГПП-СГПЗ'!W16+'14. ГП Благовещенск (Ам ГПЗ)'!W31+'14. ГП Благовещенск (Ам ГПЗ)'!W33 -> 5298.6 | S12: ='1. ГПП-АГПЗ+'!Y22+'2. ГПП-ОГХК'!Y21+'2. ГПП-ОГХК'!Y25+'2. ГПП-ОГХК'!Y27+'2. ГПП-ОГХК'!Y29+'2. ГПП-ОГХК'!Y31+'2. ГПП-ОГХК'!Y33+'2. ГПП-ОГХК'!Y35+'3. ГПП-СГПЗ'!Y18+'3. ГПП-СГПЗ'!Y16+'14. ГП Благовещенск (Ам ГПЗ)'!Y31+'14. ГП Благовещенск (Ам ГПЗ)'!Y33 -> 0 | T12: =IFERROR(S12-R12,"-") -> -5298.6 | U12: =IFERROR(S12/R12,"-") -> 0 | V12: ='1. ГПП-АГПЗ+'!AC22+'2. ГПП-ОГХК'!AC21+'2. ГПП-ОГХК'!AC25+'2. ГПП-ОГХК'!AC27+'2. ГПП-ОГХК'!AC29+'2. ГПП-ОГХК'!AC31+'2. ГПП-ОГХК'!AC33+'2. ГПП-ОГХК'!AC35+'3. ГПП-СГПЗ'!AC18+'3. ГПП-СГПЗ'!AC16+'14. ГП Благовещенск (Ам ГПЗ)'!AC31+'14. ГП Благовещенск (Ам ГПЗ)'!AC33 -> 4785.6 | W12: ='1. ГПП-АГПЗ+'!AE22+'2. ГПП-ОГХК'!AE21+'2. ГПП-ОГХК'!AE25+'2. ГПП-ОГХК'!AE27+'2. ГПП-ОГХК'!AE29+'2. ГПП-ОГХК'!AE31+'2. ГПП-ОГХК'!AE33+'2. ГПП-ОГХК'!AE35+'3. ГПП-СГПЗ'!AE18+'3. ГПП-СГПЗ'!AE16+'14. ГП Благовещенск (Ам ГПЗ)'!AE31+'14. ГП Благовещенск (Ам ГПЗ)'!AE33 -> 0 | X12: =IFERROR(W12-V12,"-") -> -4785.6 | Y12: =IFERROR(W12/V12,"-") -> 0 | Z12: ='1. ГПП-АГПЗ+'!AI22+'2. ГПП-ОГХК'!AI21+'2. ГПП-ОГХК'!AI25+'2. ГПП-ОГХК'!AI27+'2. ГПП-ОГХК'!AI29+'2. ГПП-ОГХК'!AI31+'2. ГПП-ОГХК'!AI33+'2. ГПП-ОГХК'!AI35+'3. ГПП-СГПЗ'!AI18+'3. ГПП-СГПЗ'!AI16+'14. ГП Благовещенск (Ам ГПЗ)'!AI31+'14. ГП Благовещенск (Ам ГПЗ)'!AI33 -> 4866.3 | AA12: ='1. ГПП-АГПЗ+'!AK22+'2. ГПП-ОГХК'!AK21+'2. ГПП-ОГХК'!AK25+'2. ГПП-ОГХК'!AK27+'2. ГПП-ОГХК'!AK29+'2. ГПП-ОГХК'!AK31+'2. ГПП-ОГХК'!AK33+'2. ГПП-ОГХК'!AK35+'3. ГПП-СГПЗ'!AK18+'3. ГПП-СГПЗ'!AK16+'14. ГП Благовещенск (Ам ГПЗ)'!AK31+'14. ГП Благовещенск (Ам ГПЗ)'!AK33 -> 0 | AB12: =IFERROR(AA12-Z12,"-") -> -4866.3 | AC12: =IFERROR(AA12/Z12,"-") -> 0 | AD12: =AH12+AL12+AP12 -> 13601 | AE12: =AI12+AM12+AQ12 -> 0 | AF12: =IFERROR(AE12-AD12,"-") -> -13601 | AG12: =IFERROR(AE12/AD12,"-") -> 0 | AH12: ='1. ГПП-АГПЗ+'!AU22+'2. ГПП-ОГХК'!AU21+'2. ГПП-ОГХК'!AU25+'2. ГПП-ОГХК'!AU27+'2. ГПП-ОГХК'!AU29+'2. ГПП-ОГХК'!AU31+'2. ГПП-ОГХК'!AU33+'2. ГПП-ОГХК'!AU35+'3. ГПП-СГПЗ'!AU18+'3. ГПП-СГПЗ'!AU16+'14. ГП Благовещенск (Ам ГПЗ)'!AU31+'14. ГП Благовещенск (Ам ГПЗ)'!AU33 -> 4158.4 | AI12: ='1. ГПП-АГПЗ+'!AW22+'2. ГПП-ОГХК'!AW21+'2. ГПП-ОГХК'!AW25+'2. ГПП-ОГХК'!AW27+'2. ГПП-ОГХК'!AW29+'2. ГПП-ОГХК'!AW31+'2. ГПП-ОГХК'!AW33+'2. ГПП-ОГХК'!AW35+'3. ГПП-СГПЗ'!AW18+'3. ГПП-СГПЗ'!AW16+'14. ГП Благовещенск (Ам ГПЗ)'!AW31+'14. ГП Благовещенск (Ам ГПЗ)'!AW33 -> 0 | AJ12: =IFERROR(AI12-AH12,"-") -> -4158.4 | AK12: =IFERROR(AI12/AH12,"-") -> 0 | AL12: ='1. ГПП-АГПЗ+'!BA22+'2. ГПП-ОГХК'!BA21+'2. ГПП-ОГХК'!BA25+'2. ГПП-ОГХК'!BA27+'2. ГПП-ОГХК'!BA29+'2. ГПП-ОГХК'!BA31+'2. ГПП-ОГХК'!BA33+'2. ГПП-ОГХК'!BA35+'3. ГПП-СГПЗ'!BA18+'3. ГПП-СГПЗ'!BA16+'14. ГП Благовещенск (Ам ГПЗ)'!BA31+'14. ГП Благовещенск (Ам ГПЗ)'!BA33 -> 4817.5 | AM12: ='1. ГПП-АГПЗ+'!BC22+'2. ГПП-ОГХК'!BC21+'2. ГПП-ОГХК'!BC25+'2. ГПП-ОГХК'!BC27+'2. ГПП-ОГХК'!BC29+'2. ГПП-ОГХК'!BC31+'2. ГПП-ОГХК'!BC33+'2. ГПП-ОГХК'!BC35+'3. ГПП-СГПЗ'!BC18+'3. ГПП-СГПЗ'!BC16+'14. ГП Благовещенск (Ам ГПЗ)'!BC31+'14. ГП Благовещенск (Ам ГПЗ)'!BC33 -> 0 | AN12: =IFERROR(AM12-AL12,"-") -> -4817.5 | AO12: =IFERROR(AM12/AL12,"-") -> 0 | AP12: ='1. ГПП-АГПЗ+'!BG22+'2. ГПП-ОГХК'!BG21+'2. ГПП-ОГХК'!BG25+'2. ГПП-ОГХК'!BG27+'2. ГПП-ОГХК'!BG29+'2. ГПП-ОГХК'!BG31+'2. ГПП-ОГХК'!BG33+'2. ГПП-ОГХК'!BG35+'3. ГПП-СГПЗ'!BG18+'3. ГПП-СГПЗ'!BG16+'14. ГП Благовещенск (Ам ГПЗ)'!BG31+'14. ГП Благовещенск (Ам ГПЗ)'!BG33 -> 4625.1 | AQ12: ='1. ГПП-АГПЗ+'!BI22+'2. ГПП-ОГХК'!BI21+'2. ГПП-ОГХК'!BI25+'2. ГПП-ОГХК'!BI27+'2. ГПП-ОГХК'!BI29+'2. ГПП-ОГХК'!BI31+'2. ГПП-ОГХК'!BI33+'2. ГПП-ОГХК'!BI35+'3. ГПП-СГПЗ'!BI18+'3. ГПП-СГПЗ'!BI16+'14. ГП Благовещенск (Ам ГПЗ)'!BI31+'14. ГП Благовещенск (Ам ГПЗ)'!BI33 -> 0 | AR12: =IFERROR(AQ12-AP12,"-") -> -4625.1 | AS12: =IFERROR(AQ12/AP12,"-") -> 0 | AT12: =AX12+BB12+BF12 -> 14143.7 | AU12: =AY12+BC12+BG12 -> 0 | AV12: =IFERROR(AU12-AT12,"-") -> -14143.7 | AW12: =IFERROR(AU12/AT12,"-") -> 0 | AX12: ='1. ГПП-АГПЗ+'!BS22+'2. ГПП-ОГХК'!BS21+'2. ГПП-ОГХК'!BS25+'2. ГПП-ОГХК'!BS27+'2. ГПП-ОГХК'!BS29+'2. ГПП-ОГХК'!BS31+'2. ГПП-ОГХК'!BS33+'2. ГПП-ОГХК'!BS35+'3. ГПП-СГПЗ'!BS18+'3. ГПП-СГПЗ'!BS16+'14. ГП Благовещенск (Ам ГПЗ)'!BS31+'14. ГП Благовещенск (Ам ГПЗ)'!BS33 -> 5191 | AY12: ='1. ГПП-АГПЗ+'!BU22+'2. ГПП-ОГХК'!BU21+'2. ГПП-ОГХК'!BU25+'2. ГПП-ОГХК'!BU27+'2. ГПП-ОГХК'!BU29+'2. ГПП-ОГХК'!BU31+'2. ГПП-ОГХК'!BU33+'2. ГПП-ОГХК'!BU35+'3. ГПП-СГПЗ'!BU18+'3. ГПП-СГПЗ'!BU16+'14. ГП Благовещенск (Ам ГПЗ)'!BU31+'14. ГП Благовещенск (Ам ГПЗ)'!BU33 -> 0 | AZ12: =IFERROR(AY12-AX12,"-") -> -5191 | BA12: =IFERROR(AY12/AX12,"-") -> 0 | BB12: ='1. ГПП-АГПЗ+'!BY22+'2. ГПП-ОГХК'!BY21+'2. ГПП-ОГХК'!BY25+'2. ГПП-ОГХК'!BY27+'2. ГПП-ОГХК'!BY29+'2. ГПП-ОГХК'!BY31+'2. ГПП-ОГХК'!BY33+'2. ГПП-ОГХК'!BY35+'3. ГПП-СГПЗ'!BY18+'3. ГПП-СГПЗ'!BY16+'14. ГП Благовещенск (Ам ГПЗ)'!BY31+'14. ГП Благовещенск (Ам ГПЗ)'!BY33 -> 5195.3 | BC12: ='1. ГПП-АГПЗ+'!CA22+'2. ГПП-ОГХК'!CA21+'2. ГПП-ОГХК'!CA25+'2. ГПП-ОГХК'!CA27+'2. ГПП-ОГХК'!CA29+'2. ГПП-ОГХК'!CA31+'2. ГПП-ОГХК'!CA33+'2. ГПП-ОГХК'!CA35+'3. ГПП-СГПЗ'!CA18+'3. ГПП-СГПЗ'!CA16+'14. ГП Благовещенск (Ам ГПЗ)'!CA31+'14. ГП Благовещенск (Ам ГПЗ)'!CA33 -> 0 | BD12: =IFERROR(BC12-BB12,"-") -> -5195.3 | BE12: =IFERROR(BC12/BB12,"-") -> 0 | BF12: ='1. ГПП-АГПЗ+'!CE22+'2. ГПП-ОГХК'!CE21+'2. ГПП-ОГХК'!CE25+'2. ГПП-ОГХК'!CE27+'2. ГПП-ОГХК'!CE29+'2. ГПП-ОГХК'!CE31+'2. ГПП-ОГХК'!CE33+'2. ГПП-ОГХК'!CE35+'3. ГПП-СГПЗ'!CE18+'3. ГПП-СГПЗ'!CE16+'14. ГП Благовещенск (Ам ГПЗ)'!CE31+'14. ГП Благовещенск (Ам ГПЗ)'!CE33 -> 3757.4 | BG12: ='1. ГПП-АГПЗ+'!CG22+'2. ГПП-ОГХК'!CG21+'2. ГПП-ОГХК'!CG25+'2. ГПП-ОГХК'!CG27+'2. ГПП-ОГХК'!CG29+'2. ГПП-ОГХК'!CG31+'2. ГПП-ОГХК'!CG33+'2. ГПП-ОГХК'!CG35+'3. ГПП-СГПЗ'!CG18+'3. ГПП-СГПЗ'!CG16+'14. ГП Благовещенск (Ам ГПЗ)'!CG31+'14. ГП Благовещенск (Ам ГПЗ)'!CG33 -> 0 | BH12: =IFERROR(BG12-BF12,"-") -> -3757.4 | BI12: =IFERROR(BG12/BF12,"-") -> 0 | BJ12: =BN12+BR12+BV12 -> 16094.7 | BK12: =BO12+BS12+BW12 -> 0 | BL12: =IFERROR(BK12-BJ12,"-") -> -16094.7 | BM12: =IFERROR(BK12/BJ12,"-") -> 0 | BN12: ='1. ГПП-АГПЗ+'!CQ22+'2. ГПП-ОГХК'!CQ21+'2. ГПП-ОГХК'!CQ25+'2. ГПП-ОГХК'!CQ27+'2. ГПП-ОГХК'!CQ29+'2. ГПП-ОГХК'!CQ31+'2. ГПП-ОГХК'!CQ33+'2. ГПП-ОГХК'!CQ35+'3. ГПП-СГПЗ'!CQ18+'3. ГПП-СГПЗ'!CQ16+'14. ГП Благовещенск (Ам ГПЗ)'!CQ31+'14. ГП Благовещенск (Ам ГПЗ)'!CQ33 -> 5362.8 | BO12: ='1. ГПП-АГПЗ+'!CS22+'2. ГПП-ОГХК'!CS21+'2. ГПП-ОГХК'!CS25+'2. ГПП-ОГХК'!CS27+'2. ГПП-ОГХК'!CS29+'2. ГПП-ОГХК'!CS31+'2. ГПП-ОГХК'!CS33+'2. ГПП-ОГХК'!CS35+'3. ГПП-СГПЗ'!CS18+'3. ГПП-СГПЗ'!CS16+'14. ГП Благовещенск (Ам ГПЗ)'!CS31+'14. ГП Благовещенск (Ам ГПЗ)'!CS33 -> 0 | BP12: =IFERROR(BO12-BN12,"-") -> -5362.8 | BQ12: =IFERROR(BO12/BN12,"-") -> 0 | BR12: ='1. ГПП-АГПЗ+'!CW22+'2. ГПП-ОГХК'!CW21+'2. ГПП-ОГХК'!CW25+'2. ГПП-ОГХК'!CW27+'2. ГПП-ОГХК'!CW29+'2. ГПП-ОГХК'!CW31+'2. ГПП-ОГХК'!CW33+'2. ГПП-ОГХК'!CW35+'3. ГПП-СГПЗ'!CW18+'3. ГПП-СГПЗ'!CW16+'14. ГП Благовещенск (Ам ГПЗ)'!CW31+'14. ГП Благовещенск (Ам ГПЗ)'!CW33 -> 5279.1 | BS12: ='1. ГПП-АГПЗ+'!CY22+'2. ГПП-ОГХК'!CY21+'2. ГПП-ОГХК'!CY25+'2. ГПП-ОГХК'!CY27+'2. ГПП-ОГХК'!CY29+'2. ГПП-ОГХК'!CY31+'2. ГПП-ОГХК'!CY33+'2. ГПП-ОГХК'!CY35+'3. ГПП-СГПЗ'!CY18+'3. ГПП-СГПЗ'!CY16+'14. ГП Благовещенск (Ам ГПЗ)'!CY31+'14. ГП Благовещенск (Ам ГПЗ)'!CY33 -> 0 | BT12: =IFERROR(BS12-BR12,"-") -> -5279.1 | BU12: =IFERROR(BS12/BR12,"-") -> 0 | BV12: ='1. ГПП-АГПЗ+'!DC22+'2. ГПП-ОГХК'!DC21+'2. ГПП-ОГХК'!DC25+'2. ГПП-ОГХК'!DC27+'2. ГПП-ОГХК'!DC29+'2. ГПП-ОГХК'!DC31+'2. ГПП-ОГХК'!DC33+'2. ГПП-ОГХК'!DC35+'3. ГПП-СГПЗ'!DC18+'3. ГПП-СГПЗ'!DC16+'14. ГП Благовещенск (Ам ГПЗ)'!DC31+'14. ГП Благовещенск (Ам ГПЗ)'!DC33 -> 5452.8 | BW12: ='1. ГПП-АГПЗ+'!DE22+'2. ГПП-ОГХК'!DE21+'2. ГПП-ОГХК'!DE25+'2. ГПП-ОГХК'!DE27+'2. ГПП-ОГХК'!DE29+'2. ГПП-ОГХК'!DE31+'2. ГПП-ОГХК'!DE33+'2. ГПП-ОГХК'!DE35+'3. ГПП-СГПЗ'!DE18+'3. ГПП-СГПЗ'!DE16+'14. ГП Благовещенск (Ам ГПЗ)'!DE31+'14. ГП Благовещенск (Ам ГПЗ)'!DE33 -> 0 | BX12: =IFERROR(BW12-BV12,"-") -> -5452.8 | BY12: =IFERROR(BW12/BV12,"-") -> 0
C13: Газпром переработка | G13: 1_1003335807+2_100332038+2_100332040+2_100332042+2_100332044+2_100332916+2_100332944+2_100335129+3_100330552+3_100330008 | I13: млн куб.м. | J13: =N13+AD13+AT13+BJ13 -> 23405.1 | K13: =O13+AE13+AU13+BK13 -> 0 | L13: =IFERROR(K13-J13,"-") -> -23405.1 | M13: =IFERROR(K13/J13,"-") -> 0 | N13: =R13+V13+Z13 -> 6101.1 | O13: =S13+W13+AA13 -> 0 | P13: =IFERROR(O13-N13,"-") -> -6101.1 | Q13: =IFERROR(O13/N13,"-") -> 0 | R13: ='1. ГПП-АГПЗ+'!W22+'2. ГПП-ОГХК'!W21+'2. ГПП-ОГХК'!W25+'2. ГПП-ОГХК'!W27+'2. ГПП-ОГХК'!W29+'2. ГПП-ОГХК'!W31+'2. ГПП-ОГХК'!W33+'2. ГПП-ОГХК'!W35+'3. ГПП-СГПЗ'!W18+'3. ГПП-СГПЗ'!W16 -> 2108.7 | S13: ='1. ГПП-АГПЗ+'!Y22+'2. ГПП-ОГХК'!Y21+'2. ГПП-ОГХК'!Y25+'2. ГПП-ОГХК'!Y27+'2. ГПП-ОГХК'!Y29+'2. ГПП-ОГХК'!Y31+'2. ГПП-ОГХК'!Y33+'2. ГПП-ОГХК'!Y35+'3. ГПП-СГПЗ'!Y18+'3. ГПП-СГПЗ'!Y16 -> 0 | T13: =IFERROR(S13-R13,"-") -> -2108.7 | U13: =IFERROR(S13/R13,"-") -> 0 | V13: ='1. ГПП-АГПЗ+'!AC22+'2. ГПП-ОГХК'!AC21+'2. ГПП-ОГХК'!AC25+'2. ГПП-ОГХК'!AC27+'2. ГПП-ОГХК'!AC29+'2. ГПП-ОГХК'!AC31+'2. ГПП-ОГХК'!AC33+'2. ГПП-ОГХК'!AC35+'3. ГПП-СГПЗ'!AC18+'3. ГПП-СГПЗ'!AC16 -> 1904.5 | W13: ='1. ГПП-АГПЗ+'!AE22+'2. ГПП-ОГХК'!AE21+'2. ГПП-ОГХК'!AE25+'2. ГПП-ОГХК'!AE27+'2. ГПП-ОГХК'!AE29+'2. ГПП-ОГХК'!AE31+'2. ГПП-ОГХК'!AE33+'2. ГПП-ОГХК'!AE35+'3. ГПП-СГПЗ'!AE18+'3. ГПП-СГПЗ'!AE16 -> 0 | X13: =IFERROR(W13-V13,"-") -> -1904.5 | Y13: =IFERROR(W13/V13,"-") -> 0 | Z13: ='1. ГПП-АГПЗ+'!AI22+'2. ГПП-ОГХК'!AI21+'2. ГПП-ОГХК'!AI25+'2. ГПП-ОГХК'!AI27+'2. ГПП-ОГХК'!AI29+'2. ГПП-ОГХК'!AI31+'2. ГПП-ОГХК'!AI33+'2. ГПП-ОГХК'!AI35+'3. ГПП-СГПЗ'!AI18+'3. ГПП-СГПЗ'!AI16 -> 2087.9 | AA13: ='1. ГПП-АГПЗ+'!AK22+'2. ГПП-ОГХК'!AK21+'2. ГПП-ОГХК'!AK25+'2. ГПП-ОГХК'!AK27+'2. ГПП-ОГХК'!AK29+'2. ГПП-ОГХК'!AK31+'2. ГПП-ОГХК'!AK33+'2. ГПП-ОГХК'!AK35+'3. ГПП-СГПЗ'!AK18+'3. ГПП-СГПЗ'!AK16 -> 0 | AB13: =IFERROR(AA13-Z13,"-") -> -2087.9 | AC13: =IFERROR(AA13/Z13,"-") -> 0 | AD13: =AH13+AL13+AP13 -> 4893.6 | AE13: =AI13+AM13+AQ13 -> 0 | AF13: =IFERROR(AE13-AD13,"-") -> -4893.6 | AG13: =IFERROR(AE13/AD13,"-") -> 0 | AH13: ='1. ГПП-АГПЗ+'!AU22+'2. ГПП-ОГХК'!AU21+'2. ГПП-ОГХК'!AU25+'2. ГПП-ОГХК'!AU27+'2. ГПП-ОГХК'!AU29+'2. ГПП-ОГХК'!AU31+'2. ГПП-ОГХК'!AU33+'2. ГПП-ОГХК'!AU35+'3. ГПП-СГПЗ'!AU18+'3. ГПП-СГПЗ'!AU16 -> 1802.5 | AI13: ='1. ГПП-АГПЗ+'!AW22+'2. ГПП-ОГХК'!AW21+'2. ГПП-ОГХК'!AW25+'2. ГПП-ОГХК'!AW27+'2. ГПП-ОГХК'!AW29+'2. ГПП-ОГХК'!AW31+'2. ГПП-ОГХК'!AW33+'2. ГПП-ОГХК'!AW35+'3. ГПП-СГПЗ'!AW18+'3. ГПП-СГПЗ'!AW16 -> 0 | AJ13: =IFERROR(AI13-AH13,"-") -> -1802.5 | AK13: =IFERROR(AI13/AH13,"-") -> 0 | AL13: ='1. ГПП-АГПЗ+'!BA22+'2. ГПП-ОГХК'!BA21+'2. ГПП-ОГХК'!BA25+'2. ГПП-ОГХК'!BA27+'2. ГПП-ОГХК'!BA29+'2. ГПП-ОГХК'!BA31+'2. ГПП-ОГХК'!BA33+'2. ГПП-ОГХК'!BA35+'3. ГПП-СГПЗ'!BA18+'3. ГПП-СГПЗ'!BA16 -> 1618.9 | AM13: ='1. ГПП-АГПЗ+'!BC22+'2. ГПП-ОГХК'!BC21+'2. ГПП-ОГХК'!BC25+'2. ГПП-ОГХК'!BC27+'2. ГПП-ОГХК'!BC29+'2. ГПП-ОГХК'!BC31+'2. ГПП-ОГХК'!BC33+'2. ГПП-ОГХК'!BC35+'3. ГПП-СГПЗ'!BC18+'3. ГПП-СГПЗ'!BC16 -> 0 | AN13: =IFERROR(AM13-AL13,"-") -> -1618.9 | AO13: =IFERROR(AM13/AL13,"-") -> 0 | AP13: ='1. ГПП-АГПЗ+'!BG22+'2. ГПП-ОГХК'!BG21+'2. ГПП-ОГХК'!BG25+'2. ГПП-ОГХК'!BG27+'2. ГПП-ОГХК'!BG29+'2. ГПП-ОГХК'!BG31+'2. ГПП-ОГХК'!BG33+'2. ГПП-ОГХК'!BG35+'3. ГПП-СГПЗ'!BG18+'3. ГПП-СГПЗ'!BG16 -> 1472.2 | AQ13: ='1. ГПП-АГПЗ+'!BI22+'2. ГПП-ОГХК'!BI21+'2. ГПП-ОГХК'!BI25+'2. ГПП-ОГХК'!BI27+'2. ГПП-ОГХК'!BI29+'2. ГПП-ОГХК'!BI31+'2. ГПП-ОГХК'!BI33+'2. ГПП-ОГХК'!BI35+'3. ГПП-СГПЗ'!BI18+'3. ГПП-СГПЗ'!BI16 -> 0 | AR13: =IFERROR(AQ13-AP13,"-") -> -1472.2 | AS13: =IFERROR(AQ13/AP13,"-") -> 0 | AT13: =AX13+BB13+BF13 -> 5948.2 | AU13: =AY13+BC13+BG13 -> 0 | AV13: =IFERROR(AU13-AT13,"-") -> -5948.2 | AW13: =IFERROR(AU13/AT13,"-") -> 0 | AX13: ='1. ГПП-АГПЗ+'!BS22+'2. ГПП-ОГХК'!BS21+'2. ГПП-ОГХК'!BS25+'2. ГПП-ОГХК'!BS27+'2. ГПП-ОГХК'!BS29+'2. ГПП-ОГХК'!BS31+'2. ГПП-ОГХК'!BS33+'2. ГПП-ОГХК'!BS35+'3. ГПП-СГПЗ'!BS18+'3. ГПП-СГПЗ'!BS16 -> 1933 | AY13: ='1. ГПП-АГПЗ+'!BU22+'2. ГПП-ОГХК'!BU21+'2. ГПП-ОГХК'!BU25+'2. ГПП-ОГХК'!BU27+'2. ГПП-ОГХК'!BU29+'2. ГПП-ОГХК'!BU31+'2. ГПП-ОГХК'!BU33+'2. ГПП-ОГХК'!BU35+'3. ГПП-СГПЗ'!BU18+'3. ГПП-СГПЗ'!BU16 -> 0 | AZ13: =IFERROR(AY13-AX13,"-") -> -1933 | BA13: =IFERROR(AY13/AX13,"-") -> 0 | BB13: ='1. ГПП-АГПЗ+'!BY22+'2. ГПП-ОГХК'!BY21+'2. ГПП-ОГХК'!BY25+'2. ГПП-ОГХК'!BY27+'2. ГПП-ОГХК'!BY29+'2. ГПП-ОГХК'!BY31+'2. ГПП-ОГХК'!BY33+'2. ГПП-ОГХК'!BY35+'3. ГПП-СГПЗ'!BY18+'3. ГПП-СГПЗ'!BY16 -> 1937.2 | BC13: ='1. ГПП-АГПЗ+'!CA22+'2. ГПП-ОГХК'!CA21+'2. ГПП-ОГХК'!CA25+'2. ГПП-ОГХК'!CA27+'2. ГПП-ОГХК'!CA29+'2. ГПП-ОГХК'!CA31+'2. ГПП-ОГХК'!CA33+'2. ГПП-ОГХК'!CA35+'3. ГПП-СГПЗ'!CA18+'3. ГПП-СГПЗ'!CA16 -> 0 | BD13: =IFERROR(BC13-BB13,"-") -> -1937.2 | BE13: =IFERROR(BC13/BB13,"-") -> 0 | BF13: ='1. ГПП-АГПЗ+'!CE22+'2. ГПП-ОГХК'!CE21+'2. ГПП-ОГХК'!CE25+'2. ГПП-ОГХК'!CE27+'2. ГПП-ОГХК'!CE29+'2. ГПП-ОГХК'!CE31+'2. ГПП-ОГХК'!CE33+'2. ГПП-ОГХК'!CE35+'3. ГПП-СГПЗ'!CE18+'3. ГПП-СГПЗ'!CE16 -> 2078 | BG13: ='1. ГПП-АГПЗ+'!CG22+'2. ГПП-ОГХК'!CG21+'2. ГПП-ОГХК'!CG25+'2. ГПП-ОГХК'!CG27+'2. ГПП-ОГХК'!CG29+'2. ГПП-ОГХК'!CG31+'2. ГПП-ОГХК'!CG33+'2. ГПП-ОГХК'!CG35+'3. ГПП-СГПЗ'!CG18+'3. ГПП-СГПЗ'!CG16 -> 0 | BH13: =IFERROR(BG13-BF13,"-") -> -2078 | BI13: =IFERROR(BG13/BF13,"-") -> 0 | BJ13: =BN13+BR13+BV13 -> 6462.2 | BK13: =BO13+BS13+BW13 -> 0 | BL13: =IFERROR(BK13-BJ13,"-") -> -6462.2 | BM13: =IFERROR(BK13/BJ13,"-") -> 0 | BN13: ='1. ГПП-АГПЗ+'!CQ22+'2. ГПП-ОГХК'!CQ21+'2. ГПП-ОГХК'!CQ25+'2. ГПП-ОГХК'!CQ27+'2. ГПП-ОГХК'!CQ29+'2. ГПП-ОГХК'!CQ31+'2. ГПП-ОГХК'!CQ33+'2. ГПП-ОГХК'!CQ35+'3. ГПП-СГПЗ'!CQ18+'3. ГПП-СГПЗ'!CQ16 -> 2141.4 | BO13: ='1. ГПП-АГПЗ+'!CS22+'2. ГПП-ОГХК'!CS21+'2. ГПП-ОГХК'!CS25+'2. ГПП-ОГХК'!CS27+'2. ГПП-ОГХК'!CS29+'2. ГПП-ОГХК'!CS31+'2. ГПП-ОГХК'!CS33+'2. ГПП-ОГХК'!CS35+'3. ГПП-СГПЗ'!CS18+'3. ГПП-СГПЗ'!CS16 -> 0 | BP13: =IFERROR(BO13-BN13,"-") -> -2141.4 | BQ13: =IFERROR(BO13/BN13,"-") -> 0 | BR13: ='1. ГПП-АГПЗ+'!CW22+'2. ГПП-ОГХК'!CW21+'2. ГПП-ОГХК'!CW25+'2. ГПП-ОГХК'!CW27+'2. ГПП-ОГХК'!CW29+'2. ГПП-ОГХК'!CW31+'2. ГПП-ОГХК'!CW33+'2. ГПП-ОГХК'!CW35+'3. ГПП-СГПЗ'!CW18+'3. ГПП-СГПЗ'!CW16 -> 2126.1 | BS13: ='1. ГПП-АГПЗ+'!CY22+'2. ГПП-ОГХК'!CY21+'2. ГПП-ОГХК'!CY25+'2. ГПП-ОГХК'!CY27+'2. ГПП-ОГХК'!CY29+'2. ГПП-ОГХК'!CY31+'2. ГПП-ОГХК'!CY33+'2. ГПП-ОГХК'!CY35+'3. ГПП-СГПЗ'!CY18+'3. ГПП-СГПЗ'!CY16 -> 0 | BT13: =IFERROR(BS13-BR13,"-") -> -2126.1 | BU13: =IFERROR(BS13/BR13,"-") -> 0 | BV13: ='1. ГПП-АГПЗ+'!DC22+'2. ГПП-ОГХК'!DC21+'2. ГПП-ОГХК'!DC25+'2. ГПП-ОГХК'!DC27+'2. ГПП-ОГХК'!DC29+'2. ГПП-ОГХК'!DC31+'2. ГПП-ОГХК'!DC33+'2. ГПП-ОГХК'!DC35+'3. ГПП-СГПЗ'!DC18+'3. ГПП-СГПЗ'!DC16 -> 2194.7 | BW13: ='1. ГПП-АГПЗ+'!DE22+'2. ГПП-ОГХК'!DE21+'2. ГПП-ОГХК'!DE25+'2. ГПП-ОГХК'!DE27+'2. ГПП-ОГХК'!DE29+'2. ГПП-ОГХК'!DE31+'2. ГПП-ОГХК'!DE33+'2. ГПП-ОГХК'!DE35+'3. ГПП-СГПЗ'!DE18+'3. ГПП-СГПЗ'!DE16 -> 0 | BX13: =IFERROR(BW13-BV13,"-") -> -2194.7 | BY13: =IFERROR(BW13/BV13,"-") -> 0
C14: Астраханский ГПЗ | G14: 1_1003335807 | I14: млн куб.м. | J14: =N14+AD14+AT14+BJ14 -> 9676.5 | K14: =O14+AE14+AU14+BK14 -> 0 | L14: =IFERROR(K14-J14,"-") -> -9676.5 | M14: =IFERROR(K14/J14,"-") -> 0 | N14: =R14+V14+Z14 -> 2427.6 | O14: =S14+W14+AA14 -> 0 | P14: =IFERROR(O14-N14,"-") -> -2427.6 | Q14: =IFERROR(O14/N14,"-") -> 0 | R14: ='1. ГПП-АГПЗ+'!W22 -> 836.1 | S14: ='1. ГПП-АГПЗ+'!Y22 -> 0 | T14: =IFERROR(S14-R14,"-") -> -836.1 | U14: =IFERROR(S14/R14,"-") -> 0 | V14: ='1. ГПП-АГПЗ+'!AC22 -> 755.3 | W14: ='1. ГПП-АГПЗ+'!AE22 -> 0 | X14: =IFERROR(W14-V14,"-") -> -755.3 | Y14: =IFERROR(W14/V14,"-") -> 0 | Z14: ='1. ГПП-АГПЗ+'!AI22 -> 836.2 | AA14: ='1. ГПП-АГПЗ+'!AK22 -> 0 | AB14: =IFERROR(AA14-Z14,"-") -> -836.2 | AC14: =IFERROR(AA14/Z14,"-") -> 0 | AD14: =AH14+AL14+AP14 -> 1851.5 | AE14: =AI14+AM14+AQ14 -> 0 | AF14: =IFERROR(AE14-AD14,"-") -> -1851.5 | AG14: =IFERROR(AE14/AD14,"-") -> 0 | AH14: ='1. ГПП-АГПЗ+'!AU22 -> 809.2 | AI14: ='1. ГПП-АГПЗ+'!AW22 -> 0 | AJ14: =IFERROR(AI14-AH14,"-") -> -809.2 | AK14: =IFERROR(AI14/AH14,"-") -> 0 | AL14: ='1. ГПП-АГПЗ+'!BA22 -> 574.9 | AM14: ='1. ГПП-АГПЗ+'!BC22 -> 0 | AN14: =IFERROR(AM14-AL14,"-") -> -574.9 | AO14: =IFERROR(AM14/AL14,"-") -> 0 | AP14: ='1. ГПП-АГПЗ+'!BG22 -> 467.4 | AQ14: ='1. ГПП-АГПЗ+'!BI22 -> 0 | AR14: =IFERROR(AQ14-AP14,"-") -> -467.4 | AS14: =IFERROR(AQ14/AP14,"-") -> 0 | AT14: =AX14+BB14+BF14 -> 2641.8 | AU14: =AY14+BC14+BG14 -> 0 | AV14: =IFERROR(AU14-AT14,"-") -> -2641.8 | AW14: =IFERROR(AU14/AT14,"-") -> 0 | AX14: ='1. ГПП-АГПЗ+'!BS22 -> 869.4 | AY14: ='1. ГПП-АГПЗ+'!BU22 -> 0 | AZ14: =IFERROR(AY14-AX14,"-") -> -869.4 | BA14: =IFERROR(AY14/AX14,"-") -> 0 | BB14: ='1. ГПП-АГПЗ+'!BY22 -> 873.4 | BC14: ='1. ГПП-АГПЗ+'!CA22 -> 0 | BD14: =IFERROR(BC14-BB14,"-") -> -873.4 | BE14: =IFERROR(BC14/BB14,"-") -> 0 | BF14: ='1. ГПП-АГПЗ+'!CE22 -> 899 | BG14: ='1. ГПП-АГПЗ+'!CG22 -> 0 | BH14: =IFERROR(BG14-BF14,"-") -> -899 | BI14: =IFERROR(BG14/BF14,"-") -> 0 | BJ14: =BN14+BR14+BV14 -> 2755.6 | BK14: =BO14+BS14+BW14 -> 0 | BL14: =IFERROR(BK14-BJ14,"-") -> -2755.6 | BM14: =IFERROR(BK14/BJ14,"-") -> 0 | BN14: ='1. ГПП-АГПЗ+'!CQ22 -> 929.1 | BO14: ='1. ГПП-АГПЗ+'!CS22 -> 0 | BP14: =IFERROR(BO14-BN14,"-") -> -929.1 | BQ14: =IFERROR(BO14/BN14,"-") -> 0 | BR14: ='1. ГПП-АГПЗ+'!CW22 -> 899.1 | BS14: ='1. ГПП-АГПЗ+'!CY22 -> 0 | BT14: =IFERROR(BS14-BR14,"-") -> -899.1 | BU14: =IFERROR(BS14/BR14,"-") -> 0 | BV14: ='1. ГПП-АГПЗ+'!DC22 -> 927.4 | BW14: ='1. ГПП-АГПЗ+'!DE22 -> 0 | BX14: =IFERROR(BW14-BV14,"-") -> -927.4 | BY14: =IFERROR(BW14/BV14,"-") -> 0
C15: Оренбургский ГХК | G15: 2_100332038+2_100332040+2_100332042+2_100332044+2_100332916+2_100332944+2_100335129 | I15: млн куб.м. | J15: =N15+AD15+AT15+BJ15 -> 11699.1 | K15: =O15+AE15+AU15+BK15 -> 0 | L15: =IFERROR(K15-J15,"-") -> -11699.1 | M15: =IFERROR(K15/J15,"-") -> 0 | N15: =R15+V15+Z15 -> 3146.3 | O15: =S15+W15+AA15 -> 0 | P15: =IFERROR(O15-N15,"-") -> -3146.3 | Q15: =IFERROR(O15/N15,"-") -> 0 | R15: ='2. ГПП-ОГХК'!W21+'2. ГПП-ОГХК'!W25+'2. ГПП-ОГХК'!W27+'2. ГПП-ОГХК'!W29+'2. ГПП-ОГХК'!W31+'2. ГПП-ОГХК'!W33+'2. ГПП-ОГХК'!W35 -> 1091.1 | S15: ='2. ГПП-ОГХК'!Y21+'2. ГПП-ОГХК'!Y25+'2. ГПП-ОГХК'!Y27+'2. ГПП-ОГХК'!Y29+'2. ГПП-ОГХК'!Y31+'2. ГПП-ОГХК'!Y33+'2. ГПП-ОГХК'!Y35 -> 0 | T15: =IFERROR(S15-R15,"-") -> -1091.1 | U15: =IFERROR(S15/R15,"-") -> 0 | V15: ='2. ГПП-ОГХК'!AC21+'2. ГПП-ОГХК'!AC25+'2. ГПП-ОГХК'!AC27+'2. ГПП-ОГХК'!AC29+'2. ГПП-ОГХК'!AC31+'2. ГПП-ОГХК'!AC33+'2. ГПП-ОГХК'!AC35 -> 985.3 | W15: ='2. ГПП-ОГХК'!AE21+'2. ГПП-ОГХК'!AE25+'2. ГПП-ОГХК'!AE27+'2. ГПП-ОГХК'!AE29+'2. ГПП-ОГХК'!AE31+'2. ГПП-ОГХК'!AE33+'2. ГПП-ОГХК'!AE35 -> 0 | X15: =IFERROR(W15-V15,"-") -> -985.3 | Y15: =IFERROR(W15/V15,"-") -> 0 | Z15: ='2. ГПП-ОГХК'!AI21+'2. ГПП-ОГХК'!AI25+'2. ГПП-ОГХК'!AI27+'2. ГПП-ОГХК'!AI29+'2. ГПП-ОГХК'!AI31+'2. ГПП-ОГХК'!AI33+'2. ГПП-ОГХК'!AI35 -> 1069.9 | AA15: ='2. ГПП-ОГХК'!AK21+'2. ГПП-ОГХК'!AK25+'2. ГПП-ОГХК'!AK27+'2. ГПП-ОГХК'!AK29+'2. ГПП-ОГХК'!AK31+'2. ГПП-ОГХК'!AK33+'2. ГПП-ОГХК'!AK35 -> 0 | AB15: =IFERROR(AA15-Z15,"-") -> -1069.9 | AC15: =IFERROR(AA15/Z15,"-") -> 0 | AD15: =AH15+AL15+AP15 -> 2580 | AE15: =AI15+AM15+AQ15 -> 0 | AF15: =IFERROR(AE15-AD15,"-") -> -2580 | AG15: =IFERROR(AE15/AD15,"-") -> 0 | AH15: ='2. ГПП-ОГХК'!AU21+'2. ГПП-ОГХК'!AU25+'2. ГПП-ОГХК'!AU27+'2. ГПП-ОГХК'!AU29+'2. ГПП-ОГХК'!AU31+'2. ГПП-ОГХК'!AU33+'2. ГПП-ОГХК'!AU35 -> 894.5 | AI15: ='2. ГПП-ОГХК'!AW21+'2. ГПП-ОГХК'!AW25+'2. ГПП-ОГХК'!AW27+'2. ГПП-ОГХК'!AW29+'2. ГПП-ОГХК'!AW31+'2. ГПП-ОГХК'!AW33+'2. ГПП-ОГХК'!AW35 -> 0 | AJ15: =IFERROR(AI15-AH15,"-") -> -894.5 | AK15: =IFERROR(AI15/AH15,"-") -> 0 | AL15: ='2. ГПП-ОГХК'!BA21+'2. ГПП-ОГХК'!BA25+'2. ГПП-ОГХК'!BA27+'2. ГПП-ОГХК'!BA29+'2. ГПП-ОГХК'!BA31+'2. ГПП-ОГХК'!BA33+'2. ГПП-ОГХК'!BA35 -> 861.1 | AM15: ='2. ГПП-ОГХК'!BC21+'2. ГПП-ОГХК'!BC25+'2. ГПП-ОГХК'!BC27+'2. ГПП-ОГХК'!BC29+'2. ГПП-ОГХК'!BC31+'2. ГПП-ОГХК'!BC33+'2. ГПП-ОГХК'!BC35 -> 0 | AN15: =IFERROR(AM15-AL15,"-") -> -861.1 | AO15: =IFERROR(AM15/AL15,"-") -> 0 | AP15: ='2. ГПП-ОГХК'!BG21+'2. ГПП-ОГХК'!BG25+'2. ГПП-ОГХК'!BG27+'2. ГПП-ОГХК'!BG29+'2. ГПП-ОГХК'!BG31+'2. ГПП-ОГХК'!BG33+'2. ГПП-ОГХК'!BG35 -> 824.4 | AQ15: ='2. ГПП-ОГХК'!BI21+'2. ГПП-ОГХК'!BI25+'2. ГПП-ОГХК'!BI27+'2. ГПП-ОГХК'!BI29+'2. ГПП-ОГХК'!BI31+'2. ГПП-ОГХК'!BI33+'2. ГПП-ОГХК'!BI35 -> 0 | AR15: =IFERROR(AQ15-AP15,"-") -> -824.4 | AS15: =IFERROR(AQ15/AP15,"-") -> 0 | AT15: =AX15+BB15+BF15 -> 2756.3 | AU15: =AY15+BC15+BG15 -> 0 | AV15: =IFERROR(AU15-AT15,"-") -> -2756.3 | AW15: =IFERROR(AU15/AT15,"-") -> 0 | AX15: ='2. ГПП-ОГХК'!BS21+'2. ГПП-ОГХК'!BS25+'2. ГПП-ОГХК'!BS27+'2. ГПП-ОГХК'!BS29+'2. ГПП-ОГХК'!BS31+'2. ГПП-ОГХК'!BS33+'2. ГПП-ОГХК'!BS35 -> 877 | AY15: ='2. ГПП-ОГХК'!BU21+'2. ГПП-ОГХК'!BU25+'2. ГПП-ОГХК'!BU27+'2. ГПП-ОГХК'!BU29+'2. ГПП-ОГХК'!BU31+'2. ГПП-ОГХК'!BU33+'2. ГПП-ОГХК'!BU35 -> 0 | AZ15: =IFERROR(AY15-AX15,"-") -> -877 | BA15: =IFERROR(AY15/AX15,"-") -> 0 | BB15: ='2. ГПП-ОГХК'!BY21+'2. ГПП-ОГХК'!BY25+'2. ГПП-ОГХК'!BY27+'2. ГПП-ОГХК'!BY29+'2. ГПП-ОГХК'!BY31+'2. ГПП-ОГХК'!BY33+'2. ГПП-ОГХК'!BY35 -> 877.6 | BC15: ='2. ГПП-ОГХК'!CA21+'2. ГПП-ОГХК'!CA25+'2. ГПП-ОГХК'!CA27+'2. ГПП-ОГХК'!CA29+'2. ГПП-ОГХК'!CA31+'2. ГПП-ОГХК'!CA33+'2. ГПП-ОГХК'!CA35 -> 0 | BD15: =IFERROR(BC15-BB15,"-") -> -877.6 | BE15: =IFERROR(BC15/BB15,"-") -> 0 | BF15: ='2. ГПП-ОГХК'!CE21+'2. ГПП-ОГХК'!CE25+'2. ГПП-ОГХК'!CE27+'2. ГПП-ОГХК'!CE29+'2. ГПП-ОГХК'!CE31+'2. ГПП-ОГХК'!CE33+'2. ГПП-ОГХК'!CE35 -> 1001.7 | BG15: ='2. ГПП-ОГХК'!CG21+'2. ГПП-ОГХК'!CG25+'2. ГПП-ОГХК'!CG27+'2. ГПП-ОГХК'!CG29+'2. ГПП-ОГХК'!CG31+'2. ГПП-ОГХК'!CG33+'2. ГПП-ОГХК'!CG35 -> 0 | BH15: =IFERROR(BG15-BF15,"-") -> -1001.7 | BI15: =IFERROR(BG15/BF15,"-") -> 0 | BJ15: =BN15+BR15+BV15 -> 3216.5 | BK15: =BO15+BS15+BW15 -> 0 | BL15: =IFERROR(BK15-BJ15,"-") -> -3216.5 | BM15: =IFERROR(BK15/BJ15,"-") -> 0 | BN15: ='2. ГПП-ОГХК'!CQ21+'2. ГПП-ОГХК'!CQ25+'2. ГПП-ОГХК'!CQ27+'2. ГПП-ОГХК'!CQ29+'2. ГПП-ОГХК'!CQ31+'2. ГПП-ОГХК'!CQ33+'2. ГПП-ОГХК'!CQ35 -> 1084.8 | BO15: ='2. ГПП-ОГХК'!CS21+'2. ГПП-ОГХК'!CS25+'2. ГПП-ОГХК'!CS27+'2. ГПП-ОГХК'!CS29+'2. ГПП-ОГХК'!CS31+'2. ГПП-ОГХК'!CS33+'2. ГПП-ОГХК'!CS35 -> 0 | BP15: =IFERROR(BO15-BN15,"-") -> -1084.8 | BQ15: =IFERROR(BO15/BN15,"-") -> 0 | BR15: ='2. ГПП-ОГХК'!CW21+'2. ГПП-ОГХК'!CW25+'2. ГПП-ОГХК'!CW27+'2. ГПП-ОГХК'!CW29+'2. ГПП-ОГХК'!CW31+'2. ГПП-ОГХК'!CW33+'2. ГПП-ОГХК'!CW35 -> 1048.7 | BS15: ='2. ГПП-ОГХК'!CY21+'2. ГПП-ОГХК'!CY25+'2. ГПП-ОГХК'!CY27+'2. ГПП-ОГХК'!CY29+'2. ГПП-ОГХК'!CY31+'2. ГПП-ОГХК'!CY33+'2. ГПП-ОГХК'!CY35 -> 0 | BT15: =IFERROR(BS15-BR15,"-") -> -1048.7 | BU15: =IFERROR(BS15/BR15,"-") -> 0 | BV15: ='2. ГПП-ОГХК'!DC21+'2. ГПП-ОГХК'!DC25+'2. ГПП-ОГХК'!DC27+'2. ГПП-ОГХК'!DC29+'2. ГПП-ОГХК'!DC31+'2. ГПП-ОГХК'!DC33+'2. ГПП-ОГХК'!DC35 -> 1083 | BW15: ='2. ГПП-ОГХК'!DE21+'2. ГПП-ОГХК'!DE25+'2. ГПП-ОГХК'!DE27+'2. ГПП-ОГХК'!DE29+'2. ГПП-ОГХК'!DE31+'2. ГПП-ОГХК'!DE33+'2. ГПП-ОГХК'!DE35 -> 0 | BX15: =IFERROR(BW15-BV15,"-") -> -1083 | BY15: =IFERROR(BW15/BV15,"-") -> 0
C16: Сосногорский ГПЗ | G16: 3_100330552+3_100330008 | I16: млн куб.м. | J16: =N16+AD16+AT16+BJ16 -> 2029.5 | K16: =O16+AE16+AU16+BK16 -> 0 | L16: =IFERROR(K16-J16,"-") -> -2029.5 | M16: =IFERROR(K16/J16,"-") -> 0 | N16: =R16+V16+Z16 -> 527.2 | O16: =S16+W16+AA16 -> 0 | P16: =IFERROR(O16-N16,"-") -> -527.2 | Q16: =IFERROR(O16/N16,"-") -> 0 | R16: ='3. ГПП-СГПЗ'!W18+'3. ГПП-СГПЗ'!W16 -> 181.5 | S16: ='3. ГПП-СГПЗ'!Y18+'3. ГПП-СГПЗ'!Y16 -> 0 | T16: =IFERROR(S16-R16,"-") -> -181.5 | U16: =IFERROR(S16/R16,"-") -> 0 | V16: ='3. ГПП-СГПЗ'!AC18+'3. ГПП-СГПЗ'!AC16 -> 163.9 | W16: ='3. ГПП-СГПЗ'!AE18+'3. ГПП-СГПЗ'!AE16 -> 0 | X16: =IFERROR(W16-V16,"-") -> -163.9 | Y16: =IFERROR(W16/V16,"-") -> 0 | Z16: ='3. ГПП-СГПЗ'!AI18+'3. ГПП-СГПЗ'!AI16 -> 181.8 | AA16: ='3. ГПП-СГПЗ'!AK18+'3. ГПП-СГПЗ'!AK16 -> 0 | AB16: =IFERROR(AA16-Z16,"-") -> -181.8 | AC16: =IFERROR(AA16/Z16,"-") -> 0 | AD16: =AH16+AL16+AP16 -> 462.1 | AE16: =AI16+AM16+AQ16 -> 0 | AF16: =IFERROR(AE16-AD16,"-") -> -462.1 | AG16: =IFERROR(AE16/AD16,"-") -> 0 | AH16: ='3. ГПП-СГПЗ'!AU18+'3. ГПП-СГПЗ'!AU16 -> 98.8 | AI16: ='3. ГПП-СГПЗ'!AW18+'3. ГПП-СГПЗ'!AW16 -> 0 | AJ16: =IFERROR(AI16-AH16,"-") -> -98.8 | AK16: =IFERROR(AI16/AH16,"-") -> 0 | AL16: ='3. ГПП-СГПЗ'!BA18+'3. ГПП-СГПЗ'!BA16 -> 182.9 | AM16: ='3. ГПП-СГПЗ'!BC18+'3. ГПП-СГПЗ'!BC16 -> 0 | AN16: =IFERROR(AM16-AL16,"-") -> -182.9 | AO16: =IFERROR(AM16/AL16,"-") -> 0 | AP16: ='3. ГПП-СГПЗ'!BG18+'3. ГПП-СГПЗ'!BG16 -> 180.4 | AQ16: ='3. ГПП-СГПЗ'!BI18+'3. ГПП-СГПЗ'!BI16 -> 0 | AR16: =IFERROR(AQ16-AP16,"-") -> -180.4 | AS16: =IFERROR(AQ16/AP16,"-") -> 0 | AT16: =AX16+BB16+BF16 -> 550.1 | AU16: =AY16+BC16+BG16 -> 0 | AV16: =IFERROR(AU16-AT16,"-") -> -550.1 | AW16: =IFERROR(AU16/AT16,"-") -> 0 | AX16: ='3. ГПП-СГПЗ'!BS18+'3. ГПП-СГПЗ'!BS16 -> 186.6 | AY16: ='3. ГПП-СГПЗ'!BU18+'3. ГПП-СГПЗ'!BU16 -> 0 | AZ16: =IFERROR(AY16-AX16,"-") -> -186.6 | BA16: =IFERROR(AY16/AX16,"-") -> 0 | BB16: ='3. ГПП-СГПЗ'!BY18+'3. ГПП-СГПЗ'!BY16 -> 186.2 | BC16: ='3. ГПП-СГПЗ'!CA18+'3. ГПП-СГПЗ'!CA16 -> 0 | BD16: =IFERROR(BC16-BB16,"-") -> -186.2 | BE16: =IFERROR(BC16/BB16,"-") -> 0 | BF16: ='3. ГПП-СГПЗ'!CE18+'3. ГПП-СГПЗ'!CE16 -> 177.3 | BG16: ='3. ГПП-СГПЗ'!CG18+'3. ГПП-СГПЗ'!CG16 -> 0 | BH16: =IFERROR(BG16-BF16,"-") -> -177.3 | BI16: =IFERROR(BG16/BF16,"-") -> 0 | BJ16: =BN16+BR16+BV16 -> 490.1 | BK16: =BO16+BS16+BW16 -> 0 | BL16: =IFERROR(BK16-BJ16,"-") -> -490.1 | BM16: =IFERROR(BK16/BJ16,"-") -> 0 | BN16: ='3. ГПП-СГПЗ'!CQ18+'3. ГПП-СГПЗ'!CQ16 -> 127.5 | BO16: ='3. ГПП-СГПЗ'!CS18+'3. ГПП-СГПЗ'!CS16 -> 0 | BP16: =IFERROR(BO16-BN16,"-") -> -127.5 | BQ16: =IFERROR(BO16/BN16,"-") -> 0 | BR16: ='3. ГПП-СГПЗ'!CW18+'3. ГПП-СГПЗ'!CW16 -> 178.3 | BS16: ='3. ГПП-СГПЗ'!CY18+'3. ГПП-СГПЗ'!CY16 -> 0 | BT16: =IFERROR(BS16-BR16,"-") -> -178.3 | BU16: =IFERROR(BS16/BR16,"-") -> 0 | BV16: ='3. ГПП-СГПЗ'!DC18+'3. ГПП-СГПЗ'!DC16 -> 184.3 | BW16: ='3. ГПП-СГПЗ'!DE18+'3. ГПП-СГПЗ'!DE16 -> 0 | BX16: =IFERROR(BW16-BV16,"-") -> -184.3 | BY16: =IFERROR(BW16/BV16,"-") -> 0
C17: Газпром переработка Благовещенск | G17: 14_100335074+14_100335076 | I17: млн куб.м. | J17: =N17+AD17+AT17+BJ17 -> 35384.8 | K17: =O17+AE17+AU17+BK17 -> 0 | L17: =IFERROR(K17-J17,"-") -> -35384.8 | M17: =IFERROR(K17/J17,"-") -> 0 | N17: =R17+V17+Z17 -> 8849.4 | O17: =S17+W17+AA17 -> 0 | P17: =IFERROR(O17-N17,"-") -> -8849.4 | Q17: =IFERROR(O17/N17,"-") -> 0 | R17: ='14. ГП Благовещенск (Ам ГПЗ)'!W31+'14. ГП Благовещенск (Ам ГПЗ)'!W33 -> 3189.9 | S17: ='14. ГП Благовещенск (Ам ГПЗ)'!Y31+'14. ГП Благовещенск (Ам ГПЗ)'!Y33 -> 0 | T17: =IFERROR(S17-R17,"-") -> -3189.9 | U17: =IFERROR(S17/R17,"-") -> 0 | V17: ='14. ГП Благовещенск (Ам ГПЗ)'!AC31+'14. ГП Благовещенск (Ам ГПЗ)'!AC33 -> 2881.1 | W17: ='14. ГП Благовещенск (Ам ГПЗ)'!AE31+'14. ГП Благовещенск (Ам ГПЗ)'!AE33 -> 0 | X17: =IFERROR(W17-V17,"-") -> -2881.1 | Y17: =IFERROR(W17/V17,"-") -> 0 | Z17: ='14. ГП Благовещенск (Ам ГПЗ)'!AI31+'14. ГП Благовещенск (Ам ГПЗ)'!AI33 -> 2778.4 | AA17: ='14. ГП Благовещенск (Ам ГПЗ)'!AK31+'14. ГП Благовещенск (Ам ГПЗ)'!AK33 -> 0 | AB17: =IFERROR(AA17-Z17,"-") -> -2778.4 | AC17: =IFERROR(AA17/Z17,"-") -> 0 | AD17: =AH17+AL17+AP17 -> 8707.4 | AE17: =AI17+AM17+AQ17 -> 0 | AF17: =IFERROR(AE17-AD17,"-") -> -8707.4 | AG17: =IFERROR(AE17/AD17,"-") -> 0 | AH17: ='14. ГП Благовещенск (Ам ГПЗ)'!AU31+'14. ГП Благовещенск (Ам ГПЗ)'!AU33 -> 2355.9 | AI17: ='14. ГП Благовещенск (Ам ГПЗ)'!AW31+'14. ГП Благовещенск (Ам ГПЗ)'!AW33 -> 0 | AJ17: =IFERROR(AI17-AH17,"-") -> -2355.9 | AK17: =IFERROR(AI17/AH17,"-") -> 0 | AL17: ='14. ГП Благовещенск (Ам ГПЗ)'!BA31+'14. ГП Благовещенск (Ам ГПЗ)'!BA33 -> 3198.6 | AM17: ='14. ГП Благовещенск (Ам ГПЗ)'!BC31+'14. ГП Благовещенск (Ам ГПЗ)'!BC33 -> 0 | AN17: =IFERROR(AM17-AL17,"-") -> -3198.6 | AO17: =IFERROR(AM17/AL17,"-") -> 0 | AP17: ='14. ГП Благовещенск (Ам ГПЗ)'!BG31+'14. ГП Благовещенск (Ам ГПЗ)'!BG33 -> 3152.9 | AQ17: ='14. ГП Благовещенск (Ам ГПЗ)'!BI31+'14. ГП Благовещенск (Ам ГПЗ)'!BI33 -> 0 | AR17: =IFERROR(AQ17-AP17,"-") -> -3152.9 | AS17: =IFERROR(AQ17/AP17,"-") -> 0 | AT17: =AX17+BB17+BF17 -> 8195.5 | AU17: =AY17+BC17+BG17 -> 0 | AV17: =IFERROR(AU17-AT17,"-") -> -8195.5 | AW17: =IFERROR(AU17/AT17,"-") -> 0 | AX17: ='14. ГП Благовещенск (Ам ГПЗ)'!BS31+'14. ГП Благовещенск (Ам ГПЗ)'!BS33 -> 3258 | AY17: ='14. ГП Благовещенск (Ам ГПЗ)'!BU31+'14. ГП Благовещенск (Ам ГПЗ)'!BU33 -> 0 | AZ17: =IFERROR(AY17-AX17,"-") -> -3258 | BA17: =IFERROR(AY17/AX17,"-") -> 0 | BB17: ='14. ГП Благовещенск (Ам ГПЗ)'!BY31+'14. ГП Благовещенск (Ам ГПЗ)'!BY33 -> 3258.1 | BC17: ='14. ГП Благовещенск (Ам ГПЗ)'!CA31+'14. ГП Благовещенск (Ам ГПЗ)'!CA33 -> 0 | BD17: =IFERROR(BC17-BB17,"-") -> -3258.1 | BE17: =IFERROR(BC17/BB17,"-") -> 0 | BF17: ='14. ГП Благовещенск (Ам ГПЗ)'!CE31+'14. ГП Благовещенск (Ам ГПЗ)'!CE33 -> 1679.4 | BG17: ='14. ГП Благовещенск (Ам ГПЗ)'!CG31+'14. ГП Благовещенск (Ам ГПЗ)'!CG33 -> 0 | BH17: =IFERROR(BG17-BF17,"-") -> -1679.4 | BI17: =IFERROR(BG17/BF17,"-") -> 0 | BJ17: =BN17+BR17+BV17 -> 9632.5 | BK17: =BO17+BS17+BW17 -> 0 | BL17: =IFERROR(BK17-BJ17,"-") -> -9632.5 | BM17: =IFERROR(BK17/BJ17,"-") -> 0 | BN17: ='14. ГП Благовещенск (Ам ГПЗ)'!CQ31+'14. ГП Благовещенск (Ам ГПЗ)'!CQ33 -> 3221.4 | BO17: ='14. ГП Благовещенск (Ам ГПЗ)'!CS31+'14. ГП Благовещенск (Ам ГПЗ)'!CS33 -> 0 | BP17: =IFERROR(BO17-BN17,"-") -> -3221.4 | BQ17: =IFERROR(BO17/BN17,"-") -> 0 | BR17: ='14. ГП Благовещенск (Ам ГПЗ)'!CW31+'14. ГП Благовещенск (Ам ГПЗ)'!CW33 -> 3153 | BS17: ='14. ГП Благовещенск (Ам ГПЗ)'!CY31+'14. ГП Благовещенск (Ам ГПЗ)'!CY33 -> 0 | BT17: =IFERROR(BS17-BR17,"-") -> -3153 | BU17: =IFERROR(BS17/BR17,"-") -> 0 | BV17: ='14. ГП Благовещенск (Ам ГПЗ)'!DC31+'14. ГП Благовещенск (Ам ГПЗ)'!DC33 -> 3258.1 | BW17: ='14. ГП Благовещенск (Ам ГПЗ)'!DE31+'14. ГП Благовещенск (Ам ГПЗ)'!DE33 -> 0 | BX17: =IFERROR(BW17-BV17,"-") -> -3258.1 | BY17: =IFERROR(BW17/BV17,"-") -> 0
C18: Амурский ГПЗ | G18: 14_100335074+14_100335076 | I18: млн куб.м. | J18: =N18+AD18+AT18+BJ18 -> 35384.8 | K18: =O18+AE18+AU18+BK18 -> 0 | L18: =IFERROR(K18-J18,"-") -> -35384.8 | M18: =IFERROR(K18/J18,"-") -> 0 | N18: =R18+V18+Z18 -> 8849.4 | O18: =S18+W18+AA18 -> 0 | P18: =IFERROR(O18-N18,"-") -> -8849.4 | Q18: =IFERROR(O18/N18,"-") -> 0 | R18: ='14. ГП Благовещенск (Ам ГПЗ)'!W31+'14. ГП Благовещенск (Ам ГПЗ)'!W33 -> 3189.9 | S18: ='14. ГП Благовещенск (Ам ГПЗ)'!Y31+'14. ГП Благовещенск (Ам ГПЗ)'!Y33 -> 0 | T18: =IFERROR(S18-R18,"-") -> -3189.9 | U18: =IFERROR(S18/R18,"-") -> 0 | V18: ='14. ГП Благовещенск (Ам ГПЗ)'!AC31+'14. ГП Благовещенск (Ам ГПЗ)'!AC33 -> 2881.1 | W18: ='14. ГП Благовещенск (Ам ГПЗ)'!AE31+'14. ГП Благовещенск (Ам ГПЗ)'!AE33 -> 0 | X18: =IFERROR(W18-V18,"-") -> -2881.1 | Y18: =IFERROR(W18/V18,"-") -> 0 | Z18: ='14. ГП Благовещенск (Ам ГПЗ)'!AI31+'14. ГП Благовещенск (Ам ГПЗ)'!AI33 -> 2778.4 | AA18: ='14. ГП Благовещенск (Ам ГПЗ)'!AK31+'14. ГП Благовещенск (Ам ГПЗ)'!AK33 -> 0 | AB18: =IFERROR(AA18-Z18,"-") -> -2778.4 | AC18: =IFERROR(AA18/Z18,"-") -> 0 | AD18: =AH18+AL18+AP18 -> 8707.4 | AE18: =AI18+AM18+AQ18 -> 0 | AF18: =IFERROR(AE18-AD18,"-") -> -8707.4 | AG18: =IFERROR(AE18/AD18,"-") -> 0 | AH18: ='14. ГП Благовещенск (Ам ГПЗ)'!AU31+'14. ГП Благовещенск (Ам ГПЗ)'!AU33 -> 2355.9 | AI18: ='14. ГП Благовещенск (Ам ГПЗ)'!AW31+'14. ГП Благовещенск (Ам ГПЗ)'!AW33 -> 0 | AJ18: =IFERROR(AI18-AH18,"-") -> -2355.9 | AK18: =IFERROR(AI18/AH18,"-") -> 0 | AL18: ='14. ГП Благовещенск (Ам ГПЗ)'!BA31+'14. ГП Благовещенск (Ам ГПЗ)'!BA33 -> 3198.6 | AM18: ='14. ГП Благовещенск (Ам ГПЗ)'!BC31+'14. ГП Благовещенск (Ам ГПЗ)'!BC33 -> 0 | AN18: =IFERROR(AM18-AL18,"-") -> -3198.6 | AO18: =IFERROR(AM18/AL18,"-") -> 0 | AP18: ='14. ГП Благовещенск (Ам ГПЗ)'!BG31+'14. ГП Благовещенск (Ам ГПЗ)'!BG33 -> 3152.9 | AQ18: ='14. ГП Благовещенск (Ам ГПЗ)'!BI31+'14. ГП Благовещенск (Ам ГПЗ)'!BI33 -> 0 | AR18: =IFERROR(AQ18-AP18,"-") -> -3152.9 | AS18: =IFERROR(AQ18/AP18,"-") -> 0 | AT18: =AX18+BB18+BF18 -> 8195.5 | AU18: =AY18+BC18+BG18 -> 0 | AV18: =IFERROR(AU18-AT18,"-") -> -8195.5 | AW18: =IFERROR(AU18/AT18,"-") -> 0 | AX18: ='14. ГП Благовещенск (Ам ГПЗ)'!BS31+'14. ГП Благовещенск (Ам ГПЗ)'!BS33 -> 3258 | AY18: ='14. ГП Благовещенск (Ам ГПЗ)'!BU31+'14. ГП Благовещенск (Ам ГПЗ)'!BU33 -> 0 | AZ18: =IFERROR(AY18-AX18,"-") -> -3258 | BA18: =IFERROR(AY18/AX18,"-") -> 0 | BB18: ='14. ГП Благовещенск (Ам ГПЗ)'!BY31+'14. ГП Благовещенск (Ам ГПЗ)'!BY33 -> 3258.1 | BC18: ='14. ГП Благовещенск (Ам ГПЗ)'!CA31+'14. ГП Благовещенск (Ам ГПЗ)'!CA33 -> 0 | BD18: =IFERROR(BC18-BB18,"-") -> -3258.1 | BE18: =IFERROR(BC18/BB18,"-") -> 0 | BF18: ='14. ГП Благовещенск (Ам ГПЗ)'!CE31+'14. ГП Благовещенск (Ам ГПЗ)'!CE33 -> 1679.4 | BG18: ='14. ГП Благовещенск (Ам ГПЗ)'!CG31+'14. ГП Благовещенск (Ам ГПЗ)'!CG33 -> 0 | BH18: =IFERROR(BG18-BF18,"-") -> -1679.4 | BI18: =IFERROR(BG18/BF18,"-") -> 0 | BJ18: =BN18+BR18+BV18 -> 9632.5 | BK18: =BO18+BS18+BW18 -> 0 | BL18: =IFERROR(BK18-BJ18,"-") -> -9632.5 | BM18: =IFERROR(BK18/BJ18,"-") -> 0 | BN18: ='14. ГП Благовещенск (Ам ГПЗ)'!CQ31+'14. ГП Благовещенск (Ам ГПЗ)'!CQ33 -> 3221.4 | BO18: ='14. ГП Благовещенск (Ам ГПЗ)'!CS31+'14. ГП Благовещенск (Ам ГПЗ)'!CS33 -> 0 | BP18: =IFERROR(BO18-BN18,"-") -> -3221.4 | BQ18: =IFERROR(BO18/BN18,"-") -> 0 | BR18: ='14. ГП Благовещенск (Ам ГПЗ)'!CW31+'14. ГП Благовещенск (Ам ГПЗ)'!CW33 -> 3153 | BS18: ='14. ГП Благовещенск (Ам ГПЗ)'!CY31+'14. ГП Благовещенск (Ам ГПЗ)'!CY33 -> 0 | BT18: =IFERROR(BS18-BR18,"-") -> -3153 | BU18: =IFERROR(BS18/BR18,"-") -> 0 | BV18: ='14. ГП Благовещенск (Ам ГПЗ)'!DC31+'14. ГП Благовещенск (Ам ГПЗ)'!DC33 -> 3258.1 | BW18: ='14. ГП Благовещенск (Ам ГПЗ)'!DE31+'14. ГП Благовещенск (Ам ГПЗ)'!DE33 -> 0 | BX18: =IFERROR(BW18-BV18,"-") -> -3258.1 | BY18: =IFERROR(BW18/BV18,"-") -> 0
C19: Газпром СПГ Портовая | I19: млн куб.м.
C20: КСПГ Портовая | I20: млн куб.м.
B21: 1.1 | C21: Газпром | G21: 3_100330008+1_1003335807+14_100335074 | I21: млн куб.м. | J21: =N21+AD21+AT21+BJ21 -> 47078.8 | K21: =O21+AE21+AU21+BK21 -> 0 | L21: =IFERROR(K21-J21,"-") -> -47078.8 | M21: =IFERROR(K21/J21,"-") -> 0 | N21: =R21+V21+Z21 -> 11801.2 | O21: =S21+W21+AA21 -> 0 | P21: =IFERROR(O21-N21,"-") -> -11801.2 | Q21: =IFERROR(O21/N21,"-") -> 0 | R21: ='3. ГПП-СГПЗ'!W16+'1. ГПП-АГПЗ+'!W22+'14. ГП Благовещенск (Ам ГПЗ)'!W31 -> 4206.5 | S21: ='3. ГПП-СГПЗ'!Y16+'1. ГПП-АГПЗ+'!Y22+'14. ГП Благовещенск (Ам ГПЗ)'!Y31 -> 0 | T21: =IFERROR(S21-R21,"-") -> -4206.5 | U21: =IFERROR(S21/R21,"-") -> 0 | V21: ='3. ГПП-СГПЗ'!AC16+'1. ГПП-АГПЗ+'!AC22+'14. ГП Благовещенск (Ам ГПЗ)'!AC31 -> 3799.3 | W21: ='3. ГПП-СГПЗ'!AE16+'1. ГПП-АГПЗ+'!AE22+'14. ГП Благовещенск (Ам ГПЗ)'!AE31 -> 0 | X21: =IFERROR(W21-V21,"-") -> -3799.3 | Y21: =IFERROR(W21/V21,"-") -> 0 | Z21: ='3. ГПП-СГПЗ'!AI16+'1. ГПП-АГПЗ+'!AI22+'14. ГП Благовещенск (Ам ГПЗ)'!AI31 -> 3795.4 | AA21: ='3. ГПП-СГПЗ'!AK16+'1. ГПП-АГПЗ+'!AK22+'14. ГП Благовещенск (Ам ГПЗ)'!AK31 -> 0 | AB21: =IFERROR(AA21-Z21,"-") -> -3795.4 | AC21: =IFERROR(AA21/Z21,"-") -> 0 | AD21: =AH21+AL21+AP21 -> 11018 | AE21: =AI21+AM21+AQ21 -> 0 | AF21: =IFERROR(AE21-AD21,"-") -> -11018 | AG21: =IFERROR(AE21/AD21,"-") -> 0 | AH21: ='3. ГПП-СГПЗ'!AU16+'1. ГПП-АГПЗ+'!AU22+'14. ГП Благовещенск (Ам ГПЗ)'!AU31 -> 3262.9 | AI21: ='3. ГПП-СГПЗ'!AW16+'1. ГПП-АГПЗ+'!AW22+'14. ГП Благовещенск (Ам ГПЗ)'!AW31 -> 0 | AJ21: =IFERROR(AI21-AH21,"-") -> -3262.9 | AK21: =IFERROR(AI21/AH21,"-") -> 0 | AL21: ='3. ГПП-СГПЗ'!BA16+'1. ГПП-АГПЗ+'!BA22+'14. ГП Благовещенск (Ам ГПЗ)'!BA31 -> 3955.4 | AM21: ='3. ГПП-СГПЗ'!BC16+'1. ГПП-АГПЗ+'!BC22+'14. ГП Благовещенск (Ам ГПЗ)'!BC31 -> 0 | AN21: =IFERROR(AM21-AL21,"-") -> -3955.4 | AO21: =IFERROR(AM21/AL21,"-") -> 0 | AP21: ='3. ГПП-СГПЗ'!BG16+'1. ГПП-АГПЗ+'!BG22+'14. ГП Благовещенск (Ам ГПЗ)'!BG31 -> 3799.7 | AQ21: ='3. ГПП-СГПЗ'!BI16+'1. ГПП-АГПЗ+'!BI22+'14. ГП Благовещенск (Ам ГПЗ)'!BI31 -> 0 | AR21: =IFERROR(AQ21-AP21,"-") -> -3799.7 | AS21: =IFERROR(AQ21/AP21,"-") -> 0 | AT21: =AX21+BB21+BF21 -> 11384.4 | AU21: =AY21+BC21+BG21 -> 0 | AV21: =IFERROR(AU21-AT21,"-") -> -11384.4 | AW21: =IFERROR(AU21/AT21,"-") -> 0 | AX21: ='3. ГПП-СГПЗ'!BS16+'1. ГПП-АГПЗ+'!BS22+'14. ГП Благовещенск (Ам ГПЗ)'!BS31 -> 4313 | AY21: ='3. ГПП-СГПЗ'!BU16+'1. ГПП-АГПЗ+'!BU22+'14. ГП Благовещенск (Ам ГПЗ)'!BU31 -> 0 | AZ21: =IFERROR(AY21-AX21,"-") -> -4313 | BA21: =IFERROR(AY21/AX21,"-") -> 0 | BB21: ='3. ГПП-СГПЗ'!BY16+'1. ГПП-АГПЗ+'!BY22+'14. ГП Благовещенск (Ам ГПЗ)'!BY31 -> 4316.7 | BC21: ='3. ГПП-СГПЗ'!CA16+'1. ГПП-АГПЗ+'!CA22+'14. ГП Благовещенск (Ам ГПЗ)'!CA31 -> 0 | BD21: =IFERROR(BC21-BB21,"-") -> -4316.7 | BE21: =IFERROR(BC21/BB21,"-") -> 0 | BF21: ='3. ГПП-СГПЗ'!CE16+'1. ГПП-АГПЗ+'!CE22+'14. ГП Благовещенск (Ам ГПЗ)'!CE31 -> 2754.7 | BG21: ='3. ГПП-СГПЗ'!CG16+'1. ГПП-АГПЗ+'!CG22+'14. ГП Благовещенск (Ам ГПЗ)'!CG31 -> 0 | BH21: =IFERROR(BG21-BF21,"-") -> -2754.7 | BI21: =IFERROR(BG21/BF21,"-") -> 0 | BJ21: =BN21+BR21+BV21 -> 12875.2 | BK21: =BO21+BS21+BW21 -> 0 | BL21: =IFERROR(BK21-BJ21,"-") -> -12875.2 | BM21: =IFERROR(BK21/BJ21,"-") -> 0 | BN21: ='3. ГПП-СГПЗ'!CQ16+'1. ГПП-АГПЗ+'!CQ22+'14. ГП Благовещенск (Ам ГПЗ)'!CQ31 -> 4277 | BO21: ='3. ГПП-СГПЗ'!CS16+'1. ГПП-АГПЗ+'!CS22+'14. ГП Благовещенск (Ам ГПЗ)'!CS31 -> 0 | BP21: =IFERROR(BO21-BN21,"-") -> -4277 | BQ21: =IFERROR(BO21/BN21,"-") -> 0 | BR21: ='3. ГПП-СГПЗ'!CW16+'1. ГПП-АГПЗ+'!CW22+'14. ГП Благовещенск (Ам ГПЗ)'!CW31 -> 4229.4 | BS21: ='3. ГПП-СГПЗ'!CY16+'1. ГПП-АГПЗ+'!CY22+'14. ГП Благовещенск (Ам ГПЗ)'!CY31 -> 0 | BT21: =IFERROR(BS21-BR21,"-") -> -4229.4 | BU21: =IFERROR(BS21/BR21,"-") -> 0 | BV21: ='3. ГПП-СГПЗ'!DC16+'1. ГПП-АГПЗ+'!DC22+'14. ГП Благовещенск (Ам ГПЗ)'!DC31 -> 4368.8 | BW21: ='3. ГПП-СГПЗ'!DE16+'1. ГПП-АГПЗ+'!DE22+'14. ГП Благовещенск (Ам ГПЗ)'!DE31 -> 0 | BX21: =IFERROR(BW21-BV21,"-") -> -4368.8 | BY21: =IFERROR(BW21/BV21,"-") -> 0
C22: Газпром переработка | G22: 3_100330008+1_1003335807 | I22: млн куб.м. | J22: =N22+AD22+AT22+BJ22 -> 11694 | K22: =O22+AE22+AU22+BK22 -> 0 | L22: =IFERROR(K22-J22,"-") -> -11694 | M22: =IFERROR(K22/J22,"-") -> 0 | N22: =R22+V22+Z22 -> 2951.8 | O22: =S22+W22+AA22 -> 0 | P22: =IFERROR(O22-N22,"-") -> -2951.8 | Q22: =IFERROR(O22/N22,"-") -> 0 | R22: ='3. ГПП-СГПЗ'!W16+'1. ГПП-АГПЗ+'!W22 -> 1016.6 | S22: ='3. ГПП-СГПЗ'!Y16+'1. ГПП-АГПЗ+'!Y22 -> 0 | T22: =IFERROR(S22-R22,"-") -> -1016.6 | U22: =IFERROR(S22/R22,"-") -> 0 | V22: ='3. ГПП-СГПЗ'!AC16+'1. ГПП-АГПЗ+'!AC22 -> 918.2 | W22: ='3. ГПП-СГПЗ'!AE16+'1. ГПП-АГПЗ+'!AE22 -> 0 | X22: =IFERROR(W22-V22,"-") -> -918.2 | Y22: =IFERROR(W22/V22,"-") -> 0 | Z22: ='3. ГПП-СГПЗ'!AI16+'1. ГПП-АГПЗ+'!AI22 -> 1017 | AA22: ='3. ГПП-СГПЗ'!AK16+'1. ГПП-АГПЗ+'!AK22 -> 0 | AB22: =IFERROR(AA22-Z22,"-") -> -1017 | AC22: =IFERROR(AA22/Z22,"-") -> 0 | AD22: =AH22+AL22+AP22 -> 2310.6 | AE22: =AI22+AM22+AQ22 -> 0 | AF22: =IFERROR(AE22-AD22,"-") -> -2310.6 | AG22: =IFERROR(AE22/AD22,"-") -> 0 | AH22: ='3. ГПП-СГПЗ'!AU16+'1. ГПП-АГПЗ+'!AU22 -> 907 | AI22: ='3. ГПП-СГПЗ'!AW16+'1. ГПП-АГПЗ+'!AW22 -> 0 | AJ22: =IFERROR(AI22-AH22,"-") -> -907 | AK22: =IFERROR(AI22/AH22,"-") -> 0 | AL22: ='3. ГПП-СГПЗ'!BA16+'1. ГПП-АГПЗ+'!BA22 -> 756.8 | AM22: ='3. ГПП-СГПЗ'!BC16+'1. ГПП-АГПЗ+'!BC22 -> 0 | AN22: =IFERROR(AM22-AL22,"-") -> -756.8 | AO22: =IFERROR(AM22/AL22,"-") -> 0 | AP22: ='3. ГПП-СГПЗ'!BG16+'1. ГПП-АГПЗ+'!BG22 -> 646.8 | AQ22: ='3. ГПП-СГПЗ'!BI16+'1. ГПП-АГПЗ+'!BI22 -> 0 | AR22: =IFERROR(AQ22-AP22,"-") -> -646.8 | AS22: =IFERROR(AQ22/AP22,"-") -> 0 | AT22: =AX22+BB22+BF22 -> 3188.9 | AU22: =AY22+BC22+BG22 -> 0 | AV22: =IFERROR(AU22-AT22,"-") -> -3188.9 | AW22: =IFERROR(AU22/AT22,"-") -> 0 | AX22: ='3. ГПП-СГПЗ'!BS16+'1. ГПП-АГПЗ+'!BS22 -> 1055 | AY22: ='3. ГПП-СГПЗ'!BU16+'1. ГПП-АГПЗ+'!BU22 -> 0 | AZ22: =IFERROR(AY22-AX22,"-") -> -1055 | BA22: =IFERROR(AY22/AX22,"-") -> 0 | BB22: ='3. ГПП-СГПЗ'!BY16+'1. ГПП-АГПЗ+'!BY22 -> 1058.6 | BC22: ='3. ГПП-СГПЗ'!CA16+'1. ГПП-АГПЗ+'!CA22 -> 0 | BD22: =IFERROR(BC22-BB22,"-") -> -1058.6 | BE22: =IFERROR(BC22/BB22,"-") -> 0 | BF22: ='3. ГПП-СГПЗ'!CE16+'1. ГПП-АГПЗ+'!CE22 -> 1075.3 | BG22: ='3. ГПП-СГПЗ'!CG16+'1. ГПП-АГПЗ+'!CG22 -> 0 | BH22: =IFERROR(BG22-BF22,"-") -> -1075.3 | BI22: =IFERROR(BG22/BF22,"-") -> 0 | BJ22: =BN22+BR22+BV22 -> 3242.7 | BK22: =BO22+BS22+BW22 -> 0 | BL22: =IFERROR(BK22-BJ22,"-") -> -3242.7 | BM22: =IFERROR(BK22/BJ22,"-") -> 0 | BN22: ='3. ГПП-СГПЗ'!CQ16+'1. ГПП-АГПЗ+'!CQ22 -> 1055.6 | BO22: ='3. ГПП-СГПЗ'!CS16+'1. ГПП-АГПЗ+'!CS22 -> 0 | BP22: =IFERROR(BO22-BN22,"-") -> -1055.6 | BQ22: =IFERROR(BO22/BN22,"-") -> 0 | BR22: ='3. ГПП-СГПЗ'!CW16+'1. ГПП-АГПЗ+'!CW22 -> 1076.4 | BS22: ='3. ГПП-СГПЗ'!CY16+'1. ГПП-АГПЗ+'!CY22 -> 0 | BT22: =IFERROR(BS22-BR22,"-") -> -1076.4 | BU22: =IFERROR(BS22/BR22,"-") -> 0 | BV22: ='3. ГПП-СГПЗ'!DC16+'1. ГПП-АГПЗ+'!DC22 -> 1110.7 | BW22: ='3. ГПП-СГПЗ'!DE16+'1. ГПП-АГПЗ+'!DE22 -> 0 | BX22: =IFERROR(BW22-BV22,"-") -> -1110.7 | BY22: =IFERROR(BW22/BV22,"-") -> 0
C23: Астраханский ГПЗ | G23: 1_1003335807 | I23: млн куб.м. | J23: =N23+AD23+AT23+BJ23 -> 9676.5 | K23: =O23+AE23+AU23+BK23 -> 0 | L23: =IFERROR(K23-J23,"-") -> -9676.5 | M23: =IFERROR(K23/J23,"-") -> 0 | N23: =R23+V23+Z23 -> 2427.6 | O23: =S23+W23+AA23 -> 0 | P23: =IFERROR(O23-N23,"-") -> -2427.6 | Q23: =IFERROR(O23/N23,"-") -> 0 | R23: ='1. ГПП-АГПЗ+'!W22 -> 836.1 | S23: ='1. ГПП-АГПЗ+'!Y22 -> 0 | T23: =IFERROR(S23-R23,"-") -> -836.1 | U23: =IFERROR(S23/R23,"-") -> 0 | V23: ='1. ГПП-АГПЗ+'!AC22 -> 755.3 | W23: ='1. ГПП-АГПЗ+'!AE22 -> 0 | X23: =IFERROR(W23-V23,"-") -> -755.3 | Y23: =IFERROR(W23/V23,"-") -> 0 | Z23: ='1. ГПП-АГПЗ+'!AI22 -> 836.2 | AA23: ='1. ГПП-АГПЗ+'!AK22 -> 0 | AB23: =IFERROR(AA23-Z23,"-") -> -836.2 | AC23: =IFERROR(AA23/Z23,"-") -> 0 | AD23: =AH23+AL23+AP23 -> 1851.5 | AE23: =AI23+AM23+AQ23 -> 0 | AF23: =IFERROR(AE23-AD23,"-") -> -1851.5 | AG23: =IFERROR(AE23/AD23,"-") -> 0 | AH23: ='1. ГПП-АГПЗ+'!AU22 -> 809.2 | AI23: ='1. ГПП-АГПЗ+'!AW22 -> 0 | AJ23: =IFERROR(AI23-AH23,"-") -> -809.2 | AK23: =IFERROR(AI23/AH23,"-") -> 0 | AL23: ='1. ГПП-АГПЗ+'!BA22 -> 574.9 | AM23: ='1. ГПП-АГПЗ+'!BC22 -> 0 | AN23: =IFERROR(AM23-AL23,"-") -> -574.9 | AO23: =IFERROR(AM23/AL23,"-") -> 0 | AP23: ='1. ГПП-АГПЗ+'!BG22 -> 467.4 | AQ23: ='1. ГПП-АГПЗ+'!BI22 -> 0 | AR23: =IFERROR(AQ23-AP23,"-") -> -467.4 | AS23: =IFERROR(AQ23/AP23,"-") -> 0 | AT23: =AX23+BB23+BF23 -> 2641.8 | AU23: =AY23+BC23+BG23 -> 0 | AV23: =IFERROR(AU23-AT23,"-") -> -2641.8 | AW23: =IFERROR(AU23/AT23,"-") -> 0 | AX23: ='1. ГПП-АГПЗ+'!BS22 -> 869.4 | AY23: ='1. ГПП-АГПЗ+'!BU22 -> 0 | AZ23: =IFERROR(AY23-AX23,"-") -> -869.4 | BA23: =IFERROR(AY23/AX23,"-") -> 0 | BB23: ='1. ГПП-АГПЗ+'!BY22 -> 873.4 | BC23: ='1. ГПП-АГПЗ+'!CA22 -> 0 | BD23: =IFERROR(BC23-BB23,"-") -> -873.4 | BE23: =IFERROR(BC23/BB23,"-") -> 0 | BF23: ='1. ГПП-АГПЗ+'!CE22 -> 899 | BG23: ='1. ГПП-АГПЗ+'!CG22 -> 0 | BH23: =IFERROR(BG23-BF23,"-") -> -899 | BI23: =IFERROR(BG23/BF23,"-") -> 0 | BJ23: =BN23+BR23+BV23 -> 2755.6 | BK23: =BO23+BS23+BW23 -> 0 | BL23: =IFERROR(BK23-BJ23,"-") -> -2755.6 | BM23: =IFERROR(BK23/BJ23,"-") -> 0 | BN23: ='1. ГПП-АГПЗ+'!CQ22 -> 929.1 | BO23: ='1. ГПП-АГПЗ+'!CS22 -> 0 | BP23: =IFERROR(BO23-BN23,"-") -> -929.1 | BQ23: =IFERROR(BO23/BN23,"-") -> 0 | BR23: ='1. ГПП-АГПЗ+'!CW22 -> 899.1 | BS23: ='1. ГПП-АГПЗ+'!CY22 -> 0 | BT23: =IFERROR(BS23-BR23,"-") -> -899.1 | BU23: =IFERROR(BS23/BR23,"-") -> 0 | BV23: ='1. ГПП-АГПЗ+'!DC22 -> 927.4 | BW23: ='1. ГПП-АГПЗ+'!DE22 -> 0 | BX23: =IFERROR(BW23-BV23,"-") -> -927.4 | BY23: =IFERROR(BW23/BV23,"-") -> 0
C24: Сосногорский ГПЗ | G24: 3_100330008 | I24: млн куб.м. | J24: =N24+AD24+AT24+BJ24 -> 2017.5 | K24: =O24+AE24+AU24+BK24 -> 0 | L24: =IFERROR(K24-J24,"-") -> -2017.5 | M24: =IFERROR(K24/J24,"-") -> 0 | N24: =R24+V24+Z24 -> 524.2 | O24: =S24+W24+AA24 -> 0 | P24: =IFERROR(O24-N24,"-") -> -524.2 | Q24: =IFERROR(O24/N24,"-") -> 0 | R24: ='3. ГПП-СГПЗ'!W16 -> 180.5 | S24: ='3. ГПП-СГПЗ'!Y16 -> 0 | T24: =IFERROR(S24-R24,"-") -> -180.5 | U24: =IFERROR(S24/R24,"-") -> 0 | V24: ='3. ГПП-СГПЗ'!AC16 -> 162.9 | W24: ='3. ГПП-СГПЗ'!AE16 -> 0 | X24: =IFERROR(W24-V24,"-") -> -162.9 | Y24: =IFERROR(W24/V24,"-") -> 0 | Z24: ='3. ГПП-СГПЗ'!AI16 -> 180.8 | AA24: ='3. ГПП-СГПЗ'!AK16 -> 0 | AB24: =IFERROR(AA24-Z24,"-") -> -180.8 | AC24: =IFERROR(AA24/Z24,"-") -> 0 | AD24: =AH24+AL24+AP24 -> 459.1 | AE24: =AI24+AM24+AQ24 -> 0 | AF24: =IFERROR(AE24-AD24,"-") -> -459.1 | AG24: =IFERROR(AE24/AD24,"-") -> 0 | AH24: ='3. ГПП-СГПЗ'!AU16 -> 97.8 | AI24: ='3. ГПП-СГПЗ'!AW16 -> 0 | AJ24: =IFERROR(AI24-AH24,"-") -> -97.8 | AK24: =IFERROR(AI24/AH24,"-") -> 0 | AL24: ='3. ГПП-СГПЗ'!BA16 -> 181.9 | AM24: ='3. ГПП-СГПЗ'!BC16 -> 0 | AN24: =IFERROR(AM24-AL24,"-") -> -181.9 | AO24: =IFERROR(AM24/AL24,"-") -> 0 | AP24: ='3. ГПП-СГПЗ'!BG16 -> 179.4 | AQ24: ='3. ГПП-СГПЗ'!BI16 -> 0 | AR24: =IFERROR(AQ24-AP24,"-") -> -179.4 | AS24: =IFERROR(AQ24/AP24,"-") -> 0 | AT24: =AX24+BB24+BF24 -> 547.1 | AU24: =AY24+BC24+BG24 -> 0 | AV24: =IFERROR(AU24-AT24,"-") -> -547.1 | AW24: =IFERROR(AU24/AT24,"-") -> 0 | AX24: ='3. ГПП-СГПЗ'!BS16 -> 185.6 | AY24: ='3. ГПП-СГПЗ'!BU16 -> 0 | AZ24: =IFERROR(AY24-AX24,"-") -> -185.6 | BA24: =IFERROR(AY24/AX24,"-") -> 0 | BB24: ='3. ГПП-СГПЗ'!BY16 -> 185.2 | BC24: ='3. ГПП-СГПЗ'!CA16 -> 0 | BD24: =IFERROR(BC24-BB24,"-") -> -185.2 | BE24: =IFERROR(BC24/BB24,"-") -> 0 | BF24: ='3. ГПП-СГПЗ'!CE16 -> 176.3 | BG24: ='3. ГПП-СГПЗ'!CG16 -> 0 | BH24: =IFERROR(BG24-BF24,"-") -> -176.3 | BI24: =IFERROR(BG24/BF24,"-") -> 0 | BJ24: =BN24+BR24+BV24 -> 487.1 | BK24: =BO24+BS24+BW24 -> 0 | BL24: =IFERROR(BK24-BJ24,"-") -> -487.1 | BM24: =IFERROR(BK24/BJ24,"-") -> 0 | BN24: ='3. ГПП-СГПЗ'!CQ16 -> 126.5 | BO24: ='3. ГПП-СГПЗ'!CS16 -> 0 | BP24: =IFERROR(BO24-BN24,"-") -> -126.5 | BQ24: =IFERROR(BO24/BN24,"-") -> 0 | BR24: ='3. ГПП-СГПЗ'!CW16 -> 177.3 | BS24: ='3. ГПП-СГПЗ'!CY16 -> 0 | BT24: =IFERROR(BS24-BR24,"-") -> -177.3 | BU24: =IFERROR(BS24/BR24,"-") -> 0 | BV24: ='3. ГПП-СГПЗ'!DC16 -> 183.3 | BW24: ='3. ГПП-СГПЗ'!DE16 -> 0 | BX24: =IFERROR(BW24-BV24,"-") -> -183.3 | BY24: =IFERROR(BW24/BV24,"-") -> 0
C25: Газпром добыча Краснодар | G25: 3_100330008 | I25: млн куб.м. | J25: =N25+AD25+AT25+BJ25 -> 2017.5 | K25: =O25+AE25+AU25+BK25 -> 0 | L25: =IFERROR(K25-J25,"-") -> -2017.5 | M25: =IFERROR(K25/J25,"-") -> 0 | N25: =R25+V25+Z25 -> 524.2 | O25: =S25+W25+AA25 -> 0 | P25: =IFERROR(O25-N25,"-") -> -524.2 | Q25: =IFERROR(O25/N25,"-") -> 0 | R25: ='3. ГПП-СГПЗ'!W16 -> 180.5 | S25: ='3. ГПП-СГПЗ'!Y16 -> 0 | T25: =IFERROR(S25-R25,"-") -> -180.5 | U25: =IFERROR(S25/R25,"-") -> 0 | V25: ='3. ГПП-СГПЗ'!AC16 -> 162.9 | W25: ='3. ГПП-СГПЗ'!AE16 -> 0 | X25: =IFERROR(W25-V25,"-") -> -162.9 | Y25: =IFERROR(W25/V25,"-") -> 0 | Z25: ='3. ГПП-СГПЗ'!AI16 -> 180.8 | AA25: ='3. ГПП-СГПЗ'!AK16 -> 0 | AB25: =IFERROR(AA25-Z25,"-") -> -180.8 | AC25: =IFERROR(AA25/Z25,"-") -> 0 | AD25: =AH25+AL25+AP25 -> 459.1 | AE25: =AI25+AM25+AQ25 -> 0 | AF25: =IFERROR(AE25-AD25,"-") -> -459.1 | AG25: =IFERROR(AE25/AD25,"-") -> 0 | AH25: ='3. ГПП-СГПЗ'!AU16 -> 97.8 | AI25: ='3. ГПП-СГПЗ'!AW16 -> 0 | AJ25: =IFERROR(AI25-AH25,"-") -> -97.8 | AK25: =IFERROR(AI25/AH25,"-") -> 0 | AL25: ='3. ГПП-СГПЗ'!BA16 -> 181.9 | AM25: ='3. ГПП-СГПЗ'!BC16 -> 0 | AN25: =IFERROR(AM25-AL25,"-") -> -181.9 | AO25: =IFERROR(AM25/AL25,"-") -> 0 | AP25: ='3. ГПП-СГПЗ'!BG16 -> 179.4 | AQ25: ='3. ГПП-СГПЗ'!BI16 -> 0 | AR25: =IFERROR(AQ25-AP25,"-") -> -179.4 | AS25: =IFERROR(AQ25/AP25,"-") -> 0 | AT25: =AX25+BB25+BF25 -> 547.1 | AU25: =AY25+BC25+BG25 -> 0 | AV25: =IFERROR(AU25-AT25,"-") -> -547.1 | AW25: =IFERROR(AU25/AT25,"-") -> 0 | AX25: ='3. ГПП-СГПЗ'!BS16 -> 185.6 | AY25: ='3. ГПП-СГПЗ'!BU16 -> 0 | AZ25: =IFERROR(AY25-AX25,"-") -> -185.6 | BA25: =IFERROR(AY25/AX25,"-") -> 0 | BB25: ='3. ГПП-СГПЗ'!BY16 -> 185.2 | BC25: ='3. ГПП-СГПЗ'!CA16 -> 0 | BD25: =IFERROR(BC25-BB25,"-") -> -185.2 | BE25: =IFERROR(BC25/BB25,"-") -> 0 | BF25: ='3. ГПП-СГПЗ'!CE16 -> 176.3 | BG25: ='3. ГПП-СГПЗ'!CG16 -> 0 | BH25: =IFERROR(BG25-BF25,"-") -> -176.3 | BI25: =IFERROR(BG25/BF25,"-") -> 0 | BJ25: =BN25+BR25+BV25 -> 487.1 | BK25: =BO25+BS25+BW25 -> 0 | BL25: =IFERROR(BK25-BJ25,"-") -> -487.1 | BM25: =IFERROR(BK25/BJ25,"-") -> 0 | BN25: ='3. ГПП-СГПЗ'!CQ16 -> 126.5 | BO25: ='3. ГПП-СГПЗ'!CS16 -> 0 | BP25: =IFERROR(BO25-BN25,"-") -> -126.5 | BQ25: =IFERROR(BO25/BN25,"-") -> 0 | BR25: ='3. ГПП-СГПЗ'!CW16 -> 177.3 | BS25: ='3. ГПП-СГПЗ'!CY16 -> 0 | BT25: =IFERROR(BS25-BR25,"-") -> -177.3 | BU25: =IFERROR(BS25/BR25,"-") -> 0 | BV25: ='3. ГПП-СГПЗ'!DC16 -> 183.3 | BW25: ='3. ГПП-СГПЗ'!DE16 -> 0 | BX25: =IFERROR(BW25-BV25,"-") -> -183.3 | BY25: =IFERROR(BW25/BV25,"-") -> 0
C26: Газпром переработка Благовещенск | G26: 14_100335074 | I26: млн куб.м. | J26: =N26+AD26+AT26+BJ26 -> 35384.8 | K26: =O26+AE26+AU26+BK26 -> 0 | L26: =IFERROR(K26-J26,"-") -> -35384.8 | M26: =IFERROR(K26/J26,"-") -> 0 | N26: =R26+V26+Z26 -> 8849.4 | O26: =S26+W26+AA26 -> 0 | P26: =IFERROR(O26-N26,"-") -> -8849.4 | Q26: =IFERROR(O26/N26,"-") -> 0 | R26: ='14. ГП Благовещенск (Ам ГПЗ)'!W31 -> 3189.9 | S26: ='14. ГП Благовещенск (Ам ГПЗ)'!Y31 -> 0 | T26: =IFERROR(S26-R26,"-") -> -3189.9 | U26: =IFERROR(S26/R26,"-") -> 0 | V26: ='14. ГП Благовещенск (Ам ГПЗ)'!AC31 -> 2881.1 | W26: ='14. ГП Благовещенск (Ам ГПЗ)'!AE31 -> 0 | X26: =IFERROR(W26-V26,"-") -> -2881.1 | Y26: =IFERROR(W26/V26,"-") -> 0 | Z26: ='14. ГП Благовещенск (Ам ГПЗ)'!AI31 -> 2778.4 | AA26: ='14. ГП Благовещенск (Ам ГПЗ)'!AK31 -> 0 | AB26: =IFERROR(AA26-Z26,"-") -> -2778.4 | AC26: =IFERROR(AA26/Z26,"-") -> 0 | AD26: =AH26+AL26+AP26 -> 8707.4 | AE26: =AI26+AM26+AQ26 -> 0 | AF26: =IFERROR(AE26-AD26,"-") -> -8707.4 | AG26: =IFERROR(AE26/AD26,"-") -> 0 | AH26: ='14. ГП Благовещенск (Ам ГПЗ)'!AU31 -> 2355.9 | AI26: ='14. ГП Благовещенск (Ам ГПЗ)'!AW31 -> 0 | AJ26: =IFERROR(AI26-AH26,"-") -> -2355.9 | AK26: =IFERROR(AI26/AH26,"-") -> 0 | AL26: ='14. ГП Благовещенск (Ам ГПЗ)'!BA31 -> 3198.6 | AM26: ='14. ГП Благовещенск (Ам ГПЗ)'!BC31 -> 0 | AN26: =IFERROR(AM26-AL26,"-") -> -3198.6 | AO26: =IFERROR(AM26/AL26,"-") -> 0 | AP26: ='14. ГП Благовещенск (Ам ГПЗ)'!BG31 -> 3152.9 | AQ26: ='14. ГП Благовещенск (Ам ГПЗ)'!BI31 -> 0 | AR26: =IFERROR(AQ26-AP26,"-") -> -3152.9 | AS26: =IFERROR(AQ26/AP26,"-") -> 0 | AT26: =AX26+BB26+BF26 -> 8195.5 | AU26: =AY26+BC26+BG26 -> 0 | AV26: =IFERROR(AU26-AT26,"-") -> -8195.5 | AW26: =IFERROR(AU26/AT26,"-") -> 0 | AX26: ='14. ГП Благовещенск (Ам ГПЗ)'!BS31 -> 3258 | AY26: ='14. ГП Благовещенск (Ам ГПЗ)'!BU31 -> 0 | AZ26: =IFERROR(AY26-AX26,"-") -> -3258 | BA26: =IFERROR(AY26/AX26,"-") -> 0 | BB26: ='14. ГП Благовещенск (Ам ГПЗ)'!BY31 -> 3258.1 | BC26: ='14. ГП Благовещенск (Ам ГПЗ)'!CA31 -> 0 | BD26: =IFERROR(BC26-BB26,"-") -> -3258.1 | BE26: =IFERROR(BC26/BB26,"-") -> 0 | BF26: ='14. ГП Благовещенск (Ам ГПЗ)'!CE31 -> 1679.4 | BG26: ='14. ГП Благовещенск (Ам ГПЗ)'!CG31 -> 0 | BH26: =IFERROR(BG26-BF26,"-") -> -1679.4 | BI26: =IFERROR(BG26/BF26,"-") -> 0 | BJ26: =BN26+BR26+BV26 -> 9632.5 | BK26: =BO26+BS26+BW26 -> 0 | BL26: =IFERROR(BK26-BJ26,"-") -> -9632.5 | BM26: =IFERROR(BK26/BJ26,"-") -> 0 | BN26: ='14. ГП Благовещенск (Ам ГПЗ)'!CQ31 -> 3221.4 | BO26: ='14. ГП Благовещенск (Ам ГПЗ)'!CS31 -> 0 | BP26: =IFERROR(BO26-BN26,"-") -> -3221.4 | BQ26: =IFERROR(BO26/BN26,"-") -> 0 | BR26: ='14. ГП Благовещенск (Ам ГПЗ)'!CW31 -> 3153 | BS26: ='14. ГП Благовещенск (Ам ГПЗ)'!CY31 -> 0 | BT26: =IFERROR(BS26-BR26,"-") -> -3153 | BU26: =IFERROR(BS26/BR26,"-") -> 0 | BV26: ='14. ГП Благовещенск (Ам ГПЗ)'!DC31 -> 3258.1 | BW26: ='14. ГП Благовещенск (Ам ГПЗ)'!DE31 -> 0 | BX26: =IFERROR(BW26-BV26,"-") -> -3258.1 | BY26: =IFERROR(BW26/BV26,"-") -> 0
