Workbook
Name _INTERNAL_KEY1: Лист1!$5:$5
Name _INTERNAL_KEY2: 'Лист1 (2)'!$5:$5
Name _SET_ROW1: Лист1!$C:$H
Name _SET_ROW2: 'Лист1 (2)'!$C:$H
Name _SHEET_ID1: 1
Name _SHEET_ID2: 1
Name _SHEET_ID20: 1
Name _SHEET_ID21: 1
Name _SHEET_ID22: 1
Name _STATIC_REP_INTERNAL_KEY1: 'Отчёт КПД ДО'!$5:$5
Name _STATIC_REP_SET_ROW1: 'Отчёт КПД ДО'!$C:$D
Name _SUM_REP_INTERNAL_KEY1: 'План общий '!$5:$5
Name _SUM_REP_INTERNAL_KEY2: 'Баланс ЗС'!$5:$5
Name _SUM_REP_SET_ROW1: 'План общий '!$C:$H
Name _SUM_REP_SET_ROW2: 'Баланс ЗС'!$C:$H

Sheet План общий 
B2: Показатели | C2: Внутренние настройки листа | I2: Ед. изм.
C3: Ключ статьи | D3: Ключ спец расчётов | E3: Ключ ввод данных | F3: Формула месяц | G3: Формула % Выхода | H3: Строка проверка
B6: Объемы реализации ЖУВ | E6: 1 | I6: тыс.т
B7: в т.ч. на экспорт | E7: 2 | I7: тыс.т
B8: в т.ч. на внутренний рынок | E8: 3 | I8: тыс.т
B9: Поступление денежных средств | E9: 4 | I9: млрд руб. с НДС
B10: в т.ч. на экспорт | E10: 5 | I10: млрд руб. с НДС
B11: в т.ч. на внутренний рынок | E11: 6 | I11: млрд руб. с НДС
B12: Объем производства ООО "ГПП" для реализации ПАО "Газпром" | E12: 7 | I12: тыс.т
B13: Объем реализации продукции ООО "ГПП" с учетом остатков | E13: 8 | I13: тыс.т
E14: 9
B15: Раздел 1. Прогнозные показатели по переработке углеводородного сырья и производству продукции | E15: 10
B16: ПАО "Газпром" и основных дочерних обществ | E16: 11
B17: CЫРЬЕ | E17: 12
E18: 13
B19: 1. Переработка газа на ГПЗ-всего | F19: 1_1003335807+2_100332038+2_100332040+2_100332042+2_100332044+2_100332916+2_100332944+2_100335129+3_100330552+3_100330008+14_100335074+14_100335076 | I19: млн куб.м.
B20: без СПГ Портовой | E20: 14 | I20: млн куб.м.
B21: Газпром переработка | F21: 1_1003335807+2_100332038+2_100332040+2_100332042+2_100332044+2_100332916+2_100332944+2_100335129+3_100330552+3_100330008 | I21: млн куб.м.
B22: Астраханский ГПЗ | F22: 1_1003335807 | I22: млн куб.м.
B23: Оренбургский ГХК | F23: 2_100332038+2_100332040+2_100332042+2_100332044+2_100332916+2_100332944+2_100335129 | I23: млн куб.м.
B24: Сосногорский ГПЗ | F24: 3_100330552+3_100330008 | I24: млн куб.м.
B25: Газпром переработка Благовещенск | F25: 14_100335074+14_100335076 | I25: млн куб.м.
B26: Амурский ГПЗ | F26: 14_100335074+14_100335076 | I26: млн куб.м.
B27: Газпром СПГ Портовая | E27: 15 | I27: млн куб.м.
B28: КСПГ Портовая | E28: 16 | I28: млн куб.м.
B29: 1.1. Газпром | F29: 3_100330008+1_1003335807+14_100335074 | I29: млн куб.м.
B30: Газпром переработка | F30: 3_100330008+1_1003335807 | I30: млн куб.м.
B31: Астраханский ГПЗ | F31: 1_1003335807 | I31: млн куб.м.
B32: Сосногорский ГПЗ | F32: 3_100330008 | I32: млн куб.м.
B33: Газпром добыча Краснодар | F33: 3_100330008 | I33: млн куб.м.
B34: Газпром переработка Благовещенск | F34: 14_100335074 | I34: млн куб.м.
B35: Амурский ГПЗ | F35: 14_100335074 | I35: млн куб.м.
B36: Газпром СПГ Портовая | E36: 17 | I36: млн куб.м.
B37: КСПГ Портовая | E37: 18 | I37: млн куб.м.
B38: в т.ч. на ПНР | E38: 19 | I38: млн куб.м.
B39: в т.ч. СТН | E39: 20 | I39: млн куб.м.
B40: в т.ч. на переработку | E40: 21 | I40: млн куб.м.
B41: 1.2. Дочерние общества | F41: 2_100332038+2_100332040+2_100332042+2_100332044+2_100332916+2_100332944+2_100335129+3_100330552+14_100335076 | I41: млн куб.м.
B42: Газпром добыча Астрахань | F42: 0 | I42: млн куб.м.
B43: Астраханский ГПЗ | F43: 0 | I43: млн куб.м.
...

Sheet Отчёт КПД ДО
B2: Показатели | C2: Внутренние настройки листа | E2: Ед. изм. | F2: Удельный вес КПД | G2: Плановое значение | H2: Границы планового значения | J2: Фактическое значение | K2: Выполнение КПД, в % | L2: Причины отклонений фактических значений КПД от плановых значений | M2: Центр ответственности за расчёт КПД ДО
C3: формула | D3: описание
H4: пороговое | I4: максимальное
A6: 26. | B6: ООО "Газпром переработка"
B7: Контролируемые затраты | F7: 0.5 | M7: Департамент 816
B8: Объём переработки газа | C8: 1_100335807+2_100332038+2_100332040+3_100330008 | F8: 0.25 | H8: =G8*0.95 -> 0 | I8: =G8*1.1 -> 0 | K8: =G8/J8 -> #DIV/0! | M8: Департамент 816
B9: Объём переработки нестабильного газового конденсата и нефти | C9: 1_100331985+2_100332061+3_100330017+4_100331828+4_100335040+4_100331835+2_100332066+2_100332067+3_100330196+4_100335093+4_100333678+4_100331838+10_100330861 | F9: 0.25 | H9: =G9*0.95 -> 0 | I9: =G9*1.1 -> 0 | K9: =G9/J9 -> #DIV/0! | M9: Департамент 816

Sheet Баланс ЗС
B2: Показатели | C2: Внутренние настройки листа | I2: Ед. изм. | J2: 2026 | K2: 2026 | L2: 2026 | O2: 2026 год 1 квартал | P2: 2026 год 1 квартал | Q2: 2026 год 1 квартал | T2: 2026 год январь | U2: 2026 год январь | V2: 2026 год январь | Y2: 2026 год февраль | Z2: 2026 год февраль | AA2: 2026 год февраль | AD2: 2026 год март | AE2: 2026 год март | AF2: 2026 год март | AI2: 2026 год 2 квартал | AJ2: 2026 год 2 квартал | AK2: 2026 год 2 квартал | AN2: 2026 год апрель | AO2: 2026 год апрель | AP2: 2026 год апрель | AS2: 2026 год май | AT2: 2026 год май | AU2: 2026 год май | AX2: 2026 год июнь | AY2: 2026 год июнь | AZ2: 2026 год июнь | BC2: 2026 год 3 квартал | BD2: 2026 год 3 квартал | BE2: 2026 год 3 квартал | BH2: 2026 год июль | BI2: 2026 год июль | BJ2: 2026 год июль | BM2: 2026 год август | BN2: 2026 год август | BO2: 2026 год август | BR2: 2026 год сентябрь | BS2: 2026 год сентябрь | BT2: 2026 год сентябрь | BW2: 2026 год 4 квартал | BX2: 2026 год 4 квартал | BY2: 2026 год 4 квартал | CB2: 2026 год октябрь | CC2: 2026 год октябрь | CD2: 2026 год октябрь | CG2: 2026 год ноябрь | CH2: 2026 год ноябрь | CI2: 2026 год ноябрь | CL2: 2026 год декабрь | CM2: 2026 год декабрь | CN2: 2026 год декабрь
C3: Ключ статьи | D3: Ключ спец расчётов | E3: Ключ ввод данных | F3: Формула месяц | G3: Формула % Выхода | H3: Строка проверка | J3: Среднесрочн. план 2026: Вариант утвержденный | K3: Среднесрочн. план 2026 ПРЭУ: Вариант на утверждение | L3: Факт | M3: Отклонение | O3: Среднесрочн. план 2026: Вариант утвержденный | P3: Среднесрочн. план 2026 ПРЭУ: Вариант на утверждение | Q3: Факт | R3: Отклонение | T3: Среднесрочн. план 2026: Вариант утвержденный | U3: Среднесрочн. план 2026 ПРЭУ: Вариант на утверждение | V3: Факт | W3: Отклонение | Y3: Среднесрочн. план 2026: Вариант утвержденный | Z3: Среднесрочн. план 2026 ПРЭУ: Вариант на утверждение | AA3: Факт | AB3: Отклонение | AD3: Среднесрочн. план 2026: Вариант утвержденный | AE3: Среднесрочн. план 2026 ПРЭУ: Вариант на утверждение | AF3: Факт | AG3: Отклонение | AI3: Среднесрочн. план 2026: Вариант утвержденный | AJ3: Среднесрочн. план 2026 ПРЭУ: Вариант на утверждение | AK3: Факт | AL3: Отклонение | AN3: Среднесрочн. план 2026: Вариант утвержденный | AO3: Среднесрочн. план 2026 ПРЭУ: Вариант на утверждение | AP3: Факт | AQ3: Отклонение | AS3: Среднесрочн. план 2026: Вариант утвержденный | AT3: Среднесрочн. план 2026 ПРЭУ: Вариант на утверждение | AU3: Факт | AV3: Отклонение | AX3: Среднесрочн. план 2026: Вариант утвержденный | AY3: Среднесрочн. план 2026 ПРЭУ: Вариант на утверждение | AZ3: Факт | BA3: Отклонение | BC3: Среднесрочн. план 2026: Вариант утвержденный | BD3: Среднесрочн. план 2026 ПРЭУ: Вариант на утверждение | BE3: Факт | BF3: Отклонение | BH3: Среднесрочн. план 2026: Вариант утвержденный | BI3: Среднесрочн. план 2026 ПРЭУ: Вариант на утверждение | BJ3: Факт | BK3: Отклонение | BM3: Среднесрочн. план 2026: Вариант утвержденный | BN3: Среднесрочн. план 2026 ПРЭУ: Вариант на утверждение | BO3: Факт | BP3: Отклонение | BR3: Среднесрочн. план 2026: Вариант утвержденный | BS3: Среднесрочн. план 2026 ПРЭУ: Вариант на утверждение | BT3: Факт | BU3: Отклонение | BW3: Среднесрочн. план 2026: Вариант утвержденный | BX3: Среднесрочн. план 2026 ПРЭУ: Вариант на утверждение | BY3: Факт | BZ3: Отклонение | CB3: Среднесрочн. план 2026: Вариант утвержденный | CC3: Среднесрочн. план 2026 ПРЭУ: Вариант на утверждение | CD3: Факт | CE3: Отклонение | CG3: Среднесрочн. план 2026: Вариант утвержденный | CH3: Среднесрочн. план 2026 ПРЭУ: Вариант на утверждение | CI3: Факт | CJ3: Отклонение | CL3: Среднесрочн. план 2026: Вариант утвержденный | CM3: Среднесрочн. план 2026 ПРЭУ: Вариант на утверждение | CN3: Факт | CO3: Отклонение
M4: + / - | N4: % вып. | R4: + / - | S4: % вып. | W4: + / - | X4: % вып. | AB4: + / - | AC4: % вып. | AG4: + / - | AH4: % вып. | AL4: + / - | AM4: % вып. | AQ4: + / - | AR4: % вып. | AV4: + / - | AW4: % вып. | BA4: + / - | BB4: % вып. | BF4: + / - | BG4: % вып. | BK4: + / - | BL4: % вып. | BP4: + / - | BQ4: % вып. | BU4: + / - | BV4: % вып. | BZ4: + / - | CA4: % вып. | CE4: + / - | CF4: % вып. | CJ4: + / - | CK4: % вып. | CO4: + / - | CP4: % вып.
J5: year2026:1:2260099 | K5: year2026:1:2260010 | L5: year2026:15:None | O5: year2026:Q1:1:2260099 | P5: year2026:Q1:1:2260010 | Q5: year2026:Q1:15:None | T5: year2026:M1_1:1:2260099 | U5: year2026:M1_1:1:2260010 | V5: year2026:M1_1:15:None | Y5: year2026:M1_2:1:2260099 | Z5: year2026:M1_2:1:2260010 | AA5: year2026:M1_2:15:None | AD5: year2026:M1_3:1:2260099 | AE5: year2026:M1_3:1:2260010 | AF5: year2026:M1_3:15:None | AI5: year2026:Q2:1:2260099 | AJ5: year2026:Q2:1:2260010 | AK5: year2026:Q2:15:None | AN5: year2026:M2_1:1:2260099 | AO5: year2026:M2_1:1:2260010 | AP5: year2026:M2_1:15:None | AS5: year2026:M2_2:1:2260099 | AT5: year2026:M2_2:1:2260010 | AU5: year2026:M2_2:15:None | AX5: year2026:M2_3:1:2260099 | AY5: year2026:M2_3:1:2260010 | AZ5: year2026:M2_3:15:None | BC5: year2026:Q3:1:2260099 | BD5: year2026:Q3:1:2260010 | BE5: year2026:Q3:15:None | BH5: year2026:M3_1:1:2260099 | BI5: year2026:M3_1:1:2260010 | BJ5: year2026:M3_1:15:None | BM5: year2026:M3_2:1:2260099 | BN5: year2026:M3_2:1:2260010 | BO5: year2026:M3_2:15:None | BR5: year2026:M3_3:1:2260099 | BS5: year2026:M3_3:1:2260010 | BT5: year2026:M3_3:15:None | BW5: year2026:Q4:1:2260099 | BX5: year2026:Q4:1:2260010 | BY5: year2026:Q4:15:None | CB5: year2026:M4_1:1:2260099 | CC5: year2026:M4_1:1:2260010 | CD5: year2026:M4_1:15:None | CG5: year2026:M4_2:1:2260099 | CH5: year2026:M4_2:1:2260010 | CI5: year2026:M4_2:15:None | CL5: year2026:M4_3:1:2260099 | CM5: year2026:M4_3:1:2260010 | CN5: year2026:M4_3:15:None
F6: 1_100331978+1_100335798 | J6: =O6+AI6+BC6+BW6 -> 13574.2 | K6: =P6+AJ6+BD6+BX6 -> 13574.2 | L6: =Q6+AK6+BE6+BY6 -> 3725.5687 | M6: =IFERROR(K6-J6,"-") -> 0 | N6: =IFERROR(K6/J6,"-") -> 1 | O6: =T6+Y6+AD6 -> 3405.4 | P6: =U6+Z6+AE6 -> 3405.4 | Q6: =V6+AA6+AF6 -> 2363.5888 | R6: =IFERROR(P6-O6,"-") -> 0 | S6: =IFERROR(P6/O6,"-") -> 1 | T6: =Лист1!Z7+Лист1!Z9 -> 1172.9 | U6: =Лист1!AB7+Лист1!AB9 -> 1172.9 | V6: =Лист1!AD7+Лист1!AD9 -> 852.21491 | W6: =IFERROR(U6-T6,"-") -> 0 | X6: =IFERROR(U6/T6,"-") -> 1 | Y6: =Лист1!AH7+Лист1!AH9 -> 1059.5 | Z6: =Лист1!AJ7+Лист1!AJ9 -> 1059.5 | AA6: =Лист1!AL7+Лист1!AL9 -> 663.76837 | AB6: =IFERROR(Z6-Y6,"-") -> 0 | AC6: =IFERROR(Z6/Y6,"-") -> 1 | AD6: =Лист1!AP7+Лист1!AP9 -> 1173 | AE6: =Лист1!AR7+Лист1!AR9 -> 1173 | AF6: =Лист1!AT7+Лист1!AT9 -> 847.6055 | AG6: =IFERROR(AE6-AD6,"-") -> 0 | AH6: =IFERROR(AE6/AD6,"-") -> 1 | AI6: =AN6+AS6+AX6 -> 2597.4 | AJ6: =AO6+AT6+AY6 -> 2597.4 | AK6: =AP6+AU6+AZ6 -> 1361.9799 | AL6: =IFERROR(AJ6-AI6,"-") -> 0 | AM6: =IFERROR(AJ6/AI6,"-") -> 1 | AN6: =Лист1!BF7+Лист1!BF9 -> 1135.2 | AO6: =Лист1!BH7+Лист1!BH9 -> 1135.2 | AP6: =Лист1!BJ7+Лист1!BJ9 -> 807.96479 | AQ6: =IFERROR(AO6-AN6,"-") -> 0 | AR6: =IFERROR(AO6/AN6,"-") -> 1 | AS6: =Лист1!BN7+Лист1!BN9 -> 806.4 | AT6: =Лист1!BP7+Лист1!BP9 -> 806.4 | AU6: =Лист1!BR7+Лист1!BR9 -> 328.213 | AV6: =IFERROR(AT6-AS6,"-") -> 0 | AW6: =IFERROR(AT6/AS6,"-") -> 1 | AX6: =Лист1!BV7+Лист1!BV9 -> 655.8 | AY6: =Лист1!BX7+Лист1!BX9 -> 655.8 | AZ6: =Лист1!BZ7+Лист1!BZ9 -> 225.80213 | BA6: =IFERROR(AY6-AX6,"-") -> 0 | BB6: =IFERROR(AY6/AX6,"-") -> 1 | BC6: =BH6+BM6+BR6 -> 3706 | BD6: =BI6+BN6+BS6 -> 3706 | BE6: =BJ6+BO6+BT6 -> 0 | BF6: =IFERROR(BD6-BC6,"-") -> 0 | BG6: =IFERROR(BD6/BC6,"-") -> 1 | BH6: =Лист1!CL7+Лист1!CL9 -> 1219.6 | BI6: =Лист1!CN7+Лист1!CN9 -> 1219.6 | BJ6: =Лист1!CP7+Лист1!CP9 -> 0 | BK6: =IFERROR(BI6-BH6,"-") -> 0 | BL6: =IFERROR(BI6/BH6,"-") -> 1 | BM6: =Лист1!CT7+Лист1!CT9 -> 1225.1 | BN6: =Лист1!CV7+Лист1!CV9 -> 1225.1 | BO6: =Лист1!CX7+Лист1!CX9 -> 0 | BP6: =IFERROR(BN6-BM6,"-") -> 0 | BQ6: =IFERROR(BN6/BM6,"-") -> 1 | BR6: =Лист1!DB7+Лист1!DB9 -> 1261.3 | BS6: =Лист1!DD7+Лист1!DD9 -> 1261.3 | BT6: =Лист1!DF7+Лист1!DF9 -> 0 | BU6: =IFERROR(BS6-BR6,"-") -> 0 | BV6: =IFERROR(BS6/BR6,"-") -> 1 | BW6: =CB6+CG6+CL6 -> 3865.4 | BX6: =CC6+CH6+CM6 -> 3865.4 | BY6: =CD6+CI6+CN6 -> 0 | BZ6: =IFERROR(BX6-BW6,"-") -> 0 | CA6: =IFERROR(BX6/BW6,"-") -> 1 | CB6: =Лист1!DR7+Лист1!DR9 -> 1303.3 | CC6: =Лист1!DT7+Лист1!DT9 -> 1303.3 | CD6: =Лист1!DV7+Лист1!DV9 -> 0 | CE6: =IFERROR(CC6-CB6,"-") -> 0 | CF6: =IFERROR(CC6/CB6,"-") -> 1 | CG6: =Лист1!DZ7+Лист1!DZ9 -> 1261.3 | CH6: =Лист1!EB7+Лист1!EB9 -> 1261.3 | CI6: =Лист1!ED7+Лист1!ED9 -> 0 | CJ6: =IFERROR(CH6-CG6,"-") -> 0 | CK6: =IFERROR(CH6/CG6,"-") -> 1 | CL6: =Лист1!EH7+Лист1!EH9 -> 1300.8 | CM6: =Лист1!EJ7+Лист1!EJ9 -> 1300.8 | CN6: =Лист1!EL7+Лист1!EL9 -> 0 | CO6: =IFERROR(CM6-CL6,"-") -> 0 | CP6: =IFERROR(CM6/CL6,"-") -> 1
E7: 1 | J7: =O7+AI7+BC7+BW7 -> 111.99 | K7: =P7+AJ7+BD7+BX7 -> 0 | L7: =Q7+AK7+BE7+BY7 -> 0 | M7: =IFERROR(K7-J7,"-") -> -111.99 | N7: =IFERROR(K7/J7,"-") -> 0 | O7: =T7+Y7+AD7 -> 111.99 | P7: =U7+Z7+AE7 -> 0 | Q7: =V7+AA7+AF7 -> 0 | R7: =IFERROR(P7-O7,"-") -> -111.99 | S7: =IFERROR(P7/O7,"-") -> 0 | T7: 111.99 | W7: =IFERROR(U7-T7,"-") -> -111.99 | X7: =IFERROR(U7/T7,"-") -> 0 | AB7: =IFERROR(Z7-Y7,"-") -> 0 | AC7: =IFERROR(Z7/Y7,"-") -> - | AG7: =IFERROR(AE7-AD7,"-") -> 0 | AH7: =IFERROR(AE7/AD7,"-") -> - | AI7: =AN7+AS7+AX7 -> 0 | AJ7: =AO7+AT7+AY7 -> 0 | AK7: =AP7+AU7+AZ7 -> 0 | AL7: =IFERROR(AJ7-AI7,"-") -> 0 | AM7: =IFERROR(AJ7/AI7,"-") -> - | AQ7: =IFERROR(AO7-AN7,"-") -> 0 | AR7: =IFERROR(AO7/AN7,"-") -> - | AV7: =IFERROR(AT7-AS7,"-") -> 0 | AW7: =IFERROR(AT7/AS7,"-") -> - | BA7: =IFERROR(AY7-AX7,"-") -> 0 | BB7: =IFERROR(AY7/AX7,"-") -> - | BC7: =BH7+BM7+BR7 -> 0 | BD7: =BI7+BN7+BS7 -> 0 | BE7: =BJ7+BO7+BT7 -> 0 | BF7: =IFERROR(BD7-BC7,"-") -> 0 | BG7: =IFERROR(BD7/BC7,"-") -> - | BK7: =IFERROR(BI7-BH7,"-") -> 0 | BL7: =IFERROR(BI7/BH7,"-") -> - | BP7: =IFERROR(BN7-BM7,"-") -> 0 | BQ7: =IFERROR(BN7/BM7,"-") -> - | BU7: =IFERROR(BS7-BR7,"-") -> 0 | BV7: =IFERROR(BS7/BR7,"-") -> - | BW7: =CB7+CG7+CL7 -> 0 | BX7: =CC7+CH7+CM7 -> 0 | BY7: =CD7+CI7+CN7 -> 0 | BZ7: =IFERROR(BX7-BW7,"-") -> 0 | CA7: =IFERROR(BX7/BW7,"-") -> - | CE7: =IFERROR(CC7-CB7,"-") -> 0 | CF7: =IFERROR(CC7/CB7,"-") -> - | CJ7: =IFERROR(CH7-CG7,"-") -> 0 | CK7: =IFERROR(CH7/CG7,"-") -> - | CO7: =IFERROR(CM7-CL7,"-") -> 0 | CP7: =IFERROR(CM7/CL7,"-") -> -
E8: 2 | J8: =O8+AI8+BC8+BW8 -> 159.44 | K8: =P8+AJ8+BD8+BX8 -> 0 | L8: =Q8+AK8+BE8+BY8 -> 0 | M8: =IFERROR(K8-J8,"-") -> -159.44 | N8: =IFERROR(K8/J8,"-") -> 0 | O8: =T8+Y8+AD8 -> 159.44 | P8: =U8+Z8+AE8 -> 0 | Q8: =V8+AA8+AF8 -> 0 | R8: =IFERROR(P8-O8,"-") -> -159.44 | S8: =IFERROR(P8/O8,"-") -> 0 | T8: 159.44 | W8: =IFERROR(U8-T8,"-") -> -159.44 | X8: =IFERROR(U8/T8,"-") -> 0 | AB8: =IFERROR(Z8-Y8,"-") -> 0 | AC8: =IFERROR(Z8/Y8,"-") -> - | AG8: =IFERROR(AE8-AD8,"-") -> 0 | AH8: =IFERROR(AE8/AD8,"-") -> - | AI8: =AN8+AS8+AX8 -> 0 | AJ8: =AO8+AT8+AY8 -> 0 | AK8: =AP8+AU8+AZ8 -> 0 | AL8: =IFERROR(AJ8-AI8,"-") -> 0 | AM8: =IFERROR(AJ8/AI8,"-") -> - | AQ8: =IFERROR(AO8-AN8,"-") -> 0 | AR8: =IFERROR(AO8/AN8,"-") -> - | AV8: =IFERROR(AT8-AS8,"-") -> 0 | AW8: =IFERROR(AT8/AS8,"-") -> - | BA8: =IFERROR(AY8-AX8,"-") -> 0 | BB8: =IFERROR(AY8/AX8,"-") -> - | BC8: =BH8+BM8+BR8 -> 0 | BD8: =BI8+BN8+BS8 -> 0 | BE8: =BJ8+BO8+BT8 -> 0 | BF8: =IFERROR(BD8-BC8,"-") -> 0 | BG8: =IFERROR(BD8/BC8,"-") -> - | BK8: =IFERROR(BI8-BH8,"-") -> 0 | BL8: =IFERROR(BI8/BH8,"-") -> - | BP8: =IFERROR(BN8-BM8,"-") -> 0 | BQ8: =IFERROR(BN8/BM8,"-") -> - | BU8: =IFERROR(BS8-BR8,"-") -> 0 | BV8: =IFERROR(BS8/BR8,"-") -> - | BW8: =CB8+CG8+CL8 -> 0 | BX8: =CC8+CH8+CM8 -> 0 | BY8: =CD8+CI8+CN8 -> 0 | BZ8: =IFERROR(BX8-BW8,"-") -> 0 | CA8: =IFERROR(BX8/BW8,"-") -> - | CE8: =IFERROR(CC8-CB8,"-") -> 0 | CF8: =IFERROR(CC8/CB8,"-") -> - | CJ8: =IFERROR(CH8-CG8,"-") -> 0 | CK8: =IFERROR(CH8/CG8,"-") -> - | CO8: =IFERROR(CM8-CL8,"-") -> 0 | CP8: =IFERROR(CM8/CL8,"-") -> -
F9: =F10+F11+1000 -> #VALUE! | J9: =O9+AI9+BC9+BW9 -> 22328.7 | K9: =P9+AJ9+BD9+BX9 -> 22328.7 | L9: =Q9+AK9+BE9+BY9 -> 14830.981 | M9: =IFERROR(K9-J9,"-") -> 0 | N9: =IFERROR(K9/J9,"-") -> 1 | O9: =T9+Y9+AD9 -> 5591.2 | P9: =U9+Z9+AE9 -> 5591.2 | Q9: =V9+AA9+AF9 -> 4796.716 | R9: =IFERROR(P9-O9,"-") -> 0 | S9: =IFERROR(P9/O9,"-") -> 1 | T9: =T10+T11+1000 -> 1892.5 | U9: =U10+U11+1000 -> 1892.5 | V9: =V10+V11+1000 -> 1648.219 | W9: =IFERROR(U9-T9,"-") -> 0 | X9: =IFERROR(U9/T9,"-") -> 1 | Y9: =Y10+Y11+1000 -> 1806.2 | Z9: =Z10+Z11+1000 -> 1806.2 | AA9: =AA10+AA11+1000 -> 1504.768 | AB9: =IFERROR(Z9-Y9,"-") -> 0 | AC9: =IFERROR(Z9/Y9,"-") -> 1 | AD9: =AD10+AD11+1000 -> 1892.5 | AE9: =AE10+AE11+1000 -> 1892.5 | AF9: =AF10+AF11+1000 -> 1643.729 | AG9: =IFERROR(AE9-AD9,"-") -> 0 | AH9: =IFERROR(AE9/AD9,"-") -> 1 | AI9: =AN9+AS9+AX9 -> 4976.3 | AJ9: =AO9+AT9+AY9 -> 4976.3 | AK9: =AP9+AU9+AZ9 -> 4034.265 | AL9: =IFERROR(AJ9-AI9,"-") -> 0 | AM9: =IFERROR(AJ9/AI9,"-") -> 1 | AN9: =AN10+AN11+1000 -> 1863.8 | AO9: =AO10+AO11+1000 -> 1863.8 | AP9: =AP10+AP11+1000 -> 1612.959 | AQ9: =IFERROR(AO9-AN9,"-") -> 0 | AR9: =IFERROR(AO9/AN9,"-") -> 1 | AS9: =AS10+AS11+1000 -> 1613.6 | AT9: =AT10+AT11+1000 -> 1613.6 | AU9: =AU10+AU11+1000 -> 1249.514 | AV9: =IFERROR(AT9-AS9,"-") -> 0 | AW9: =IFERROR(AT9/AS9,"-") -> 1 | AX9: =AX10+AX11+1000 -> 1498.9 | AY9: =AY10+AY11+1000 -> 1498.9 | AZ9: =AZ10+AZ11+1000 -> 1171.792 | BA9: =IFERROR(AY9-AX9,"-") -> 0 | BB9: =IFERROR(AY9/AX9,"-") -> 1 | BC9: =BH9+BM9+BR9 -> 5819.9 | BD9: =BI9+BN9+BS9 -> 5819.9 | BE9: =BJ9+BO9+BT9 -> 3000 | BF9: =IFERROR(BD9-BC9,"-") -> 0 | BG9: =IFERROR(BD9/BC9,"-") -> 1 | BH9: =BH10+BH11+1000 -> 1928 | BI9: =BI10+BI11+1000 -> 1928 | BJ9: =BJ10+BJ11+1000 -> 1000 | BK9: =IFERROR(BI9-BH9,"-") -> 0 | BL9: =IFERROR(BI9/BH9,"-") -> 1 | BM9: =BM10+BM11+1000 -> 1932.2 | BN9: =BN10+BN11+1000 -> 1932.2 | BO9: =BO10+BO11+1000 -> 1000 | BP9: =IFERROR(BN9-BM9,"-") -> 0 | BQ9: =IFERROR(BN9/BM9,"-") -> 1 | BR9: =BR10+BR11+1000 -> 1959.7 | BS9: =BS10+BS11+1000 -> 1959.7 | BT9: =BT10+BT11+1000 -> 1000 | BU9: =IFERROR(BS9-BR9,"-") -> 0 | BV9: =IFERROR(BS9/BR9,"-") -> 1 | BW9: =CB9+CG9+CL9 -> 5941.3 | BX9: =CC9+CH9+CM9 -> 5941.3 | BY9: =CD9+CI9+CN9 -> 3000 | BZ9: =IFERROR(BX9-BW9,"-") -> 0 | CA9: =IFERROR(BX9/BW9,"-") -> 1 | CB9: =CB10+CB11+1000 -> 1991.7 | CC9: =CC10+CC11+1000 -> 1991.7 | CD9: =CD10+CD11+1000 -> 1000 | CE9: =IFERROR(CC9-CB9,"-") -> 0 | CF9: =IFERROR(CC9/CB9,"-") -> 1 | CG9: =CG10+CG11+1000 -> 1959.7 | CH9: =CH10+CH11+1000 -> 1959.7 | CI9: =CI10+CI11+1000 -> 1000 | CJ9: =IFERROR(CH9-CG9,"-") -> 0 | CK9: =IFERROR(CH9/CG9,"-") -> 1 | CL9: =CL10+CL11+1000 -> 1989.9 | CM9: =CM10+CM11+1000 -> 1989.9 | CN9: =CN10+CN11+1000 -> 1000 | CO9: =IFERROR(CM9-CL9,"-") -> 0 | CP9: =IFERROR(CM9/CL9,"-") -> 1
F10: 1_100335800 | J10: =O10+AI10+BC10+BW10 -> 13.6 | K10: =P10+AJ10+BD10+BX10 -> 13.6 | L10: =Q10+AK10+BE10+BY10 -> 3.721 | M10: =IFERROR(K10-J10,"-") -> 0 | N10: =IFERROR(K10/J10,"-") -> 1 | O10: =T10+Y10+AD10 -> 3.4 | P10: =U10+Z10+AE10 -> 3.4 | Q10: =V10+AA10+AF10 -> 2.362 | R10: =IFERROR(P10-O10,"-") -> 0 | S10: =IFERROR(P10/O10,"-") -> 1 | T10: =Лист1!Z11 -> 1.2 | U10: =Лист1!AB11 -> 1.2 | V10: =Лист1!AD11 -> 0.852 | W10: =IFERROR(U10-T10,"-") -> 0 | X10: =IFERROR(U10/T10,"-") -> 1 | Y10: =Лист1!AH11 -> 1.1 | Z10: =Лист1!AJ11 -> 1.1 | AA10: =Лист1!AL11 -> 0.663 | AB10: =IFERROR(Z10-Y10,"-") -> 0 | AC10: =IFERROR(Z10/Y10,"-") -> 1 | AD10: =Лист1!AP11 -> 1.1 | AE10: =Лист1!AR11 -> 1.1 | AF10: =Лист1!AT11 -> 0.847 | AG10: =IFERROR(AE10-AD10,"-") -> 0 | AH10: =IFERROR(AE10/AD10,"-") -> 1 | AI10: =AN10+AS10+AX10 -> 2.6 | AJ10: =AO10+AT10+AY10 -> 2.6 | AK10: =AP10+AU10+AZ10 -> 1.359 | AL10: =IFERROR(AJ10-AI10,"-") -> 0 | AM10: =IFERROR(AJ10/AI10,"-") -> 1 | AN10: =Лист1!BF11 -> 1.2 | AO10: =Лист1!BH11 -> 1.2 | AP10: =Лист1!BJ11 -> 0.807 | AQ10: =IFERROR(AO10-AN10,"-") -> 0 | AR10: =IFERROR(AO10/AN10,"-") -> 1 | AS10: =Лист1!BN11 -> 0.8 | AT10: =Лист1!BP11 -> 0.8 | AU10: =Лист1!BR11 -> 0.327 | AV10: =IFERROR(AT10-AS10,"-") -> 0 | AW10: =IFERROR(AT10/AS10,"-") -> 1 | AX10: =Лист1!BV11 -> 0.6 | AY10: =Лист1!BX11 -> 0.6 | AZ10: =Лист1!BZ11 -> 0.225 | BA10: =IFERROR(AY10-AX10,"-") -> 0 | BB10: =IFERROR(AY10/AX10,"-") -> 1 | BC10: =BH10+BM10+BR10 -> 3.7 | BD10: =BI10+BN10+BS10 -> 3.7 | BE10: =BJ10+BO10+BT10 -> 0 | BF10: =IFERROR(BD10-BC10,"-") -> 0 | BG10: =IFERROR(BD10/BC10,"-") -> 1 | BH10: =Лист1!CL11 -> 1.2 | BI10: =Лист1!CN11 -> 1.2 | BJ10: =Лист1!CP11 -> 0 | BK10: =IFERROR(BI10-BH10,"-") -> 0 | BL10: =IFERROR(BI10/BH10,"-") -> 1 | BM10: =Лист1!CT11 -> 1.2 | BN10: =Лист1!CV11 -> 1.2 | BO10: =Лист1!CX11 -> 0 | BP10: =IFERROR(BN10-BM10,"-") -> 0 | BQ10: =IFERROR(BN10/BM10,"-") -> 1 | BR10: =Лист1!DB11 -> 1.3 | BS10: =Лист1!DD11 -> 1.3 | BT10: =Лист1!DF11 -> 0 | BU10: =IFERROR(BS10-BR10,"-") -> 0 | BV10: =IFERROR(BS10/BR10,"-") -> 1 | BW10: =CB10+CG10+CL10 -> 3.9 | BX10: =CC10+CH10+CM10 -> 3.9 | BY10: =CD10+CI10+CN10 -> 0 | BZ10: =IFERROR(BX10-BW10,"-") -> 0 | CA10: =IFERROR(BX10/BW10,"-") -> 1 | CB10: =Лист1!DR11 -> 1.3 | CC10: =Лист1!DT11 -> 1.3 | CD10: =Лист1!DV11 -> 0 | CE10: =IFERROR(CC10-CB10,"-") -> 0 | CF10: =IFERROR(CC10/CB10,"-") -> 1 | CG10: =Лист1!DZ11 -> 1.3 | CH10: =Лист1!EB11 -> 1.3 | CI10: =Лист1!ED11 -> 0 | CJ10: =IFERROR(CH10-CG10,"-") -> 0 | CK10: =IFERROR(CH10/CG10,"-") -> 1 | CL10: =Лист1!EH11 -> 1.3 | CM10: =Лист1!EJ11 -> 1.3 | CN10: =Лист1!EL11 -> 0 | CO10: =IFERROR(CM10-CL10,"-") -> 0 | CP10: =IFERROR(CM10/CL10,"-") -> 1
F11: 1_100335802 | J11: =O11+AI11+BC11+BW11 -> 10315.1 | K11: =P11+AJ11+BD11+BX11 -> 10315.1 | L11: =Q11+AK11+BE11+BY11 -> 2827.26 | M11: =IFERROR(K11-J11,"-") -> 0 | N11: =IFERROR(K11/J11,"-") -> 1 | O11: =T11+Y11+AD11 -> 2587.8 | P11: =U11+Z11+AE11 -> 2587.8 | Q11: =V11+AA11+AF11 -> 1794.354 | R11: =IFERROR(P11-O11,"-") -> 0 | S11: =IFERROR(P11/O11,"-") -> 1 | T11: =Лист1!Z13 -> 891.3 | U11: =Лист1!AB13 -> 891.3 | V11: =Лист1!AD13 -> 647.367 | W11: =IFERROR(U11-T11,"-") -> 0 | X11: =IFERROR(U11/T11,"-") -> 1 | Y11: =Лист1!AH13 -> 805.1 | Z11: =Лист1!AJ13 -> 805.1 | AA11: =Лист1!AL13 -> 504.105 | AB11: =IFERROR(Z11-Y11,"-") -> 0 | AC11: =IFERROR(Z11/Y11,"-") -> 1 | AD11: =Лист1!AP13 -> 891.4 | AE11: =Лист1!AR13 -> 891.4 | AF11: =Лист1!AT13 -> 642.882 | AG11: =IFERROR(AE11-AD11,"-") -> 0 | AH11: =IFERROR(AE11/AD11,"-") -> 1 | AI11: =AN11+AS11+AX11 -> 1973.7 | AJ11: =AO11+AT11+AY11 -> 1973.7 | AK11: =AP11+AU11+AZ11 -> 1032.906 | AL11: =IFERROR(AJ11-AI11,"-") -> 0 | AM11: =IFERROR(AJ11/AI11,"-") -> 1 | AN11: =Лист1!BF13 -> 862.6 | AO11: =Лист1!BH13 -> 862.6 | AP11: =Лист1!BJ13 -> 612.152 | AQ11: =IFERROR(AO11-AN11,"-") -> 0 | AR11: =IFERROR(AO11/AN11,"-") -> 1 | AS11: =Лист1!BN13 -> 612.8 | AT11: =Лист1!BP13 -> 612.8 | AU11: =Лист1!BR13 -> 249.187 | AV11: =IFERROR(AT11-AS11,"-") -> 0 | AW11: =IFERROR(AT11/AS11,"-") -> 1 | AX11: =Лист1!BV13 -> 498.3 | AY11: =Лист1!BX13 -> 498.3 | AZ11: =Лист1!BZ13 -> 171.567 | BA11: =IFERROR(AY11-AX11,"-") -> 0 | BB11: =IFERROR(AY11/AX11,"-") -> 1 | BC11: =BH11+BM11+BR11 -> 2816.2 | BD11: =BI11+BN11+BS11 -> 2816.2 | BE11: =BJ11+BO11+BT11 -> 0 | BF11: =IFERROR(BD11-BC11,"-") -> 0 | BG11: =IFERROR(BD11/BC11,"-") -> 1 | BH11: =Лист1!CL13 -> 926.8 | BI11: =Лист1!CN13 -> 926.8 | BJ11: =Лист1!CP13 -> 0 | BK11: =IFERROR(BI11-BH11,"-") -> 0 | BL11: =IFERROR(BI11/BH11,"-") -> 1 | BM11: =Лист1!CT13 -> 931 | BN11: =Лист1!CV13 -> 931 | BO11: =Лист1!CX13 -> 0 | BP11: =IFERROR(BN11-BM11,"-") -> 0 | BQ11: =IFERROR(BN11/BM11,"-") -> 1 | BR11: =Лист1!DB13 -> 958.4 | BS11: =Лист1!DD13 -> 958.4 | BT11: =Лист1!DF13 -> 0 | BU11: =IFERROR(BS11-BR11,"-") -> 0 | BV11: =IFERROR(BS11/BR11,"-") -> 1 | BW11: =CB11+CG11+CL11 -> 2937.4 | BX11: =CC11+CH11+CM11 -> 2937.4 | BY11: =CD11+CI11+CN11 -> 0 | BZ11: =IFERROR(BX11-BW11,"-") -> 0 | CA11: =IFERROR(BX11/BW11,"-") -> 1 | CB11: =Лист1!DR13 -> 990.4 | CC11: =Лист1!DT13 -> 990.4 | CD11: =Лист1!DV13 -> 0 | CE11: =IFERROR(CC11-CB11,"-") -> 0 | CF11: =IFERROR(CC11/CB11,"-") -> 1 | CG11: =Лист1!DZ13 -> 958.4 | CH11: =Лист1!EB13 -> 958.4 | CI11: =Лист1!ED13 -> 0 | CJ11: =IFERROR(CH11-CG11,"-") -> 0 | CK11: =IFERROR(CH11/CG11,"-") -> 1 | CL11: =Лист1!EH13 -> 988.6 | CM11: =Лист1!EJ13 -> 988.6 | CN11: =Лист1!EL13 -> 0 | CO11: =IFERROR(CM11-CL11,"-") -> 0 | CP11: =IFERROR(CM11/CL11,"-") -> 1
F12: 1_100335802+1_100335804 | J12: =O12+AI12+BC12+BW12 -> 13560.6 | K12: =P12+AJ12+BD12+BX12 -> 13560.6 | L12: =Q12+AK12+BE12+BY12 -> 3721.8477 | M12: =IFERROR(K12-J12,"-") -> 0 | N12: =IFERROR(K12/J12,"-") -> 1 | O12: =T12+Y12+AD12 -> 3402 | P12: =U12+Z12+AE12 -> 3402 | Q12: =V12+AA12+AF12 -> 2361.2268 | R12: =IFERROR(P12-O12,"-") -> 0 | S12: =IFERROR(P12/O12,"-") -> 1 | T12: =Лист1!Z13+Лист1!Z15 -> 1171.7 | U12: =Лист1!AB13+Лист1!AB15 -> 1171.7 | V12: =Лист1!AD13+Лист1!AD15 -> 851.3629 | W12: =IFERROR(U12-T12,"-") -> 0 | X12: =IFERROR(U12/T12,"-") -> 1 | Y12: =Лист1!AH13+Лист1!AH15 -> 1058.4 | Z12: =Лист1!AJ13+Лист1!AJ15 -> 1058.4 | AA12: =Лист1!AL13+Лист1!AL15 -> 663.10537 | AB12: =IFERROR(Z12-Y12,"-") -> 0 | AC12: =IFERROR(Z12/Y12,"-") -> 1 | AD12: =Лист1!AP13+Лист1!AP15 -> 1171.9 | AE12: =Лист1!AR13+Лист1!AR15 -> 1171.9 | AF12: =Лист1!AT13+Лист1!AT15 -> 846.7585 | AG12: =IFERROR(AE12-AD12,"-") -> 0 | AH12: =IFERROR(AE12/AD12,"-") -> 1 | AI12: =AN12+AS12+AX12 -> 2594.8 | AJ12: =AO12+AT12+AY12 -> 2594.8 | AK12: =AP12+AU12+AZ12 -> 1360.6209 | AL12: =IFERROR(AJ12-AI12,"-") -> 0 | AM12: =IFERROR(AJ12/AI12,"-") -> 1 | AN12: =Лист1!BF13+Лист1!BF15 -> 1134 | AO12: =Лист1!BH13+Лист1!BH15 -> 1134 | AP12: =Лист1!BJ13+Лист1!BJ15 -> 807.15779 | AQ12: =IFERROR(AO12-AN12,"-") -> 0 | AR12: =IFERROR(AO12/AN12,"-") -> 1 | AS12: =Лист1!BN13+Лист1!BN15 -> 805.6 | AT12: =Лист1!BP13+Лист1!BP15 -> 805.6 | AU12: =Лист1!BR13+Лист1!BR15 -> 327.886 | AV12: =IFERROR(AT12-AS12,"-") -> 0 | AW12: =IFERROR(AT12/AS12,"-") -> 1 | AX12: =Лист1!BV13+Лист1!BV15 -> 655.2 | AY12: =Лист1!BX13+Лист1!BX15 -> 655.2 | AZ12: =Лист1!BZ13+Лист1!BZ15 -> 225.57713 | BA12: =IFERROR(AY12-AX12,"-") -> 0 | BB12: =IFERROR(AY12/AX12,"-") -> 1 | BC12: =BH12+BM12+BR12 -> 3702.3 | BD12: =BI12+BN12+BS12 -> 3702.3 | BE12: =BJ12+BO12+BT12 -> 0 | BF12: =IFERROR(BD12-BC12,"-") -> 0 | BG12: =IFERROR(BD12/BC12,"-") -> 1 | BH12: =Лист1!CL13+Лист1!CL15 -> 1218.4 | BI12: =Лист1!CN13+Лист1!CN15 -> 1218.4 | BJ12: =Лист1!CP13+Лист1!CP15 -> 0 | BK12: =IFERROR(BI12-BH12,"-") -> 0 | BL12: =IFERROR(BI12/BH12,"-") -> 1 | BM12: =Лист1!CT13+Лист1!CT15 -> 1223.9 | BN12: =Лист1!CV13+Лист1!CV15 -> 1223.9 | BO12: =Лист1!CX13+Лист1!CX15 -> 0 | BP12: =IFERROR(BN12-BM12,"-") -> 0 | BQ12: =IFERROR(BN12/BM12,"-") -> 1 | BR12: =Лист1!DB13+Лист1!DB15 -> 1260 | BS12: =Лист1!DD13+Лист1!DD15 -> 1260 | BT12: =Лист1!DF13+Лист1!DF15 -> 0 | BU12: =IFERROR(BS12-BR12,"-") -> 0 | BV12: =IFERROR(BS12/BR12,"-") -> 1 | BW12: =CB12+CG12+CL12 -> 3861.5 | BX12: =CC12+CH12+CM12 -> 3861.5 | BY12: =CD12+CI12+CN12 -> 0 | BZ12: =IFERROR(BX12-BW12,"-") -> 0 | CA12: =IFERROR(BX12/BW12,"-") -> 1 | CB12: =Лист1!DR13+Лист1!DR15 -> 1302 | CC12: =Лист1!DT13+Лист1!DT15 -> 1302 | CD12: =Лист1!DV13+Лист1!DV15 -> 0 | CE12: =IFERROR(CC12-CB12,"-") -> 0 | CF12: =IFERROR(CC12/CB12,"-") -> 1 | CG12: =Лист1!DZ13+Лист1!DZ15 -> 1260 | CH12: =Лист1!EB13+Лист1!EB15 -> 1260 | CI12: =Лист1!ED13+Лист1!ED15 -> 0 | CJ12: =IFERROR(CH12-CG12,"-") -> 0 | CK12: =IFERROR(CH12/CG12,"-") -> 1 | CL12: =Лист1!EH13+Лист1!EH15 -> 1299.5 | CM12: =Лист1!EJ13+Лист1!EJ15 -> 1299.5 | CN12: =Лист1!EL13+Лист1!EL15 -> 0 | CO12: =IFERROR(CM12-CL12,"-") -> 0 | CP12: =IFERROR(CM12/CL12,"-") -> 1
E13: 3 | J13: =O13+AI13+BC13+BW13 -> 0 | K13: =P13+AJ13+BD13+BX13 -> 0 | L13: =Q13+AK13+BE13+BY13 -> 0 | M13: =IFERROR(K13-J13,"-") -> 0 | N13: =IFERROR(K13/J13,"-") -> - | O13: =T13+Y13+AD13 -> 0 | P13: =U13+Z13+AE13 -> 0 | Q13: =V13+AA13+AF13 -> 0 | R13: =IFERROR(P13-O13,"-") -> 0 | S13: =IFERROR(P13/O13,"-") -> - | W13: =IFERROR(U13-T13,"-") -> 0 | X13: =IFERROR(U13/T13,"-") -> - | AB13: =IFERROR(Z13-Y13,"-") -> 0 | AC13: =IFERROR(Z13/Y13,"-") -> - | AG13: =IFERROR(AE13-AD13,"-") -> 0 | AH13: =IFERROR(AE13/AD13,"-") -> - | AI13: =AN13+AS13+AX13 -> 0 | AJ13: =AO13+AT13+AY13 -> 0 | AK13: =AP13+AU13+AZ13 -> 0 | AL13: =IFERROR(AJ13-AI13,"-") -> 0 | AM13: =IFERROR(AJ13/AI13,"-") -> - | AQ13: =IFERROR(AO13-AN13,"-") -> 0 | AR13: =IFERROR(AO13/AN13,"-") -> - | AV13: =IFERROR(AT13-AS13,"-") -> 0 | AW13: =IFERROR(AT13/AS13,"-") -> - | BA13: =IFERROR(AY13-AX13,"-") -> 0 | BB13: =IFERROR(AY13/AX13,"-") -> - | BC13: =BH13+BM13+BR13 -> 0 | BD13: =BI13+BN13+BS13 -> 0 | BE13: =BJ13+BO13+BT13 -> 0 | BF13: =IFERROR(BD13-BC13,"-") -> 0 | BG13: =IFERROR(BD13/BC13,"-") -> - | BK13: =IFERROR(BI13-BH13,"-") -> 0 | BL13: =IFERROR(BI13/BH13,"-") -> - | BP13: =IFERROR(BN13-BM13,"-") -> 0 | BQ13: =IFERROR(BN13/BM13,"-") -> - | BU13: =IFERROR(BS13-BR13,"-") -> 0 | BV13: =IFERROR(BS13/BR13,"-") -> - | BW13: =CB13+CG13+CL13 -> 0 | BX13: =CC13+CH13+CM13 -> 0 | BY13: =CD13+CI13+CN13 -> 0 | BZ13: =IFERROR(BX13-BW13,"-") -> 0 | CA13: =IFERROR(BX13/BW13,"-") -> - | CE13: =IFERROR(CC13-CB13,"-") -> 0 | CF13: =IFERROR(CC13/CB13,"-") -> - | CJ13: =IFERROR(CH13-CG13,"-") -> 0 | CK13: =IFERROR(CH13/CG13,"-") -> - | CO13: =IFERROR(CM13-CL13,"-") -> 0 | CP13: =IFERROR(CM13/CL13,"-") -> -
E14: 4 | J14: =O14+AI14+BC14+BW14 -> 0 | K14: =P14+AJ14+BD14+BX14 -> 2556 | L14: =Q14+AK14+BE14+BY14 -> 0 | M14: =IFERROR(K14-J14,"-") -> 2556 | N14: =IFERROR(K14/J14,"-") -> - | O14: =T14+Y14+AD14 -> 0 | P14: =U14+Z14+AE14 -> 2556 | Q14: =V14+AA14+AF14 -> 0 | R14: =IFERROR(P14-O14,"-") -> 2556 | S14: =IFERROR(P14/O14,"-") -> - | U14: 2556 | W14: =IFERROR(U14-T14,"-") -> 2556 | X14: =IFERROR(U14/T14,"-") -> - | AB14: =IFERROR(Z14-Y14,"-") -> 0 | AC14: =IFERROR(Z14/Y14,"-") -> - | AG14: =IFERROR(AE14-AD14,"-") -> 0 | AH14: =IFERROR(AE14/AD14,"-") -> - | AI14: =AN14+AS14+AX14 -> 0 | AJ14: =AO14+AT14+AY14 -> 0 | AK14: =AP14+AU14+AZ14 -> 0 | AL14: =IFERROR(AJ14-AI14,"-") -> 0 | AM14: =IFERROR(AJ14/AI14,"-") -> - | AQ14: =IFERROR(AO14-AN14,"-") -> 0 | AR14: =IFERROR(AO14/AN14,"-") -> - | AV14: =IFERROR(AT14-AS14,"-") -> 0 | AW14: =IFERROR(AT14/AS14,"-") -> - | BA14: =IFERROR(AY14-AX14,"-") -> 0 | BB14: =IFERROR(AY14/AX14,"-") -> - | BC14: =BH14+BM14+BR14 -> 0 | BD14: =BI14+BN14+BS14 -> 0 | BE14: =BJ14+BO14+BT14 -> 0 | BF14: =IFERROR(BD14-BC14,"-") -> 0 | BG14: =IFERROR(BD14/BC14,"-") -> - | BK14: =IFERROR(BI14-BH14,"-") -> 0 | BL14: =IFERROR(BI14/BH14,"-") -> - | BP14: =IFERROR(BN14-BM14,"-") -> 0 | BQ14: =IFERROR(BN14/BM14,"-") -> - | BU14: =IFERROR(BS14-BR14,"-") -> 0 | BV14: =IFERROR(BS14/BR14,"-") -> - | BW14: =CB14+CG14+CL14 -> 0 | BX14: =CC14+CH14+CM14 -> 0 | BY14: =CD14+CI14+CN14 -> 0 | BZ14: =IFERROR(BX14-BW14,"-") -> 0 | CA14: =IFERROR(BX14/BW14,"-") -> - | CE14: =IFERROR(CC14-CB14,"-") -> 0 | CF14: =IFERROR(CC14/CB14,"-") -> - | CJ14: =IFERROR(CH14-CG14,"-") -> 0 | CK14: =IFERROR(CH14/CG14,"-") -> - | CO14: =IFERROR(CM14-CL14,"-") -> 0 | CP14: =IFERROR(CM14/CL14,"-") -> -
E15: 5 | J15: =O15+AI15+BC15+BW15 -> 0 | K15: =P15+AJ15+BD15+BX15 -> 0 | L15: =Q15+AK15+BE15+BY15 -> 0 | M15: =IFERROR(K15-J15,"-") -> 0 | N15: =IFERROR(K15/J15,"-") -> - | O15: =T15+Y15+AD15 -> 0 | P15: =U15+Z15+AE15 -> 0 | Q15: =V15+AA15+AF15 -> 0 | R15: =IFERROR(P15-O15,"-") -> 0 | S15: =IFERROR(P15/O15,"-") -> - | W15: =IFERROR(U15-T15,"-") -> 0 | X15: =IFERROR(U15/T15,"-") -> - | AB15: =IFERROR(Z15-Y15,"-") -> 0 | AC15: =IFERROR(Z15/Y15,"-") -> - | AG15: =IFERROR(AE15-AD15,"-") -> 0 | AH15: =IFERROR(AE15/AD15,"-") -> - | AI15: =AN15+AS15+AX15 -> 0 | AJ15: =AO15+AT15+AY15 -> 0 | AK15: =AP15+AU15+AZ15 -> 0 | AL15: =IFERROR(AJ15-AI15,"-") -> 0 | AM15: =IFERROR(AJ15/AI15,"-") -> - | AQ15: =IFERROR(AO15-AN15,"-") -> 0 | AR15: =IFERROR(AO15/AN15,"-") -> - | AV15: =IFERROR(AT15-AS15,"-") -> 0 | AW15: =IFERROR(AT15/AS15,"-") -> - | BA15: =IFERROR(AY15-AX15,"-") -> 0 | BB15: =IFERROR(AY15/AX15,"-") -> - | BC15: =BH15+BM15+BR15 -> 0 | BD15: =BI15+BN15+BS15 -> 0 | BE15: =BJ15+BO15+BT15 -> 0 | BF15: =IFERROR(BD15-BC15,"-") -> 0 | BG15: =IFERROR(BD15/BC15,"-") -> - | BK15: =IFERROR(BI15-BH15,"-") -> 0 | BL15: =IFERROR(BI15/BH15,"-") -> - | BP15: =IFERROR(BN15-BM15,"-") -> 0 | BQ15: =IFERROR(BN15/BM15,"-") -> - | BU15: =IFERROR(BS15-BR15,"-") -> 0 | BV15: =IFERROR(BS15/BR15,"-") -> - | BW15: =CB15+CG15+CL15 -> 0 | BX15: =CC15+CH15+CM15 -> 0 | BY15: =CD15+CI15+CN15 -> 0 | BZ15: =IFERROR(BX15-BW15,"-") -> 0 | CA15: =IFERROR(BX15/BW15,"-") -> - | CE15: =IFERROR(CC15-CB15,"-") -> 0 | CF15: =IFERROR(CC15/CB15,"-") -> - | CJ15: =IFERROR(CH15-CG15,"-") -> 0 | CK15: =IFERROR(CH15/CG15,"-") -> - | CO15: =IFERROR(CM15-CL15,"-") -> 0 | CP15: =IFERROR(CM15/CL15,"-") -> -
F16: 1_100335806+1_100331985+1_100331986 | J16: =O16+AI16+BC16+BW16 -> 13871.102 | K16: =P16+AJ16+BD16+BX16 -> 13871.102 | L16: =Q16+AK16+BE16+BY16 -> 3869.4245 | M16: =IFERROR(K16-J16,"-") -> 0 | N16: =IFERROR(K16/J16,"-") -> 1 | O16: =T16+Y16+AD16 -> 3450.842 | P16: =U16+Z16+AE16 -> 3450.842 | Q16: =V16+AA16+AF16 -> 2460.9858 | R16: =IFERROR(P16-O16,"-") -> 0 | S16: =IFERROR(P16/O16,"-") -> 1 | T16: =Лист1!Z17+Лист1!Z19+Лист1!Z20 -> 1186.918 | U16: =Лист1!AB17+Лист1!AB19+Лист1!AB20 -> 1186.918 | V16: =Лист1!AD17+Лист1!AD19+Лист1!AD20 -> 882.73091 | W16: =IFERROR(U16-T16,"-") -> 0 | X16: =IFERROR(U16/T16,"-") -> 1 | Y16: =Лист1!AH17+Лист1!AH19+Лист1!AH20 -> 1074.907 | Z16: =Лист1!AJ17+Лист1!AJ19+Лист1!AJ20 -> 1074.907 | AA16: =Лист1!AL17+Лист1!AL19+Лист1!AL20 -> 694.34137 | AB16: =IFERROR(Z16-Y16,"-") -> 0 | AC16: =IFERROR(Z16/Y16,"-") -> 1 | AD16: =Лист1!AP17+Лист1!AP19+Лист1!AP20 -> 1189.017 | AE16: =Лист1!AR17+Лист1!AR19+Лист1!AR20 -> 1189.017 | AF16: =Лист1!AT17+Лист1!AT19+Лист1!AT20 -> 883.9135 | AG16: =IFERROR(AE16-AD16,"-") -> 0 | AH16: =IFERROR(AE16/AD16,"-") -> 1 | AI16: =AN16+AS16+AX16 -> 2665.769 | AJ16: =AO16+AT16+AY16 -> 2665.769 | AK16: =AP16+AU16+AZ16 -> 1408.4387 | AL16: =IFERROR(AJ16-AI16,"-") -> 0 | AM16: =IFERROR(AJ16/AI16,"-") -> 1 | AN16: =Лист1!BF17+Лист1!BF19+Лист1!BF20 -> 1168.842 | AO16: =Лист1!BH17+Лист1!BH19+Лист1!BH20 -> 1168.842 | AP16: =Лист1!BJ17+Лист1!BJ19+Лист1!BJ20 -> 834.79661 | AQ16: =IFERROR(AO16-AN16,"-") -> 0 | AR16: =IFERROR(AO16/AN16,"-") -> 1 | AS16: =Лист1!BN17+Лист1!BN19+Лист1!BN20 -> 829.027 | AT16: =Лист1!BP17+Лист1!BP19+Лист1!BP20 -> 829.027 | AU16: =Лист1!BR17+Лист1!BR19+Лист1!BR20 -> 340.308 | AV16: =IFERROR(AT16-AS16,"-") -> 0 | AW16: =IFERROR(AT16/AS16,"-") -> 1 | AX16: =Лист1!BV17+Лист1!BV19+Лист1!BV20 -> 667.9 | AY16: =Лист1!BX17+Лист1!BX19+Лист1!BX20 -> 667.9 | AZ16: =Лист1!BZ17+Лист1!BZ19+Лист1!BZ20 -> 233.33413 | BA16: =IFERROR(AY16-AX16,"-") -> 0 | BB16: =IFERROR(AY16/AX16,"-") -> 1 | BC16: =BH16+BM16+BR16 -> 3849.863 | BD16: =BI16+BN16+BS16 -> 3849.863 | BE16: =BJ16+BO16+BT16 -> 0 | BF16: =IFERROR(BD16-BC16,"-") -> 0 | BG16: =IFERROR(BD16/BC16,"-") -> 1 | BH16: =Лист1!CL17+Лист1!CL19+Лист1!CL20 -> 1265.972 | BI16: =Лист1!CN17+Лист1!CN19+Лист1!CN20 -> 1265.972 | BJ16: =Лист1!CP17+Лист1!CP19+Лист1!CP20 -> 0 | BK16: =IFERROR(BI16-BH16,"-") -> 0 | BL16: =IFERROR(BI16/BH16,"-") -> 1 | BM16: =Лист1!CT17+Лист1!CT19+Лист1!CT20 -> 1290.147 | BN16: =Лист1!CV17+Лист1!CV19+Лист1!CV20 -> 1290.147 | BO16: =Лист1!CX17+Лист1!CX19+Лист1!CX20 -> 0 | BP16: =IFERROR(BN16-BM16,"-") -> 0 | BQ16: =IFERROR(BN16/BM16,"-") -> 1 | BR16: =Лист1!DB17+Лист1!DB19+Лист1!DB20 -> 1293.744 | BS16: =Лист1!DD17+Лист1!DD19+Лист1!DD20 -> 1293.744 | BT16: =Лист1!DF17+Лист1!DF19+Лист1!DF20 -> 0 | BU16: =IFERROR(BS16-BR16,"-") -> 0 | BV16: =IFERROR(BS16/BR16,"-") -> 1 | BW16: =CB16+CG16+CL16 -> 3904.628 | BX16: =CC16+CH16+CM16 -> 3904.628 | BY16: =CD16+CI16+CN16 -> 0 | BZ16: =IFERROR(BX16-BW16,"-") -> 0 | CA16: =IFERROR(BX16/BW16,"-") -> 1 | CB16: =Лист1!DR17+Лист1!DR19+Лист1!DR20 -> 1317.897 | CC16: =Лист1!DT17+Лист1!DT19+Лист1!DT20 -> 1317.897 | CD16: =Лист1!DV17+Лист1!DV19+Лист1!DV20 -> 0 | CE16: =IFERROR(CC16-CB16,"-") -> 0 | CF16: =IFERROR(CC16/CB16,"-") -> 1 | CG16: =Лист1!DZ17+Лист1!DZ19+Лист1!DZ20 -> 1276.213 | CH16: =Лист1!EB17+Лист1!EB19+Лист1!EB20 -> 1276.213 | CI16: =Лист1!ED17+Лист1!ED19+Лист1!ED20 -> 0 | CJ16: =IFERROR(CH16-CG16,"-") -> 0 | CK16: =IFERROR(CH16/CG16,"-") -> 1 | CL16: =Лист1!EH17+Лист1!EH19+Лист1!EH20 -> 1310.518 | CM16: =Лист1!EJ17+Лист1!EJ19+Лист1!EJ20 -> 1310.518 | CN16: =Лист1!EL17+Лист1!EL19+Лист1!EL20 -> 0 | CO16: =IFERROR(CM16-CL16,"-") -> 0 | CP16: =IFERROR(CM16/CL16,"-") -> 1

Sheet Лист1
A2: № п/п | B2: Показатели | C2: Внутренние настройки листа | I2: Ед. изм. | J2: 2026 | L2: 2026 | N2: 2026 | R2: 2026 год 1 квартал | T2: 2026 год 1 квартал | V2: 2026 год 1 квартал | Z2: 2026 год январь | AB2: 2026 год январь | AD2: 2026 год январь | AH2: 2026 год февраль | AJ2: 2026 год февраль | AL2: 2026 год февраль | AP2: 2026 год март | AR2: 2026 год март | AT2: 2026 год март | AX2: 2026 год 2 квартал | AZ2: 2026 год 2 квартал | BB2: 2026 год 2 квартал | BF2: 2026 год апрель | BH2: 2026 год апрель | BJ2: 2026 год апрель | BN2: 2026 год май | BP2: 2026 год май | BR2: 2026 год май | BV2: 2026 год июнь | BX2: 2026 год июнь | BZ2: 2026 год июнь | CD2: 2026 год 3 квартал | CF2: 2026 год 3 квартал | CH2: 2026 год 3 квартал | CL2: 2026 год июль | CN2: 2026 год июль | CP2: 2026 год июль | CT2: 2026 год август | CV2: 2026 год август | CX2: 2026 год август | DB2: 2026 год сентябрь | DD2: 2026 год сентябрь | DF2: 2026 год сентябрь | DJ2: 2026 год 4 квартал | DL2: 2026 год 4 квартал | DN2: 2026 год 4 квартал | DR2: 2026 год октябрь | DT2: 2026 год октябрь | DV2: 2026 год октябрь | DZ2: 2026 год ноябрь | EB2: 2026 год ноябрь | ED2: 2026 год ноябрь | EH2: 2026 год декабрь | EJ2: 2026 год декабрь | EL2: 2026 год декабрь
C3: Ключ статьи | D3: Ключ спец расчётов | E3: Ключ ввод данных | F3: Формула месяц | G3: Формула % Выхода | H3: Строка проверка | J3: Среднесрочн. план 2026: Вариант утвержденный | K3: % выхода | L3: Среднесрочн. план 2026 ПРЭУ: Вариант на утверждение | M3: % выхода | N3: Факт | O3: % выхода | P3: Отклонение | R3: Среднесрочн. план 2026: Вариант утвержденный | S3: % выхода | T3: Среднесрочн. план 2026 ПРЭУ: Вариант на утверждение | U3: % выхода | V3: Факт | W3: % выхода | X3: Отклонение | Z3: Среднесрочн. план 2026: Вариант утвержденный | AA3: % выхода | AB3: Среднесрочн. план 2026 ПРЭУ: Вариант на утверждение | AC3: % выхода | AD3: Факт | AE3: % выхода | AF3: Отклонение | AH3: Среднесрочн. план 2026: Вариант утвержденный | AI3: % выхода | AJ3: Среднесрочн. план 2026 ПРЭУ: Вариант на утверждение | AK3: % выхода | AL3: Факт | AM3: % выхода | AN3: Отклонение | AP3: Среднесрочн. план 2026: Вариант утвержденный | AQ3: % выхода | AR3: Среднесрочн. план 2026 ПРЭУ: Вариант на утверждение | AS3: % выхода | AT3: Факт | AU3: % выхода | AV3: Отклонение | AX3: Среднесрочн. план 2026: Вариант утвержденный | AY3: % выхода | AZ3: Среднесрочн. план 2026 ПРЭУ: Вариант на утверждение | BA3: % выхода | BB3: Факт | BC3: % выхода | BD3: Отклонение | BF3: Среднесрочн. план 2026: Вариант утвержденный | BG3: % выхода | BH3: Среднесрочн. план 2026 ПРЭУ: Вариант на утверждение | BI3: % выхода | BJ3: Факт | BK3: % выхода | BL3: Отклонение | BN3: Среднесрочн. план 2026: Вариант утвержденный | BO3: % выхода | BP3: Среднесрочн. план 2026 ПРЭУ: Вариант на утверждение | BQ3: % выхода | BR3: Факт | BS3: % выхода | BT3: Отклонение | BV3: Среднесрочн. план 2026: Вариант утвержденный | BW3: % выхода | BX3: Среднесрочн. план 2026 ПРЭУ: Вариант на утверждение | BY3: % выхода | BZ3: Факт | CA3: % выхода | CB3: Отклонение | CD3: Среднесрочн. план 2026: Вариант утвержденный | CE3: % выхода | CF3: Среднесрочн. план 2026 ПРЭУ: Вариант на утверждение | CG3: % выхода | CH3: Факт | CI3: % выхода | CJ3: Отклонение | CL3: Среднесрочн. план 2026: Вариант утвержденный | CM3: % выхода | CN3: Среднесрочн. план 2026 ПРЭУ: Вариант на утверждение | CO3: % выхода | CP3: Факт | CQ3: % выхода | CR3: Отклонение | CT3: Среднесрочн. план 2026: Вариант утвержденный | CU3: % выхода | CV3: Среднесрочн. план 2026 ПРЭУ: Вариант на утверждение | CW3: % выхода | CX3: Факт | CY3: % выхода | CZ3: Отклонение | DB3: Среднесрочн. план 2026: Вариант утвержденный | DC3: % выхода | DD3: Среднесрочн. план 2026 ПРЭУ: Вариант на утверждение | DE3: % выхода | DF3: Факт | DG3: % выхода | DH3: Отклонение | DJ3: Среднесрочн. план 2026: Вариант утвержденный | DK3: % выхода | DL3: Среднесрочн. план 2026 ПРЭУ: Вариант на утверждение | DM3: % выхода | DN3: Факт | DO3: % выхода | DP3: Отклонение | DR3: Среднесрочн. план 2026: Вариант утвержденный | DS3: % выхода | DT3: Среднесрочн. план 2026 ПРЭУ: Вариант на утверждение | DU3: % выхода | DV3: Факт | DW3: % выхода | DX3: Отклонение | DZ3: Среднесрочн. план 2026: Вариант утвержденный | EA3: % выхода | EB3: Среднесрочн. план 2026 ПРЭУ: Вариант на утверждение | EC3: % выхода | ED3: Факт | EE3: % выхода | EF3: Отклонение | EH3: Среднесрочн. план 2026: Вариант утвержденный | EI3: % выхода | EJ3: Среднесрочн. план 2026 ПРЭУ: Вариант на утверждение | EK3: % выхода | EL3: Факт | EM3: % выхода | EN3: Отклонение
P4: + / - | Q4: % вып. | X4: + / - | Y4: % вып. | AF4: + / - | AG4: % вып. | AN4: + / - | AO4: % вып. | AV4: + / - | AW4: % вып. | BD4: + / - | BE4: % вып. | BL4: + / - | BM4: % вып. | BT4: + / - | BU4: % вып. | CB4: + / - | CC4: % вып. | CJ4: + / - | CK4: % вып. | CR4: + / - | CS4: % вып. | CZ4: + / - | DA4: % вып. | DH4: + / - | DI4: % вып. | DP4: + / - | DQ4: % вып. | DX4: + / - | DY4: % вып. | EF4: + / - | EG4: % вып. | EN4: + / - | EO4: % вып.
J5: year2026:1:2260099 | L5: year2026:1:2260010 | N5: year2026:15:None | R5: year2026:Q1:1:2260099 | T5: year2026:Q1:1:2260010 | V5: year2026:Q1:15:None | Z5: year2026:M1_1:1:2260099 | AB5: year2026:M1_1:1:2260010 | AD5: year2026:M1_1:15:None | AH5: year2026:M1_2:1:2260099 | AJ5: year2026:M1_2:1:2260010 | AL5: year2026:M1_2:15:None | AP5: year2026:M1_3:1:2260099 | AR5: year2026:M1_3:1:2260010 | AT5: year2026:M1_3:15:None | AX5: year2026:Q2:1:2260099 | AZ5: year2026:Q2:1:2260010 | BB5: year2026:Q2:15:None | BF5: year2026:M2_1:1:2260099 | BH5: year2026:M2_1:1:2260010 | BJ5: year2026:M2_1:15:None | BN5: year2026:M2_2:1:2260099 | BP5: year2026:M2_2:1:2260010 | BR5: year2026:M2_2:15:None | BV5: year2026:M2_3:1:2260099 | BX5: year2026:M2_3:1:2260010 | BZ5: year2026:M2_3:15:None | CD5: year2026:Q3:1:2260099 | CF5: year2026:Q3:1:2260010 | CH5: year2026:Q3:15:None | CL5: year2026:M3_1:1:2260099 | CN5: year2026:M3_1:1:2260010 | CP5: year2026:M3_1:15:None | CT5: year2026:M3_2:1:2260099 | CV5: year2026:M3_2:1:2260010 | CX5: year2026:M3_2:15:None | DB5: year2026:M3_3:1:2260099 | DD5: year2026:M3_3:1:2260010 | DF5: year2026:M3_3:15:None | DJ5: year2026:Q4:1:2260099 | DL5: year2026:Q4:1:2260010 | DN5: year2026:Q4:15:None | DR5: year2026:M4_1:1:2260099 | DT5: year2026:M4_1:1:2260010 | DV5: year2026:M4_1:15:None | DZ5: year2026:M4_2:1:2260099 | EB5: year2026:M4_2:1:2260010 | ED5: year2026:M4_2:15:None | EH5: year2026:M4_3:1:2260099 | EJ5: year2026:M4_3:1:2260010 | EL5: year2026:M4_3:15:None
A6: 1 | B6: ОКАЗАНИЕ УСЛУГ ПО СЕПАРАЦИИ СЫРЬЯ ООО "Газпром добыча Астрахань" | C6: 100331977 | F6: 100331978+100335798 | G6: ОКРУГЛ({100331977:-1}/{100331977:-1}*$100;$6) | H6: Да | J6: =R6+AX6+CD6+DJ6 -> 13574.2 | K6: =ROUND(J6/J6*100,6) -> 100 | L6: =T6+AZ6+CF6+DL6 -> 13574.2 | M6: =ROUND(L6/L6*100,6) -> 100 | N6: =V6+BB6+CH6+DN6 -> 3725.5687 | O6: =ROUND(N6/N6*100,6) -> 100 | P6: =IFERROR(L6-J6,"-") -> 0 | Q6: =IFERROR(L6/J6,"-") -> 1 | R6: =Z6+AH6+AP6 -> 3405.4 | S6: =ROUND(R6/R6*100,6) -> 100 | T6: =AB6+AJ6+AR6 -> 3405.4 | U6: =ROUND(T6/T6*100,6) -> 100 | V6: =AD6+AL6+AT6 -> 2363.5888 | W6: =ROUND(V6/V6*100,6) -> 100 | X6: =IFERROR(T6-R6,"-") -> 0 | Y6: =IFERROR(T6/R6,"-") -> 1 | Z6: =Z7+Z9 -> 1172.9 | AA6: =ROUND(Z6/Z6*100,6) -> 100 | AB6: =AB7+AB9 -> 1172.9 | AC6: =ROUND(AB6/AB6*100,6) -> 100 | AD6: =AD7+AD9 -> 852.21491 | AE6: =ROUND(AD6/AD6*100,6) -> 100 | AF6: =IFERROR(AB6-Z6,"-") -> 0 | AG6: =IFERROR(AB6/Z6,"-") -> 1 | AH6: =AH7+AH9 -> 1059.5 | AI6: =ROUND(AH6/AH6*100,6) -> 100 | AJ6: =AJ7+AJ9 -> 1059.5 | AK6: =ROUND(AJ6/AJ6*100,6) -> 100 | AL6: =AL7+AL9 -> 663.76837 | AM6: =ROUND(AL6/AL6*100,6) -> 100 | AN6: =IFERROR(AJ6-AH6,"-") -> 0 | AO6: =IFERROR(AJ6/AH6,"-") -> 1 | AP6: =AP7+AP9 -> 1173 | AQ6: =ROUND(AP6/AP6*100,6) -> 100 | AR6: =AR7+AR9 -> 1173 | AS6: =ROUND(AR6/AR6*100,6) -> 100 | AT6: =AT7+AT9 -> 847.6055 | AU6: =ROUND(AT6/AT6*100,6) -> 100 | AV6: =IFERROR(AR6-AP6,"-") -> 0 | AW6: =IFERROR(AR6/AP6,"-") -> 1 | AX6: =BF6+BN6+BV6 -> 2597.4 | AY6: =ROUND(AX6/AX6*100,6) -> 100 | AZ6: =BH6+BP6+BX6 -> 2597.4 | BA6: =ROUND(AZ6/AZ6*100,6) -> 100 | BB6: =BJ6+BR6+BZ6 -> 1361.9799 | BC6: =ROUND(BB6/BB6*100,6) -> 100 | BD6: =IFERROR(AZ6-AX6,"-") -> 0 | BE6: =IFERROR(AZ6/AX6,"-") -> 1 | BF6: =BF7+BF9 -> 1135.2 | BG6: =ROUND(BF6/BF6*100,6) -> 100 | BH6: =BH7+BH9 -> 1135.2 | BI6: =ROUND(BH6/BH6*100,6) -> 100 | BJ6: =BJ7+BJ9 -> 807.96479 | BK6: =ROUND(BJ6/BJ6*100,6) -> 100 | BL6: =IFERROR(BH6-BF6,"-") -> 0 | BM6: =IFERROR(BH6/BF6,"-") -> 1 | BN6: =BN7+BN9 -> 806.4 | BO6: =ROUND(BN6/BN6*100,6) -> 100 | BP6: =BP7+BP9 -> 806.4 | BQ6: =ROUND(BP6/BP6*100,6) -> 100 | BR6: =BR7+BR9 -> 328.213 | BS6: =ROUND(BR6/BR6*100,6) -> 100 | BT6: =IFERROR(BP6-BN6,"-") -> 0 | BU6: =IFERROR(BP6/BN6,"-") -> 1 | BV6: =BV7+BV9 -> 655.8 | BW6: =ROUND(BV6/BV6*100,6) -> 100 | BX6: =BX7+BX9 -> 655.8 | BY6: =ROUND(BX6/BX6*100,6) -> 100 | BZ6: =BZ7+BZ9 -> 225.80213 | CA6: =ROUND(BZ6/BZ6*100,6) -> 100 | CB6: =IFERROR(BX6-BV6,"-") -> 0 | CC6: =IFERROR(BX6/BV6,"-") -> 1 | CD6: =CL6+CT6+DB6 -> 3706 | CE6: =ROUND(CD6/CD6*100,6) -> 100 | CF6: =CN6+CV6+DD6 -> 3706 | CG6: =ROUND(CF6/CF6*100,6) -> 100 | CH6: =CP6+CX6+DF6 -> 0 | CI6: =ROUND(CH6/CH6*100,6) -> #DIV/0! | CJ6: =IFERROR(CF6-CD6,"-") -> 0 | CK6: =IFERROR(CF6/CD6,"-") -> 1 | CL6: =CL7+CL9 -> 1219.6 | CM6: =ROUND(CL6/CL6*100,6) -> 100 | CN6: =CN7+CN9 -> 1219.6 | CO6: =ROUND(CN6/CN6*100,6) -> 100 | CP6: =CP7+CP9 -> 0 | CQ6: =ROUND(CP6/CP6*100,6) -> #DIV/0! | CR6: =IFERROR(CN6-CL6,"-") -> 0 | CS6: =IFERROR(CN6/CL6,"-") -> 1 | CT6: =CT7+CT9 -> 1225.1 | CU6: =ROUND(CT6/CT6*100,6) -> 100 | CV6: =CV7+CV9 -> 1225.1 | CW6: =ROUND(CV6/CV6*100,6) -> 100 | CX6: =CX7+CX9 -> 0 | CY6: =ROUND(CX6/CX6*100,6) -> #DIV/0! | CZ6: =IFERROR(CV6-CT6,"-") -> 0 | DA6: =IFERROR(CV6/CT6,"-") -> 1 | DB6: =DB7+DB9 -> 1261.3 | DC6: =ROUND(DB6/DB6*100,6) -> 100 | DD6: =DD7+DD9 -> 1261.3 | DE6: =ROUND(DD6/DD6*100,6) -> 100 | DF6: =DF7+DF9 -> 0 | DG6: =ROUND(DF6/DF6*100,6) -> #DIV/0! | DH6: =IFERROR(DD6-DB6,"-") -> 0 | DI6: =IFERROR(DD6/DB6,"-") -> 1 | DJ6: =DR6+DZ6+EH6 -> 3865.4 | DK6: =ROUND(DJ6/DJ6*100,6) -> 100 | DL6: =DT6+EB6+EJ6 -> 3865.4 | DM6: =ROUND(DL6/DL6*100,6) -> 100 | DN6: =DV6+ED6+EL6 -> 0 | DO6: =ROUND(DN6/DN6*100,6) -> #DIV/0! | DP6: =IFERROR(DL6-DJ6,"-") -> 0 | DQ6: =IFERROR(DL6/DJ6,"-") -> 1 | DR6: =DR7+DR9 -> 1303.3 | DS6: =ROUND(DR6/DR6*100,6) -> 100 | DT6: =DT7+DT9 -> 1303.3 | DU6: =ROUND(DT6/DT6*100,6) -> 100 | DV6: =DV7+DV9 -> 0 | DW6: =ROUND(DV6/DV6*100,6) -> #DIV/0! | DX6: =IFERROR(DT6-DR6,"-") -> 0 | DY6: =IFERROR(DT6/DR6,"-") -> 1 | DZ6: =DZ7+DZ9 -> 1261.3 | EA6: =ROUND(DZ6/DZ6*100,6) -> 100 | EB6: =EB7+EB9 -> 1261.3 | EC6: =ROUND(EB6/EB6*100,6) -> 100 | ED6: =ED7+ED9 -> 0 | EE6: =ROUND(ED6/ED6*100,6) -> #DIV/0! | EF6: =IFERROR(EB6-DZ6,"-") -> 0 | EG6: =IFERROR(EB6/DZ6,"-") -> 1 | EH6: =EH7+EH9 -> 1300.8 | EI6: =ROUND(EH6/EH6*100,6) -> 100 | EJ6: =EJ7+EJ9 -> 1300.8 | EK6: =ROUND(EJ6/EJ6*100,6) -> 100 | EL6: =EL7+EL9 -> 0 | EM6: =ROUND(EL6/EL6*100,6) -> #DIV/0! | EN6: =IFERROR(EJ6-EH6,"-") -> 0 | EO6: =IFERROR(EJ6/EH6,"-") -> 1
A7: 1.1 | B7: СЕПАРАЦИЯ ПРИРОДНОГО ГАЗА, собственность ООО "Газпром добыча Астрахань" | C7: 100331978 | J7: =R7+AX7+CD7+DJ7 -> 10325.4 | L7: =T7+AZ7+CF7+DL7 -> 10325.4 | N7: =V7+BB7+CH7+DN7 -> 2830.087 | P7: =IFERROR(L7-J7,"-") -> 0 | Q7: =IFERROR(L7/J7,"-") -> 1 | R7: =Z7+AH7+AP7 -> 2590.4 | T7: =AB7+AJ7+AR7 -> 2590.4 | V7: =AD7+AL7+AT7 -> 1796.149 | X7: =IFERROR(T7-R7,"-") -> 0 | Y7: =IFERROR(T7/R7,"-") -> 1 | Z7: 892.2 | AB7: 892.2 | AD7: 648.015 | AF7: =IFERROR(AB7-Z7,"-") -> 0 | AG7: =IFERROR(AB7/Z7,"-") -> 1 | AH7: 805.9 | AJ7: 805.9 | AL7: 504.609 | AN7: =IFERROR(AJ7-AH7,"-") -> 0 | AO7: =IFERROR(AJ7/AH7,"-") -> 1 | AP7: 892.3 | AR7: 892.3 | AT7: 643.525 | AV7: =IFERROR(AR7-AP7,"-") -> 0 | AW7: =IFERROR(AR7/AP7,"-") -> 1 | AX7: =BF7+BN7+BV7 -> 1975.7 | AZ7: =BH7+BP7+BX7 -> 1975.7 | BB7: =BJ7+BR7+BZ7 -> 1033.938 | BD7: =IFERROR(AZ7-AX7,"-") -> 0 | BE7: =IFERROR(AZ7/AX7,"-") -> 1 | BF7: 863.5 | BH7: 863.5 | BJ7: 612.764 | BL7: =IFERROR(BH7-BF7,"-") -> 0 | BM7: =IFERROR(BH7/BF7,"-") -> 1 | BN7: 613.4 | BP7: 613.4 | BR7: 249.436 | BT7: =IFERROR(BP7-BN7,"-") -> 0 | BU7: =IFERROR(BP7/BN7,"-") -> 1 | BV7: 498.8 | BX7: 498.8 | BZ7: 171.738 | CB7: =IFERROR(BX7-BV7,"-") -> 0 | CC7: =IFERROR(BX7/BV7,"-") -> 1 | CD7: =CL7+CT7+DB7 -> 2819 | CF7: =CN7+CV7+DD7 -> 2819 | CH7: =CP7+CX7+DF7 -> 0 | CJ7: =IFERROR(CF7-CD7,"-") -> 0 | CK7: =IFERROR(CF7/CD7,"-") -> 1 | CL7: 927.7 | CN7: 927.7 | CR7: =IFERROR(CN7-CL7,"-") -> 0 | CS7: =IFERROR(CN7/CL7,"-") -> 1 | CT7: 931.9 | CV7: 931.9 | CZ7: =IFERROR(CV7-CT7,"-") -> 0 | DA7: =IFERROR(CV7/CT7,"-") -> 1 | DB7: 959.4 | DD7: 959.4 | DH7: =IFERROR(DD7-DB7,"-") -> 0 | DI7: =IFERROR(DD7/DB7,"-") -> 1 | DJ7: =DR7+DZ7+EH7 -> 2940.3 | DL7: =DT7+EB7+EJ7 -> 2940.3 | DN7: =DV7+ED7+EL7 -> 0 | DP7: =IFERROR(DL7-DJ7,"-") -> 0 | DQ7: =IFERROR(DL7/DJ7,"-") -> 1 | DR7: 991.4 | DT7: 991.4 | DX7: =IFERROR(DT7-DR7,"-") -> 0 | DY7: =IFERROR(DT7/DR7,"-") -> 1 | DZ7: 959.4 | EB7: 959.4 | EF7: =IFERROR(EB7-DZ7,"-") -> 0 | EG7: =IFERROR(EB7/DZ7,"-") -> 1 | EH7: 989.5 | EJ7: 989.5 | EN7: =IFERROR(EJ7-EH7,"-") -> 0 | EO7: =IFERROR(EJ7/EH7,"-") -> 1
C8: 100331979 | G8: ОКРУГЛ({100331977:-1}/{100331979:-1}*$100;$6) | H8: *+59 | J8: =R8+AX8+CD8+DJ8 -> 9686.1 | K8: =ROUND(J6/J8*100,6) -> 140.14103 | L8: =T8+AZ8+CF8+DL8 -> 9686.1 | M8: =ROUND(L6/L8*100,6) -> 140.14103 | N8: =V8+BB8+CH8+DN8 -> 2671.357 | O8: =ROUND(N6/N8*100,6) -> 139.46353 | P8: =IFERROR(L8-J8,"-") -> 0 | Q8: =IFERROR(L8/J8,"-") -> 1 | R8: =Z8+AH8+AP8 -> 2430 | S8: =ROUND(R6/R8*100,6) -> 140.13992 | T8: =AB8+AJ8+AR8 -> 2430 | U8: =ROUND(T6/T8*100,6) -> 140.13992 | V8: =AD8+AL8+AT8 -> 1691.83 | W8: =ROUND(V6/V8*100,6) -> 139.70604 | X8: =IFERROR(T8-R8,"-") -> 0 | Y8: =IFERROR(T8/R8,"-") -> 1 | Z8: 837 | AA8: =ROUND(Z6/Z8*100,6) -> 140.13142 | AB8: 837 | AC8: =ROUND(AB6/AB8*100,6) -> 140.13142 | AD8: 608.825 | AE8: =ROUND(AD6/AD8*100,6) -> 139.97699 | AF8: =IFERROR(AB8-Z8,"-") -> 0 | AG8: =IFERROR(AB8/Z8,"-") -> 1 | AH8: 756 | AI8: =ROUND(AH6/AH8*100,6) -> 140.1455 | AJ8: 756 | AK8: =ROUND(AJ6/AJ8*100,6) -> 140.1455 | AL8: 474.536 | AM8: =ROUND(AL6/AL8*100,6) -> 139.87735 | AN8: =IFERROR(AJ8-AH8,"-") -> 0 | AO8: =IFERROR(AJ8/AH8,"-") -> 1 | AP8: 837 | AQ8: =ROUND(AP6/AP8*100,6) -> 140.14337 | AR8: 837 | AS8: =ROUND(AR6/AR8*100,6) -> 140.14337 | AT8: 608.469 | AU8: =ROUND(AT6/AT8*100,6) -> 139.30134 | AV8: =IFERROR(AR8-AP8,"-") -> 0 | AW8: =IFERROR(AR8/AP8,"-") -> 1 | AX8: =BF8+BN8+BV8 -> 1853.4 | AY8: =ROUND(AX6/AX8*100,6) -> 140.14244 | AZ8: =BH8+BP8+BX8 -> 1853.4 | BA8: =ROUND(AZ6/AZ8*100,6) -> 140.14244 | BB8: =BJ8+BR8+BZ8 -> 979.527 | BC8: =ROUND(BB6/BB8*100,6) -> 139.04465 | BD8: =IFERROR(AZ8-AX8,"-") -> 0 | BE8: =IFERROR(AZ8/AX8,"-") -> 1 | BF8: 810 | BG8: =ROUND(BF6/BF8*100,6) -> 140.14815 | BH8: 810 | BI8: =ROUND(BH6/BH8*100,6) -> 140.14815 | BJ8: 581.994 | BK8: =ROUND(BJ6/BJ8*100,6) -> 138.827 | BL8: =IFERROR(BH8-BF8,"-") -> 0 | BM8: =IFERROR(BH8/BF8,"-") -> 1 | BN8: 575.4 | BO8: =ROUND(BN6/BN8*100,6) -> 140.14598 | BP8: 575.4 | BQ8: =ROUND(BP6/BP8*100,6) -> 140.14598 | BR8: 236.34 | BS8: =ROUND(BR6/BR8*100,6) -> 138.87323 | BT8: =IFERROR(BP8-BN8,"-") -> 0 | BU8: =IFERROR(BP8/BN8,"-") -> 1 | BV8: 468 | BW8: =ROUND(BV6/BV8*100,6) -> 140.12821 | BX8: 468 | BY8: =ROUND(BX6/BX8*100,6) -> 140.12821 | BZ8: 161.193 | CA8: =ROUND(BZ6/BZ8*100,6) -> 140.08185 | CB8: =IFERROR(BX8-BV8,"-") -> 0 | CC8: =IFERROR(BX8/BV8,"-") -> 1 | CD8: =CL8+CT8+DB8 -> 2644.5 | CE8: =ROUND(CD6/CD8*100,6) -> 140.13991 | CF8: =CN8+CV8+DD8 -> 2644.5 | CG8: =ROUND(CF6/CF8*100,6) -> 140.13991 | CH8: =CP8+CX8+DF8 -> 0 | CI8: =ROUND(CH6/CH8*100,6) -> #DIV/0! | CJ8: =IFERROR(CF8-CD8,"-") -> 0 | CK8: =IFERROR(CF8/CD8,"-") -> 1 | CL8: 870.3 | CM8: =ROUND(CL6/CL8*100,6) -> 140.13558 | CN8: 870.3 | CO8: =ROUND(CN6/CN8*100,6) -> 140.13558 | CQ8: =ROUND(CP6/CP8*100,6) -> #DIV/0! | CR8: =IFERROR(CN8-CL8,"-") -> 0 | CS8: =IFERROR(CN8/CL8,"-") -> 1 | CT8: 874.2 | CU8: =ROUND(CT6/CT8*100,6) -> 140.13956 | CV8: 874.2 | CW8: =ROUND(CV6/CV8*100,6) -> 140.13956 | CY8: =ROUND(CX6/CX8*100,6) -> #DIV/0! | CZ8: =IFERROR(CV8-CT8,"-") -> 0 | DA8: =IFERROR(CV8/CT8,"-") -> 1 | DB8: 900 | DC8: =ROUND(DB6/DB8*100,6) -> 140.14444 | DD8: 900 | DE8: =ROUND(DD6/DD8*100,6) -> 140.14444 | DG8: =ROUND(DF6/DF8*100,6) -> #DIV/0! | DH8: =IFERROR(DD8-DB8,"-") -> 0 | DI8: =IFERROR(DD8/DB8,"-") -> 1 | DJ8: =DR8+DZ8+EH8 -> 2758.2 | DK8: =ROUND(DJ6/DJ8*100,6) -> 140.14212 | DL8: =DT8+EB8+EJ8 -> 2758.2 | DM8: =ROUND(DL6/DL8*100,6) -> 140.14212 | DN8: =DV8+ED8+EL8 -> 0 | DO8: =ROUND(DN6/DN8*100,6) -> #DIV/0! | DP8: =IFERROR(DL8-DJ8,"-") -> 0 | DQ8: =IFERROR(DL8/DJ8,"-") -> 1 | DR8: 930 | DS8: =ROUND(DR6/DR8*100,6) -> 140.13978 | DT8: 930 | DU8: =ROUND(DT6/DT8*100,6) -> 140.13978 | DW8: =ROUND(DV6/DV8*100,6) -> #DIV/0! | DX8: =IFERROR(DT8-DR8,"-") -> 0 | DY8: =IFERROR(DT8/DR8,"-") -> 1 | DZ8: 900 | EA8: =ROUND(DZ6/DZ8*100,6) -> 140.14444 | EB8: 900 | EC8: =ROUND(EB6/EB8*100,6) -> 140.14444 | EE8: =ROUND(ED6/ED8*100,6) -> #DIV/0! | EF8: =IFERROR(EB8-DZ8,"-") -> 0 | EG8: =IFERROR(EB8/DZ8,"-") -> 1 | EH8: 928.2 | EI8: =ROUND(EH6/EH8*100,6) -> 140.14221 | EJ8: 928.2 | EK8: =ROUND(EJ6/EJ8*100,6) -> 140.14221 | EM8: =ROUND(EL6/EL8*100,6) -> #DIV/0! | EN8: =IFERROR(EJ8-EH8,"-") -> 0 | EO8: =IFERROR(EJ8/EH8,"-") -> 1
A9: 1.2 | B9: СЕПАРАЦИЯ КОНДЕНСАТА ГАЗОВОГО НЕСТАБИЛЬНОГО, собственность ООО "Газпром добыча Астрахань" | C9: 100335798 | J9: =R9+AX9+CD9+DJ9 -> 3248.8 | L9: =T9+AZ9+CF9+DL9 -> 3248.8 | N9: =V9+BB9+CH9+DN9 -> 895.4817 | P9: =IFERROR(L9-J9,"-") -> 0 | Q9: =IFERROR(L9/J9,"-") -> 1 | R9: =Z9+AH9+AP9 -> 815 | T9: =AB9+AJ9+AR9 -> 815 | V9: =AD9+AL9+AT9 -> 567.43978 | X9: =IFERROR(T9-R9,"-") -> 0 | Y9: =IFERROR(T9/R9,"-") -> 1 | Z9: 280.7 | AB9: 280.7 | AD9: 204.19991 | AF9: =IFERROR(AB9-Z9,"-") -> 0 | AG9: =IFERROR(AB9/Z9,"-") -> 1 | AH9: 253.6 | AJ9: 253.6 | AL9: 159.15937 | AN9: =IFERROR(AJ9-AH9,"-") -> 0 | AO9: =IFERROR(AJ9/AH9,"-") -> 1 | AP9: 280.7 | AR9: 280.7 | AT9: 204.0805 | AV9: =IFERROR(AR9-AP9,"-") -> 0 | AW9: =IFERROR(AR9/AP9,"-") -> 1 | AX9: =BF9+BN9+BV9 -> 621.7 | AZ9: =BH9+BP9+BX9 -> 621.7 | BB9: =BJ9+BR9+BZ9 -> 328.04192 | BD9: =IFERROR(AZ9-AX9,"-") -> 0 | BE9: =IFERROR(AZ9/AX9,"-") -> 1 | BF9: 271.7 | BH9: 271.7 | BJ9: 195.20079 | BL9: =IFERROR(BH9-BF9,"-") -> 0 | BM9: =IFERROR(BH9/BF9,"-") -> 1 | BN9: 193 | BP9: 193 | BR9: 78.777 | BT9: =IFERROR(BP9-BN9,"-") -> 0 | BU9: =IFERROR(BP9/BN9,"-") -> 1 | BV9: 157 | BX9: 157 | BZ9: 54.064132 | CB9: =IFERROR(BX9-BV9,"-") -> 0 | CC9: =IFERROR(BX9/BV9,"-") -> 1 | CD9: =CL9+CT9+DB9 -> 887 | CF9: =CN9+CV9+DD9 -> 887 | CH9: =CP9+CX9+DF9 -> 0 | CJ9: =IFERROR(CF9-CD9,"-") -> 0 | CK9: =IFERROR(CF9/CD9,"-") -> 1 | CL9: 291.9 | CN9: 291.9 | CR9: =IFERROR(CN9-CL9,"-") -> 0 | CS9: =IFERROR(CN9/CL9,"-") -> 1 | CT9: 293.2 | CV9: 293.2 | CZ9: =IFERROR(CV9-CT9,"-") -> 0 | DA9: =IFERROR(CV9/CT9,"-") -> 1 | DB9: 301.9 | DD9: 301.9 | DH9: =IFERROR(DD9-DB9,"-") -> 0 | DI9: =IFERROR(DD9/DB9,"-") -> 1 | DJ9: =DR9+DZ9+EH9 -> 925.1 | DL9: =DT9+EB9+EJ9 -> 925.1 | DN9: =DV9+ED9+EL9 -> 0 | DP9: =IFERROR(DL9-DJ9,"-") -> 0 | DQ9: =IFERROR(DL9/DJ9,"-") -> 1 | DR9: 311.9 | DT9: 311.9 | DX9: =IFERROR(DT9-DR9,"-") -> 0 | DY9: =IFERROR(DT9/DR9,"-") -> 1 | DZ9: 301.9 | EB9: 301.9 | EF9: =IFERROR(EB9-DZ9,"-") -> 0 | EG9: =IFERROR(EB9/DZ9,"-") -> 1 | EH9: 311.3 | EJ9: 311.3 | EN9: =IFERROR(EJ9-EH9,"-") -> 0 | EO9: =IFERROR(EJ9/EH9,"-") -> 1
B10: ПОТЕРИ СЫРЬЯ ПРИ ПЕРЕРАБОТКЕ (УСЛОВНЫЕ), собственность ООО "Газпром добыча Астрахань": | C10: 100335799 | F10: 1_100335800 | J10: =R10+AX10+CD10+DJ10 -> 13.6 | L10: =T10+AZ10+CF10+DL10 -> 13.6 | N10: =V10+BB10+CH10+DN10 -> 3.721 | P10: =IFERROR(L10-J10,"-") -> 0 | Q10: =IFERROR(L10/J10,"-") -> 1 | R10: =Z10+AH10+AP10 -> 3.4 | T10: =AB10+AJ10+AR10 -> 3.4 | V10: =AD10+AL10+AT10 -> 2.362 | X10: =IFERROR(T10-R10,"-") -> 0 | Y10: =IFERROR(T10/R10,"-") -> 1 | Z10: =Лист1!Z11 -> 1.2 | AB10: =Лист1!AB11 -> 1.2 | AD10: =Лист1!AD11 -> 0.852 | AF10: =IFERROR(AB10-Z10,"-") -> 0 | AG10: =IFERROR(AB10/Z10,"-") -> 1 | AH10: =Лист1!AH11 -> 1.1 | AJ10: =Лист1!AJ11 -> 1.1 | AL10: =Лист1!AL11 -> 0.663 | AN10: =IFERROR(AJ10-AH10,"-") -> 0 | AO10: =IFERROR(AJ10/AH10,"-") -> 1 | AP10: =Лист1!AP11 -> 1.1 | AR10: =Лист1!AR11 -> 1.1 | AT10: =Лист1!AT11 -> 0.847 | AV10: =IFERROR(AR10-AP10,"-") -> 0 | AW10: =IFERROR(AR10/AP10,"-") -> 1 | AX10: =BF10+BN10+BV10 -> 2.6 | AZ10: =BH10+BP10+BX10 -> 2.6 | BB10: =BJ10+BR10+BZ10 -> 1.359 | BD10: =IFERROR(AZ10-AX10,"-") -> 0 | BE10: =IFERROR(AZ10/AX10,"-") -> 1 | BF10: =Лист1!BF11 -> 1.2 | BH10: =Лист1!BH11 -> 1.2 | BJ10: =Лист1!BJ11 -> 0.807 | BL10: =IFERROR(BH10-BF10,"-") -> 0 | BM10: =IFERROR(BH10/BF10,"-") -> 1 | BN10: =Лист1!BN11 -> 0.8 | BP10: =Лист1!BP11 -> 0.8 | BR10: =Лист1!BR11 -> 0.327 | BT10: =IFERROR(BP10-BN10,"-") -> 0 | BU10: =IFERROR(BP10/BN10,"-") -> 1 | BV10: =Лист1!BV11 -> 0.6 | BX10: =Лист1!BX11 -> 0.6 | BZ10: =Лист1!BZ11 -> 0.225 | CB10: =IFERROR(BX10-BV10,"-") -> 0 | CC10: =IFERROR(BX10/BV10,"-") -> 1 | CD10: =CL10+CT10+DB10 -> 3.7 | CF10: =CN10+CV10+DD10 -> 3.7 | CH10: =CP10+CX10+DF10 -> 0 | CJ10: =IFERROR(CF10-CD10,"-") -> 0 | CK10: =IFERROR(CF10/CD10,"-") -> 1 | CL10: =Лист1!CL11 -> 1.2 | CN10: =Лист1!CN11 -> 1.2 | CP10: =Лист1!CP11 -> 0 | CR10: =IFERROR(CN10-CL10,"-") -> 0 | CS10: =IFERROR(CN10/CL10,"-") -> 1 | CT10: =Лист1!CT11 -> 1.2 | CV10: =Лист1!CV11 -> 1.2 | CX10: =Лист1!CX11 -> 0 | CZ10: =IFERROR(CV10-CT10,"-") -> 0 | DA10: =IFERROR(CV10/CT10,"-") -> 1 | DB10: =Лист1!DB11 -> 1.3 | DD10: =Лист1!DD11 -> 1.3 | DF10: =Лист1!DF11 -> 0 | DH10: =IFERROR(DD10-DB10,"-") -> 0 | DI10: =IFERROR(DD10/DB10,"-") -> 1 | DJ10: =DR10+DZ10+EH10 -> 3.9 | DL10: =DT10+EB10+EJ10 -> 3.9 | DN10: =DV10+ED10+EL10 -> 0 | DP10: =IFERROR(DL10-DJ10,"-") -> 0 | DQ10: =IFERROR(DL10/DJ10,"-") -> 1 | DR10: =Лист1!DR11 -> 1.3 | DT10: =Лист1!DT11 -> 1.3 | DV10: =Лист1!DV11 -> 0 | DX10: =IFERROR(DT10-DR10,"-") -> 0 | DY10: =IFERROR(DT10/DR10,"-") -> 1 | DZ10: =Лист1!DZ11 -> 1.3 | EB10: =Лист1!EB11 -> 1.3 | ED10: =Лист1!ED11 -> 0 | EF10: =IFERROR(EB10-DZ10,"-") -> 0 | EG10: =IFERROR(EB10/DZ10,"-") -> 1 | EH10: =Лист1!EH11 -> 1.3 | EJ10: =Лист1!EJ11 -> 1.3 | EL10: =Лист1!EL11 -> 0 | EN10: =IFERROR(EJ10-EH10,"-") -> 0 | EO10: =IFERROR(EJ10/EH10,"-") -> 1
